File: BME243_Tues_FA21_RF_Letterman_10.csv
"Time", "Load (N)", "Position (mm)", "Strain(Axial) (in)", "Strain(Transverse) (in)", "Auxiliary ()", "Control Out (V)", "Stress (MPa)"
0.0, 0.10315975, 0.00742377, NaN, NaN, NaN, -0.2020387, "- N/A -   "
0.05000007152557373, 0.6877317, 1.3296305E-4, NaN, NaN, NaN, -0.21912959, "- N/A -   "
0.10000002384185791, 0.2063195, 0.0024598166, NaN, NaN, NaN, -0.20325948, "- N/A -   "
0.1499999761581421, 0.37825242, 0.0040332125, NaN, NaN, NaN, -0.20325948, "- N/A -   "
0.20000004768371582, 0.48141217, 0.0062714242, NaN, NaN, NaN, -0.18861015, "- N/A -   "
0.25, 0.4470256, 0.006293584, NaN, NaN, NaN, -0.21058415, "- N/A -   "
0.30000007152557373, 0.75650483, 0.0072243256, NaN, NaN, NaN, -0.21912959, "- N/A -   "
0.3500000238418579, 0.5845719, 0.009174451, NaN, NaN, NaN, -0.21180493, "- N/A -   "
0.3999999761581421, 0.75650483, 0.01132402, NaN, NaN, NaN, -0.19837637, "- N/A -   "
0.4500000476837158, 0.7908914, 0.012764453, NaN, NaN, NaN, -0.19837637, "- N/A -   "
0.5, 0.7908914, 0.012764453, NaN, NaN, NaN, -0.21912959, "- N/A -   "
0.5500000715255737, 0.825278, 0.01436001, NaN, NaN, NaN, -0.21546726, "- N/A -   "
0.6000000238418579, 0.9284377, 0.015999887, NaN, NaN, NaN, -0.21424648, "- N/A -   "
0.6499999761581421, 1.1003706, 0.018415382, NaN, NaN, NaN, -0.19959715, "- N/A -   "
0.7000000476837158, 1.1003706, 0.018858593, NaN, NaN, NaN, -0.2130257, "- N/A -   "
0.75, 1.1003706, 0.020409828, NaN, NaN, NaN, -0.20692182, "- N/A -   "
0.8000000715255737, 1.1691438, 0.021274088, NaN, NaN, NaN, -0.21668804, "- N/A -   "
0.8500000238418579, 1.2723036, 0.021517854, NaN, NaN, NaN, -0.23377892, "- N/A -   "
0.8999999761581421, 1.237917, 0.022382114, NaN, NaN, NaN, -0.24232437, "- N/A -   "
0.9500000476837158, 1.3754634, 0.025063535, NaN, NaN, NaN, -0.21668804, "- N/A -   "
1.0, 1.9600352, 0.025994277, NaN, NaN, NaN, -0.22523348, "- N/A -   "
1.0499999523162842, 1.5130097, 0.028143847, NaN, NaN, NaN, -0.21180493, "- N/A -   "
1.1000001430511475, 1.650556, 0.029894525, NaN, NaN, NaN, -0.21058415, "- N/A -   "
1.1500000953674316, 1.7193291, 0.031778168, NaN, NaN, NaN, -0.19959715, "- N/A -   "
1.2000000476837158, 2.235128, 0.03182249, NaN, NaN, NaN, -0.22157115, "- N/A -   "
1.25, 1.8224889, 0.034348786, NaN, NaN, NaN, -0.19959715, "- N/A -   "
1.2999999523162842, 1.9600352, 0.036454037, NaN, NaN, NaN, -0.18983093, "- N/A -   "
1.3500001430511475, 1.9944217, 0.03782799, NaN, NaN, NaN, -0.18861015, "- N/A -   "
1.4000000953674316, 1.9944217, 0.03782799, NaN, NaN, NaN, -0.21058415, "- N/A -   "
1.4500000476837158, 2.0975816, 0.039401386, NaN, NaN, NaN, -0.2081426, "- N/A -   "
1.5, 2.0975816, 0.04048725, NaN, NaN, NaN, -0.21180493, "- N/A -   "
1.5499999523162842, 2.131968, 0.04106342, NaN, NaN, NaN, -0.22523348, "- N/A -   "
1.6000001430511475, 2.2007413, 0.042814102, NaN, NaN, NaN, -0.22279193, "- N/A -   "
1.6500000953674316, 2.303901, 0.044387497, NaN, NaN, NaN, -0.21912959, "- N/A -   "
1.7000000476837158, 2.4070609, 0.046537068, NaN, NaN, NaN, -0.20448026, "- N/A -   "
1.75, 2.5446072, 0.04835423, NaN, NaN, NaN, -0.20448026, "- N/A -   "
1.7999999523162842, 2.5789936, 0.05052596, NaN, NaN, NaN, -0.1910517, "- N/A -   "
1.8500001430511475, 2.6133802, 0.05054812, NaN, NaN, NaN, -0.2130257, "- N/A -   "
1.9000000953674316, 2.6477668, 0.05192207, NaN, NaN, NaN, -0.21058415, "- N/A -   "
1.9500000476837158, 2.7509267, 0.053761393, NaN, NaN, NaN, -0.2081426, "- N/A -   "
2.0, 2.9228594, 0.056420654, NaN, NaN, NaN, -0.18250626, "- N/A -   "
2.049999952316284, 2.9228594, 0.05708547, NaN, NaN, NaN, -0.19593482, "- N/A -   "
2.1000001430511475, 2.9228594, 0.05708547, NaN, NaN, NaN, -0.21668804, "- N/A -   "
2.1500000953674316, 3.0947924, 0.058127016, NaN, NaN, NaN, -0.22035037, "- N/A -   "
2.200000047683716, 3.060406, 0.06016578, NaN, NaN, NaN, -0.2130257, "- N/A -   "
2.25, 3.232339, 0.06255912, NaN, NaN, NaN, -0.19593482, "- N/A -   "
2.299999952316284, 3.197952, 0.06313529, NaN, NaN, NaN, -0.2081426, "- N/A -   "
2.3500001430511475, 3.7825239, 0.06404387, NaN, NaN, NaN, -0.21790881, "- N/A -   "
2.4000000953674316, 3.3354986, 0.0654843, NaN, NaN, NaN, -0.21546726, "- N/A -   "
2.450000047683716, 3.4042716, 0.06561727, NaN, NaN, NaN, -0.23133737, "- N/A -   "
2.5, 3.5418181, 0.06829869, NaN, NaN, NaN, -0.19349326, "- N/A -   "
2.549999952316284, 3.5762048, 0.069606155, NaN, NaN, NaN, -0.19593482, "- N/A -   "
2.6000001430511475, 3.5762048, 0.069606155, NaN, NaN, NaN, -0.21668804, "- N/A -   "
2.6500000953674316, 3.6449778, 0.07153412, NaN, NaN, NaN, -0.2081426, "- N/A -   "
2.700000047683716, 3.6793642, 0.072110295, NaN, NaN, NaN, -0.21790881, "- N/A -   "
2.75, 3.6793642, 0.07264215, NaN, NaN, NaN, -0.22645426, "- N/A -   "
2.799999952316284, 3.8169107, 0.07448147, NaN, NaN, NaN, -0.21790881, "- N/A -   "
2.8500001430511475, 3.9200704, 0.07609919, NaN, NaN, NaN, -0.20936337, "- N/A -   "
2.9000000953674316, 4.02323, 0.0774953, NaN, NaN, NaN, -0.20692182, "- N/A -   "
2.950000047683716, 4.0920033, 0.07953406, NaN, NaN, NaN, -0.2020387, "- N/A -   "
3.0, 4.2295494, 0.081949554, NaN, NaN, NaN, -0.1910517, "- N/A -   "
3.049999952316284, 4.263936, 0.08214901, NaN, NaN, NaN, -0.20936337, "- N/A -   "
3.1000001430511475, 4.2983227, 0.08356728, NaN, NaN, NaN, -0.20692182, "- N/A -   "
3.1499998569488525, 4.367096, 0.08454234, NaN, NaN, NaN, -0.21790881, "- N/A -   "
3.200000047683716, 4.5390286, 0.08697999, NaN, NaN, NaN, -0.19227248, "- N/A -   "
3.250000238418579, 4.607802, 0.08830962, NaN, NaN, NaN, -0.19227248, "- N/A -   "
3.299999952316284, 4.607802, 0.08830962, NaN, NaN, NaN, -0.21424648, "- N/A -   "
3.3500001430511475, 4.710962, 0.090259746, NaN, NaN, NaN, -0.20448026, "- N/A -   "
3.3999998569488525, 4.7453485, 0.091500744, NaN, NaN, NaN, -0.20448026, "- N/A -   "
3.450000047683716, 4.848508, 0.09274173, NaN, NaN, NaN, -0.20570104, "- N/A -   "
3.500000238418579, 4.917281, 0.0947805, NaN, NaN, NaN, -0.19227248, "- N/A -   "
3.549999952316284, 4.951668, 0.0947805, NaN, NaN, NaN, -0.2130257, "- N/A -   "
3.6000001430511475, 4.9860544, 0.09633173, NaN, NaN, NaN, -0.20692182, "- N/A -   "
3.6499998569488525, 5.054828, 0.09757272, NaN, NaN, NaN, -0.20936337, "- N/A -   "
3.700000047683716, 5.123601, 0.09861427, NaN, NaN, NaN, -0.2130257, "- N/A -   "
3.750000238418579, 5.2955337, 0.10118488, NaN, NaN, NaN, -0.19471404, "- N/A -   "
3.799999952316284, 5.2955337, 0.10134, NaN, NaN, NaN, -0.21424648, "- N/A -   "
3.8500001430511475, 5.2955337, 0.10249235, NaN, NaN, NaN, -0.21668804, "- N/A -   "
3.8999998569488525, 5.43308, 0.10402143, NaN, NaN, NaN, -0.21546726, "- N/A -   "
3.950000047683716, 5.43308, 0.10479704, NaN, NaN, NaN, -0.22157115, "- N/A -   "
4.000000238418579, 5.6393995, 0.10710173, NaN, NaN, NaN, -0.21180493, "- N/A -   "
4.049999952316284, 6.155198, 0.10847569, NaN, NaN, NaN, -0.2130257, "- N/A -   "
4.1000001430511475, 5.7769456, 0.10969452, NaN, NaN, NaN, -0.21546726, "- N/A -   "
4.1499998569488525, 5.7769456, 0.110979825, NaN, NaN, NaN, -0.2130257, "- N/A -   "
4.200000047683716, 5.948879, 0.11372773, NaN, NaN, NaN, -0.18494782, "- N/A -   "
4.250000238418579, 6.017652, 0.11386069, NaN, NaN, NaN, -0.20325948, "- N/A -   "
4.299999952316284, 6.499064, 0.11452551, NaN, NaN, NaN, -0.21546726, "- N/A -   "
4.3500001430511475, 6.0520387, 0.11612106, NaN, NaN, NaN, -0.20936337, "- N/A -   "
4.3999998569488525, 6.0520387, 0.116475634, NaN, NaN, NaN, -0.22523348, "- N/A -   "
4.450000047683716, 6.086425, 0.11727341, NaN, NaN, NaN, -0.2349997, "- N/A -   "
4.500000238418579, 6.258358, 0.11988835, NaN, NaN, NaN, -0.21180493, "- N/A -   "
4.549999952316284, 6.361518, 0.12059749, NaN, NaN, NaN, -0.22279193, "- N/A -   "
4.6000001430511475, 6.464678, 0.12299082, NaN, NaN, NaN, -0.20570104, "- N/A -   "
4.6499998569488525, 6.602224, 0.12502958, NaN, NaN, NaN, -0.20081793, "- N/A -   "
4.700000047683716, 6.670997, 0.12649219, NaN, NaN, NaN, -0.20081793, "- N/A -   "
4.750000238418579, 7.2211823, 0.12691323, NaN, NaN, NaN, -0.21668804, "- N/A -   "
4.799999952316284, 6.774157, 0.12875256, NaN, NaN, NaN, -0.20692182, "- N/A -   "
4.8500001430511475, 7.1524096, 0.1297941, NaN, NaN, NaN, -0.20936337, "- N/A -   "
4.8999998569488525, 6.9804764, 0.1324312, NaN, NaN, NaN, -0.18861015, "- N/A -   "
4.950000047683716, 7.014863, 0.132542, NaN, NaN, NaN, -0.2081426, "- N/A -   "
5.000000238418579, 6.9804764, 0.13396026, NaN, NaN, NaN, -0.20448026, "- N/A -   "
5.049999952316284, 7.1524096, 0.13553366, NaN, NaN, NaN, -0.20570104, "- N/A -   "
5.1000001430511475, 7.1867957, 0.13648658, NaN, NaN, NaN, -0.20936337, "- N/A -   "
5.1499998569488525, 7.3587284, 0.13879128, NaN, NaN, NaN, -0.1971556, "- N/A -   "
5.200000047683716, 7.3931155, 0.13901287, NaN, NaN, NaN, -0.21424648, "- N/A -   "
5.250000238418579, 7.4618883, 0.14089651, NaN, NaN, NaN, -0.21180493, "- N/A -   "
5.299999952316284, 7.496275, 0.14176078, NaN, NaN, NaN, -0.21546726, "- N/A -   "
5.3500001430511475, 7.5306616, 0.14235911, NaN, NaN, NaN, -0.22645426, "- N/A -   "
5.3999998569488525, 7.7025948, 0.144553, NaN, NaN, NaN, -0.20936337, "- N/A -   "
5.450000047683716, 7.7713675, 0.14577183, NaN, NaN, NaN, -0.2081426, "- N/A -   "
5.500000238418579, 8.321553, 0.14590478, NaN, NaN, NaN, -0.22767504, "- N/A -   "
5.549999952316284, 7.874528, 0.14816517, NaN, NaN, NaN, -0.21058415, "- N/A -   "
5.6000001430511475, 7.9433007, 0.14902942, NaN, NaN, NaN, -0.21546726, "- N/A -   "
5.6499998569488525, 8.115233, 0.15111251, NaN, NaN, NaN, -0.20570104, "- N/A -   "
5.700000047683716, 8.699805, 0.15177733, NaN, NaN, NaN, -0.21912959, "- N/A -   "
5.750000238418579, 8.218393, 0.15379393, NaN, NaN, NaN, -0.20692182, "- N/A -   "
5.799999952316284, 8.56226, 0.1538604, NaN, NaN, NaN, -0.22645426, "- N/A -   "
5.8500001430511475, 8.424713, 0.15658616, NaN, NaN, NaN, -0.20692182, "- N/A -   "
5.8999998569488525, 8.493486, 0.15815955, NaN, NaN, NaN, -0.20448026, "- N/A -   "
5.950000047683716, 9.043672, 0.15886869, NaN, NaN, NaN, -0.21546726, "- N/A -   "
6.000000238418579, 8.596645, 0.16033128, NaN, NaN, NaN, -0.21058415, "- N/A -   "
6.049999952316284, 8.665419, 0.16039777, NaN, NaN, NaN, -0.23133737, "- N/A -   "
6.1000001430511475, 8.802965, 0.16310133, NaN, NaN, NaN, -0.1971556, "- N/A -   "
6.1499998569488525, 8.871738, 0.16445313, NaN, NaN, NaN, -0.19593482, "- N/A -   "
6.200000047683716, 9.215604, 0.16447529, NaN, NaN, NaN, -0.21790881, "- N/A -   "
6.250000238418579, 8.974898, 0.16684647, NaN, NaN, NaN, -0.20448026, "- N/A -   "
6.299999952316284, 9.043672, 0.16786586, NaN, NaN, NaN, -0.21058415, "- N/A -   "
6.3500001430511475, 9.181217, 0.16990462, NaN, NaN, NaN, -0.19959715, "- N/A -   "
6.3999998569488525, 9.181217, 0.17072456, NaN, NaN, NaN, -0.21058415, "- N/A -   "
6.450000047683716, 9.284378, 0.17229795, NaN, NaN, NaN, -0.20570104, "- N/A -   "
6.500000238418579, 9.35315, 0.17294061, NaN, NaN, NaN, -0.21790881, "- N/A -   "
6.549999952316284, 9.490697, 0.17553338, NaN, NaN, NaN, -0.19471404, "- N/A -   "
6.6000001430511475, 9.55947, 0.17677437, NaN, NaN, NaN, -0.1971556, "- N/A -   "
6.6499998569488525, 10.075269, 0.17684086, NaN, NaN, NaN, -0.21790881, "- N/A -   "
6.700000047683716, 9.66263, 0.17914554, NaN, NaN, NaN, -0.20448026, "- N/A -   "
6.750000238418579, 9.697016, 0.17987683, NaN, NaN, NaN, -0.21180493, "- N/A -   "
6.799999952316284, 9.731403, 0.18045302, NaN, NaN, NaN, -0.2240127, "- N/A -   "
6.8500001430511475, 9.834562, 0.18222585, NaN, NaN, NaN, -0.21790881, "- N/A -   "
6.8999998569488525, 9.937722, 0.18348901, NaN, NaN, NaN, -0.22035037, "- N/A -   "
6.950000047683716, 10.006495, 0.18566075, NaN, NaN, NaN, -0.20936337, "- N/A -   "
7.000000238418579, 10.040882, 0.18619259, NaN, NaN, NaN, -0.22035037, "- N/A -   "
7.050000429153442, 10.040882, 0.18683524, NaN, NaN, NaN, -0.23377892, "- N/A -   "
7.099999666213989, 10.247202, 0.18922858, NaN, NaN, NaN, -0.21180493, "- N/A -   "
7.1499998569488525, 10.247202, 0.19004853, NaN, NaN, NaN, -0.21790881, "- N/A -   "
7.200000047683716, 10.281589, 0.19155544, NaN, NaN, NaN, -0.21180493, "- N/A -   "
7.250000238418579, 10.384748, 0.1926413, NaN, NaN, NaN, -0.2130257, "- N/A -   "
7.300000429153442, 10.384748, 0.19310667, NaN, NaN, NaN, -0.2240127, "- N/A -   "
7.349999666213989, 10.487908, 0.1945471, NaN, NaN, NaN, -0.22523348, "- N/A -   "
7.3999998569488525, 11.003707, 0.19600971, NaN, NaN, NaN, -0.22035037, "- N/A -   "
7.450000047683716, 10.694227, 0.19824791, NaN, NaN, NaN, -0.20448026, "- N/A -   "
7.500000238418579, 10.728614, 0.19833656, NaN, NaN, NaN, -0.2240127, "- N/A -   "
7.550000429153442, 10.86616, 0.20092933, NaN, NaN, NaN, -0.2020387, "- N/A -   "
7.599999666213989, 10.900547, 0.20243625, NaN, NaN, NaN, -0.20081793, "- N/A -   "
7.6499998569488525, 11.485119, 0.20276865, NaN, NaN, NaN, -0.21668804, "- N/A -   "
7.700000047683716, 11.003707, 0.20451933, NaN, NaN, NaN, -0.2081426, "- N/A -   "
7.750000238418579, 11.038093, 0.20460798, NaN, NaN, NaN, -0.22767504, "- N/A -   "
7.800000429153442, 11.106867, 0.20651379, NaN, NaN, NaN, -0.21058415, "- N/A -   "
7.849999666213989, 11.278799, 0.20877415, NaN, NaN, NaN, -0.19227248, "- N/A -   "
7.8999998569488525, 11.244412, 0.2087963, NaN, NaN, NaN, -0.2130257, "- N/A -   "
7.950000047683716, 11.347572, 0.21079075, NaN, NaN, NaN, -0.2020387, "- N/A -   "
8.000000238418579, 11.416346, 0.21185446, NaN, NaN, NaN, -0.20325948, "- N/A -   "
8.050000429153442, 11.485119, 0.21287385, NaN, NaN, NaN, -0.20325948, "- N/A -   "
8.09999966621399, 11.553891, 0.21495694, NaN, NaN, NaN, -0.19471404, "- N/A -   "
8.149999856948853, 11.588279, 0.2149791, NaN, NaN, NaN, -0.21546726, "- N/A -   "
8.200000047683716, 11.657051, 0.21697354, NaN, NaN, NaN, -0.20325948, "- N/A -   "
8.250000238418579, 12.069691, 0.21719514, NaN, NaN, NaN, -0.22035037, "- N/A -   "
8.300000429153442, 11.863371, 0.21998738, NaN, NaN, NaN, -0.19593482, "- N/A -   "
8.34999966621399, 11.932144, 0.22100675, NaN, NaN, NaN, -0.20448026, "- N/A -   "
8.399999856948853, 12.413556, 0.22191533, NaN, NaN, NaN, -0.2130257, "- N/A -   "
8.450000047683716, 12.035304, 0.22384329, NaN, NaN, NaN, -0.20448026, "- N/A -   "
8.500000238418579, 12.069691, 0.2243973, NaN, NaN, NaN, -0.21424648, "- N/A -   "
8.550000429153442, 12.104077, 0.22517294, NaN, NaN, NaN, -0.22157115, "- N/A -   "
8.59999966621399, 12.241624, 0.22752196, NaN, NaN, NaN, -0.20448026, "- N/A -   "
8.649999856948853, 12.860582, 0.2278765, NaN, NaN, NaN, -0.22035037, "- N/A -   "
8.700000047683716, 12.344784, 0.23002608, NaN, NaN, NaN, -0.20936337, "- N/A -   "
8.750000238418579, 12.413556, 0.23035848, NaN, NaN, NaN, -0.22157115, "- N/A -   "
8.800000429153442, 12.379169, 0.23093466, NaN, NaN, NaN, -0.2349997, "- N/A -   "
8.84999966621399, 12.551102, 0.23297343, NaN, NaN, NaN, -0.22279193, "- N/A -   "
8.899999856948853, 12.619876, 0.23441386, NaN, NaN, NaN, -0.22279193, "- N/A -   "
8.950000047683716, 12.688649, 0.23638615, NaN, NaN, NaN, -0.2130257, "- N/A -   "
9.000000238418579, 12.757422, 0.2372504, NaN, NaN, NaN, -0.21546726, "- N/A -   "
9.050000429153442, 12.791808, 0.23802602, NaN, NaN, NaN, -0.2240127, "- N/A -   "
9.09999966621399, 12.894968, 0.24024206, NaN, NaN, NaN, -0.21546726, "- N/A -   "
9.149999856948853, 13.307608, 0.24190411, NaN, NaN, NaN, -0.20936337, "- N/A -   "
9.200000047683716, 13.066902, 0.24265757, NaN, NaN, NaN, -0.21668804, "- N/A -   "
9.250000238418579, 13.101288, 0.24425313, NaN, NaN, NaN, -0.2130257, "- N/A -   "
9.300000429153442, 13.27322, 0.24671295, NaN, NaN, NaN, -0.19349326, "- N/A -   "
9.34999966621399, 13.27322, 0.24675725, NaN, NaN, NaN, -0.2130257, "- N/A -   "
9.399999856948853, 13.341994, 0.24859658, NaN, NaN, NaN, -0.20692182, "- N/A -   "
9.450000047683716, 13.376381, 0.24903981, NaN, NaN, NaN, -0.21790881, "- N/A -   "
9.500000238418579, 13.479541, 0.25103423, NaN, NaN, NaN, -0.20325948, "- N/A -   "
9.550000429153442, 13.548314, 0.25305083, NaN, NaN, NaN, -0.19349326, "- N/A -   "
9.59999966621399, 13.582701, 0.25305083, NaN, NaN, NaN, -0.21546726, "- N/A -   "
9.649999856948853, 13.617086, 0.25520042, NaN, NaN, NaN, -0.2020387, "- N/A -   "
9.700000047683716, 13.617086, 0.2561755, NaN, NaN, NaN, -0.20570104, "- N/A -   "
9.750000238418579, 13.754633, 0.25741646, NaN, NaN, NaN, -0.20448026, "- N/A -   "
9.800000429153442, 13.823406, 0.25934443, NaN, NaN, NaN, -0.19837637, "- N/A -   "
9.84999966621399, 14.373591, 0.2594774, NaN, NaN, NaN, -0.21912959, "- N/A -   "
9.899999856948853, 13.892179, 0.26156047, NaN, NaN, NaN, -0.20692182, "- N/A -   "
9.950000047683716, 14.236045, 0.26264635, NaN, NaN, NaN, -0.21058415, "- N/A -   "
10.000000238418579, 14.064113, 0.2651948, NaN, NaN, NaN, -0.19471404, "- N/A -   "
10.050000429153442, 13.995338, 0.26534995, NaN, NaN, NaN, -0.21180493, "- N/A -   "
10.09999966621399, 14.064113, 0.26710063, NaN, NaN, NaN, -0.20570104, "- N/A -   "
10.149999856948853, 14.132885, 0.26829728, NaN, NaN, NaN, -0.20692182, "- N/A -   "
10.200000047683716, 14.132885, 0.26876265, NaN, NaN, NaN, -0.2240127, "- N/A -   "
10.250000238418579, 14.132885, 0.2696934, NaN, NaN, NaN, -0.22889581, "- N/A -   "
10.300000429153442, 14.2704315, 0.2720867, NaN, NaN, NaN, -0.21424648, "- N/A -   "
10.34999966621399, 14.304819, 0.2734607, NaN, NaN, NaN, -0.21058415, "- N/A -   "
10.399999856948853, 14.373591, 0.27461302, NaN, NaN, NaN, -0.21546726, "- N/A -   "
10.450000047683716, 14.339205, 0.27503407, NaN, NaN, NaN, -0.23133737, "- N/A -   "
10.500000238418579, 14.407979, 0.27623072, NaN, NaN, NaN, -0.2349997, "- N/A -   "
10.550000429153442, 14.511137, 0.2787349, NaN, NaN, NaN, -0.21180493, "- N/A -   "
10.59999966621399, 14.99255, 0.27906728, NaN, NaN, NaN, -0.22645426, "- N/A -   "
10.649999856948853, 14.545525, 0.281239, NaN, NaN, NaN, -0.21424648, "- N/A -   "
10.700000047683716, 14.579911, 0.28212544, NaN, NaN, NaN, -0.21912959, "- N/A -   "
10.750000238418579, 14.717457, 0.2843858, NaN, NaN, NaN, -0.20570104, "- N/A -   "
10.800000429153442, 15.267643, 0.2847847, NaN, NaN, NaN, -0.21912959, "- N/A -   "
10.84999966621399, 14.717457, 0.28691208, NaN, NaN, NaN, -0.20692182, "- N/A -   "
10.899999856948853, 15.267643, 0.28704506, NaN, NaN, NaN, -0.22645426, "- N/A -   "
10.950000047683716, 14.889391, 0.28999242, NaN, NaN, NaN, -0.19959715, "- N/A -   "
11.000000238418579, 14.855003, 0.2911004, NaN, NaN, NaN, -0.20692182, "- N/A -   "
11.050000429153442, 15.30203, 0.29231927, NaN, NaN, NaN, -0.20936337, "- N/A -   "
11.09999966621399, 14.820617, 0.29349378, NaN, NaN, NaN, -0.21424648, "- N/A -   "
11.149999856948853, 14.923777, 0.29462397, NaN, NaN, NaN, -0.21668804, "- N/A -   "
11.200000047683716, 14.889391, 0.2972832, NaN, NaN, NaN, -0.18738937, "- N/A -   "
11.250000238418579, 14.855003, 0.29734972, NaN, NaN, NaN, -0.20692182, "- N/A -   "
11.300000429153442, 14.786231, 0.29879013, NaN, NaN, NaN, -0.20448026, "- N/A -   "
11.34999966621399, 14.855003, 0.30020842, NaN, NaN, NaN, -0.20570104, "- N/A -   "
11.399999856948853, 14.820617, 0.30100617, NaN, NaN, NaN, -0.21546726, "- N/A -   "
11.450000047683716, 14.923777, 0.30328873, NaN, NaN, NaN, -0.20448026, "- N/A -   "
11.500000238418579, 15.439575, 0.3037984, NaN, NaN, NaN, -0.21912959, "- N/A -   "
11.550000429153442, 14.923777, 0.3058815, NaN, NaN, NaN, -0.20692182, "- N/A -   "
11.59999966621399, 15.19887, 0.307056, NaN, NaN, NaN, -0.20692182, "- N/A -   "
11.649999856948853, 15.0269375, 0.30949366, NaN, NaN, NaN, -0.19471404, "- N/A -   "
11.700000047683716, 14.958163, 0.30964878, NaN, NaN, NaN, -0.21180493, "- N/A -   "
11.750000238418579, 14.958163, 0.31146595, NaN, NaN, NaN, -0.20448026, "- N/A -   "
11.800000429153442, 14.958163, 0.31241885, NaN, NaN, NaN, -0.21058415, "- N/A -   "
11.84999966621399, 14.923777, 0.31264046, NaN, NaN, NaN, -0.22523348, "- N/A -   "
11.899999856948853, 14.820617, 0.31319445, NaN, NaN, NaN, -0.23744126, "- N/A -   "
11.950000047683716, 14.889391, 0.31456843, NaN, NaN, NaN, -0.23744126, "- N/A -   "
12.000000238418579, 14.99255, 0.3164521, NaN, NaN, NaN, -0.23133737, "- N/A -   "
12.050000429153442, 14.958163, 0.3187346, NaN, NaN, NaN, -0.21546726, "- N/A -   "
12.09999966621399, 14.923777, 0.31915563, NaN, NaN, NaN, -0.23011659, "- N/A -   "
12.149999856948853, 14.99255, 0.3213717, NaN, NaN, NaN, -0.20448026, "- N/A -   "
12.200000047683716, 14.923777, 0.32281214, NaN, NaN, NaN, -0.20081793, "- N/A -   "
12.250000238418579, 14.855003, 0.32281214, NaN, NaN, NaN, -0.22279193, "- N/A -   "
12.300000429153442, 14.786231, 0.3249617, NaN, NaN, NaN, -0.2130257, "- N/A -   "
12.34999966621399, 14.786231, 0.32551572, NaN, NaN, NaN, -0.22157115, "- N/A -   "
12.399999856948853, 14.820617, 0.3275988, NaN, NaN, NaN, -0.19837637, "- N/A -   "
12.450000047683716, 14.717457, 0.32886195, NaN, NaN, NaN, -0.20081793, "- N/A -   "
12.500000238418579, 15.164483, 0.32926086, NaN, NaN, NaN, -0.21424648, "- N/A -   "
12.550000429153442, 14.614297, 0.33116665, NaN, NaN, NaN, -0.20570104, "- N/A -   "
12.59999966621399, 15.1300955, 0.33121097, NaN, NaN, NaN, -0.22645426, "- N/A -   "
12.649999856948853, 14.6486845, 0.33406967, NaN, NaN, NaN, -0.20325948, "- N/A -   "
12.700000047683716, 14.614297, 0.33535498, NaN, NaN, NaN, -0.20448026, "- N/A -   "
12.750000238418579, 15.0269375, 0.3362857, NaN, NaN, NaN, -0.21180493, "- N/A -   "
12.800000429153442, 14.511137, 0.3377705, NaN, NaN, NaN, -0.21180493, "- N/A -   "
12.84999966621399, 14.442365, 0.3392109, NaN, NaN, NaN, -0.20570104, "- N/A -   "
12.899999856948853, 14.511137, 0.34160423, NaN, NaN, NaN, -0.18983093, "- N/A -   "
12.950000047683716, 14.476751, 0.34164858, NaN, NaN, NaN, -0.20936337, "- N/A -   "
13.000000238418579, 14.442365, 0.3431998, NaN, NaN, NaN, -0.20448026, "- N/A -   "
13.050000429153442, 14.407979, 0.34435213, NaN, NaN, NaN, -0.20570104, "- N/A -   "
13.09999966621399, 14.373591, 0.34472886, NaN, NaN, NaN, -0.21546726, "- N/A -   "
13.149999856948853, 14.304819, 0.345438, NaN, NaN, NaN, -0.22279193, "- N/A -   "
13.200000047683716, 14.407979, 0.3477427, NaN, NaN, NaN, -0.21424648, "- N/A -   "
13.250000238418579, 14.614297, 0.34927177, NaN, NaN, NaN, -0.21058415, "- N/A -   "
13.300000429153442, 14.442365, 0.35035762, NaN, NaN, NaN, -0.21424648, "- N/A -   "
13.34999966621399, 14.511137, 0.3528618, NaN, NaN, NaN, -0.19349326, "- N/A -   "
13.399999856948853, 14.442365, 0.3540363, NaN, NaN, NaN, -0.19837637, "- N/A -   "
13.450000047683716, 14.889391, 0.35408062, NaN, NaN, NaN, -0.21912959, "- N/A -   "
13.500000238418579, 14.304819, 0.3564296, NaN, NaN, NaN, -0.20448026, "- N/A -   "
13.550000429153442, 14.236045, 0.35702798, NaN, NaN, NaN, -0.21546726, "- N/A -   "
13.59999966621399, 14.167273, 0.35736036, NaN, NaN, NaN, -0.23133737, "- N/A -   "
13.649999856948853, 14.064113, 0.35822463, NaN, NaN, NaN, -0.23622048, "- N/A -   "
13.700000047683716, 14.132885, 0.36064014, NaN, NaN, NaN, -0.22035037, "- N/A -   "
13.750000238418579, 14.098498, 0.36234647, NaN, NaN, NaN, -0.21546726, "- N/A -   "
13.800000429153442, 14.098498, 0.3632107, NaN, NaN, NaN, -0.22279193, "- N/A -   "
13.84999966621399, 14.167273, 0.36544895, NaN, NaN, NaN, -0.19959715, "- N/A -   "
13.899999856948853, 14.098498, 0.3670445, NaN, NaN, NaN, -0.19471404, "- N/A -   "
13.950000047683716, 13.995338, 0.3670445, NaN, NaN, NaN, -0.21546726, "- N/A -   "
14.000000238418579, 13.926566, 0.36855143, NaN, NaN, NaN, -0.21424648, "- N/A -   "
14.050000429153442, 13.892179, 0.36963728, NaN, NaN, NaN, -0.21912959, "- N/A -   "
14.09999966621399, 13.857793, 0.36996967, NaN, NaN, NaN, -0.23622048, "- N/A -   "
14.149999856948853, 13.960953, 0.3730057, NaN, NaN, NaN, -0.1971556, "- N/A -   "
14.200000047683716, 13.789021, 0.37324944, NaN, NaN, NaN, -0.21668804, "- N/A -   "
14.250000238418579, 13.720246, 0.37548766, NaN, NaN, NaN, -0.20448026, "- N/A -   "
14.300000429153442, 13.651473, 0.37566495, NaN, NaN, NaN, -0.22279193, "- N/A -   "
14.34999966621399, 13.685861, 0.37812474, NaN, NaN, NaN, -0.20081793, "- N/A -   "
14.399999856948853, 13.617086, 0.3796317, NaN, NaN, NaN, -0.19959715, "- N/A -   "
14.450000047683716, 14.029726, 0.37987542, NaN, NaN, NaN, -0.21668804, "- N/A -   "
14.500000238418579, 13.445154, 0.38211367, NaN, NaN, NaN, -0.20448026, "- N/A -   "
14.550000429153442, 13.857793, 0.38229093, NaN, NaN, NaN, -0.22035037, "- N/A -   "
14.59999966621399, 13.376381, 0.38519394, NaN, NaN, NaN, -0.18983093, "- N/A -   "
14.649999856948853, 13.238834, 0.38588095, NaN, NaN, NaN, -0.20081793, "- N/A -   "
14.700000047683716, 13.651473, 0.38636845, NaN, NaN, NaN, -0.21546726, "- N/A -   "
14.750000238418579, 13.101288, 0.3883186, NaN, NaN, NaN, -0.20448026, "- N/A -   "
14.800000429153442, 12.998128, 0.38860667, NaN, NaN, NaN, -0.2240127, "- N/A -   "
14.84999966621399, 12.894968, 0.38907203, NaN, NaN, NaN, -0.23744126, "- N/A -   "
14.899999856948853, 12.894968, 0.3902244, NaN, NaN, NaN, -0.24110359, "- N/A -   "
14.950000047683716, 12.894968, 0.39239612, NaN, NaN, NaN, -0.22767504, "- N/A -   "
15.000000238418579, 12.894968, 0.3946122, NaN, NaN, NaN, -0.21180493, "- N/A -   "
15.049999475479126, 12.791808, 0.39609694, NaN, NaN, NaN, -0.2020387, "- N/A -   "
15.100000619888306, 12.826196, 0.3982465, NaN, NaN, NaN, -0.19471404, "- N/A -   "
15.149999856948853, 12.757422, 0.39826867, NaN, NaN, NaN, -0.21668804, "- N/A -   "
15.1999990940094, 12.757422, 0.4003739, NaN, NaN, NaN, -0.2020387, "- N/A -   "
15.250000238418579, 12.619876, 0.4009944, NaN, NaN, NaN, -0.2130257, "- N/A -   "
15.299999475479126, 12.585489, 0.40263426, NaN, NaN, NaN, -0.20325948, "- N/A -   "
15.350000619888306, 12.688649, 0.4048282, NaN, NaN, NaN, -0.18861015, "- N/A -   "
15.399999856948853, 12.516716, 0.4048725, NaN, NaN, NaN, -0.20936337, "- N/A -   "
15.4499990940094, 12.447944, 0.40635723, NaN, NaN, NaN, -0.2081426, "- N/A -   "
15.500000238418579, 12.482329, 0.40699992, NaN, NaN, NaN, -0.22157115, "- N/A -   "
15.549999475479126, 12.447944, 0.40897217, NaN, NaN, NaN, -0.20570104, "- N/A -   "
15.600000619888306, 12.516716, 0.4113212, NaN, NaN, NaN, -0.19349326, "- N/A -   "
15.649999856948853, 12.447944, 0.4113212, NaN, NaN, NaN, -0.21546726, "- N/A -   "
15.6999990940094, 12.379169, 0.4131162, NaN, NaN, NaN, -0.21058415, "- N/A -   "
15.750000238418579, 12.344784, 0.41382533, NaN, NaN, NaN, -0.22157115, "- N/A -   "
15.799999475479126, 12.310396, 0.41413558, NaN, NaN, NaN, -0.23622048, "- N/A -   "
15.850000619888306, 12.413556, 0.41683915, NaN, NaN, NaN, -0.19959715, "- N/A -   "
15.899999856948853, 12.310396, 0.41757047, NaN, NaN, NaN, -0.20936337, "- N/A -   "
15.9499990940094, 12.826196, 0.41914386, NaN, NaN, NaN, -0.20570104, "- N/A -   "
16.00000023841858, 12.27601, 0.42020756, NaN, NaN, NaN, -0.21180493, "- N/A -   "
16.049999475479126, 12.757422, 0.42093888, NaN, NaN, NaN, -0.22157115, "- N/A -   "
16.100000619888306, 12.344784, 0.42375323, NaN, NaN, NaN, -0.18983093, "- N/A -   "
16.149999856948853, 12.241624, 0.4238862, NaN, NaN, NaN, -0.21058415, "- N/A -   "
16.1999990940094, 12.27601, 0.4256369, NaN, NaN, NaN, -0.20692182, "- N/A -   "
16.25000023841858, 12.207237, 0.42641252, NaN, NaN, NaN, -0.21790881, "- N/A -   "
16.299999475479126, 12.27601, 0.4287615, NaN, NaN, NaN, -0.19593482, "- N/A -   "
16.350000619888306, 12.207237, 0.43020195, NaN, NaN, NaN, -0.19959715, "- N/A -   "
16.399999856948853, 12.688649, 0.430623, NaN, NaN, NaN, -0.21668804, "- N/A -   "
16.4499990940094, 12.17285, 0.4326839, NaN, NaN, NaN, -0.20448026, "- N/A -   "
16.50000023841858, 12.104077, 0.4330385, NaN, NaN, NaN, -0.21912959, "- N/A -   "
16.549999475479126, 12.069691, 0.43343738, NaN, NaN, NaN, -0.23377892, "- N/A -   "
16.600000619888306, 12.035304, 0.43441245, NaN, NaN, NaN, -0.23866203, "- N/A -   "
16.649999856948853, 12.069691, 0.43662852, NaN, NaN, NaN, -0.22523348, "- N/A -   "
16.6999990940094, 12.104077, 0.43877807, NaN, NaN, NaN, -0.2130257, "- N/A -   "
16.75000023841858, 12.585489, 0.4399969, NaN, NaN, NaN, -0.2130257, "- N/A -   "
16.799999475479126, 12.138464, 0.44258967, NaN, NaN, NaN, -0.19227248, "- N/A -   "
16.850000619888306, 12.000917, 0.44270048, NaN, NaN, NaN, -0.21058415, "- N/A -   "
16.899999856948853, 12.000917, 0.44440684, NaN, NaN, NaN, -0.20570104, "- N/A -   "
16.9499990940094, 11.966531, 0.44547054, NaN, NaN, NaN, -0.21180493, "- N/A -   "
17.00000023841858, 11.897758, 0.4456478, NaN, NaN, NaN, -0.22645426, "- N/A -   "
17.049999475479126, 11.863371, 0.44615752, NaN, NaN, NaN, -0.23255815, "- N/A -   "
17.100000619888306, 11.897758, 0.44730988, NaN, NaN, NaN, -0.23744126, "- N/A -   "
17.149999856948853, 11.897758, 0.4494373, NaN, NaN, NaN, -0.22523348, "- N/A -   "
17.1999990940094, 11.863371, 0.45147604, NaN, NaN, NaN, -0.21546726, "- N/A -   "
17.25000023841858, 12.447944, 0.4519414, NaN, NaN, NaN, -0.22767504, "- N/A -   "
17.299999475479126, 11.966531, 0.45519903, NaN, NaN, NaN, -0.18372704, "- N/A -   "
17.350000619888306, 11.863371, 0.45562008, NaN, NaN, NaN, -0.1971556, "- N/A -   "
17.399999856948853, 11.794598, 0.45562008, NaN, NaN, NaN, -0.21912959, "- N/A -   "
17.4499990940094, 11.760211, 0.45765883, NaN, NaN, NaN, -0.20692182, "- N/A -   "
17.50000023841858, 11.725825, 0.4580577, NaN, NaN, NaN, -0.22157115, "- N/A -   "
17.549999475479126, 11.863371, 0.46067268, NaN, NaN, NaN, -0.20936337, "- N/A -   "
17.600000619888306, 11.760211, 0.4619358, NaN, NaN, NaN, -0.20692182, "- N/A -   "
17.649999856948853, 12.207237, 0.46282223, NaN, NaN, NaN, -0.21424648, "- N/A -   "
17.6999990940094, 11.725825, 0.46481666, NaN, NaN, NaN, -0.2020387, "- N/A -   "
17.75000023841858, 12.241624, 0.46521556, NaN, NaN, NaN, -0.24354514, "- N/A -   "
17.799999475479126, 11.760211, 0.46836236, NaN, NaN, NaN, -0.19959715, "- N/A -   "
17.850000619888306, 12.241624, 0.4687391, NaN, NaN, NaN, -0.21668804, "- N/A -   "
17.899999856948853, 11.725825, 0.4706449, NaN, NaN, NaN, -0.20692182, "- N/A -   "
17.9499990940094, 12.207237, 0.47157562, NaN, NaN, NaN, -0.23866203, "- N/A -   "
18.00000023841858, 11.725825, 0.4746116, NaN, NaN, NaN, -0.19959715, "- N/A -   "
18.049999475479126, 12.207237, 0.47487754, NaN, NaN, NaN, -0.21668804, "- N/A -   "
18.100000619888306, 11.657051, 0.47711575, NaN, NaN, NaN, -0.20325948, "- N/A -   "
18.149999856948853, 11.622665, 0.47769192, NaN, NaN, NaN, -0.2130257, "- N/A -   "
18.1999990940094, 11.553891, 0.47857833, NaN, NaN, NaN, -0.2630776, "- N/A -   "
18.25000023841858, 11.588279, 0.48123762, NaN, NaN, NaN, -0.25697368, "- N/A -   "
18.299999475479126, 11.657051, 0.48374173, NaN, NaN, NaN, -0.23133737, "- N/A -   "
18.350000619888306, 11.553891, 0.4845395, NaN, NaN, NaN, -0.23622048, "- N/A -   "
18.399999856948853, 11.588279, 0.48624587, NaN, NaN, NaN, -0.23255815, "- N/A -   "
18.4499990940094, 12.069691, 0.4878636, NaN, NaN, NaN, -0.22889581, "- N/A -   "
18.50000023841858, 11.553891, 0.49012396, NaN, NaN, NaN, -0.2130257, "- N/A -   "
18.549999475479126, 11.450731, 0.49070016, NaN, NaN, NaN, -0.22523348, "- N/A -   "
18.600000619888306, 11.450731, 0.49214056, NaN, NaN, NaN, -0.22645426, "- N/A -   "
18.649999856948853, 11.553891, 0.4936918, NaN, NaN, NaN, -0.22157115, "- N/A -   "
18.6999990940094, 11.416346, 0.49581924, NaN, NaN, NaN, -0.2081426, "- N/A -   "
18.75000023841858, 11.897758, 0.49646184, NaN, NaN, NaN, -0.21790881, "- N/A -   "
18.799999475479126, 11.450731, 0.49949783, NaN, NaN, NaN, -0.18494782, "- N/A -   "
18.850000619888306, 11.347572, 0.4999189, NaN, NaN, NaN, -0.20081793, "- N/A -   "
18.899999856948853, 11.657051, 0.49994108, NaN, NaN, NaN, -0.22157115, "- N/A -   "
18.9499990940094, 11.175639, 0.50226796, NaN, NaN, NaN, -0.21424648, "- N/A -   "
19.00000023841858, 11.175639, 0.5027111, NaN, NaN, NaN, -0.23744126, "- N/A -   "
19.049999475479126, 11.278799, 0.5059466, NaN, NaN, NaN, -0.20448026, "- N/A -   "
19.100000619888306, 11.691438, 0.5064341, NaN, NaN, NaN, -0.22035037, "- N/A -   "
19.149999856948853, 11.1412525, 0.50856155, NaN, NaN, NaN, -0.2081426, "- N/A -   "
19.1999990940094, 11.622665, 0.50873876, NaN, NaN, NaN, -0.24110359, "- N/A -   "
19.25000023841858, 11.1412525, 0.51226234, NaN, NaN, NaN, -0.19593482, "- N/A -   "
19.299999475479126, 11.038093, 0.5127277, NaN, NaN, NaN, -0.21180493, "- N/A -   "
19.350000619888306, 11.038093, 0.51454484, NaN, NaN, NaN, -0.20448026, "- N/A -   "
19.399999856948853, 10.934933, 0.5150767, NaN, NaN, NaN, -0.21912959, "- N/A -   "
19.4499990940094, 11.003707, 0.5178025, NaN, NaN, NaN, -0.19837637, "- N/A -   "
19.50000023841858, 10.900547, 0.518977, NaN, NaN, NaN, -0.1971556, "- N/A -   "
19.549999475479126, 11.381959, 0.5191764, NaN, NaN, NaN, -0.2349997, "- N/A -   "
19.600000619888306, 10.831773, 0.5218578, NaN, NaN, NaN, -0.21912959, "- N/A -   "
19.649999856948853, 10.86616, 0.5232761, NaN, NaN, NaN, -0.22035037, "- N/A -   "
19.6999990940094, 10.831773, 0.52531487, NaN, NaN, NaN, -0.20692182, "- N/A -   "
19.75000023841858, 10.728614, 0.5266223, NaN, NaN, NaN, -0.20692182, "- N/A -   "
19.799999475479126, 10.728614, 0.5276639, NaN, NaN, NaN, -0.21180493, "- N/A -   "
19.850000619888306, 10.7630005, 0.5298799, NaN, NaN, NaN, -0.19837637, "- N/A -   "
19.899999856948853, 10.694227, 0.5313425, NaN, NaN, NaN, -0.19471404, "- N/A -   "
19.9499990940094, 10.625454, 0.5313425, NaN, NaN, NaN, -0.22157115, "- N/A -   "
20.00000023841858, 10.556681, 0.5339353, NaN, NaN, NaN, -0.21790881, "- N/A -   "
20.049999475479126, 10.522294, 0.5348882, NaN, NaN, NaN, -0.2240127, "- N/A -   "
20.100000619888306, 10.522294, 0.53621787, NaN, NaN, NaN, -0.2240127, "- N/A -   "
20.149999856948853, 10.453521, 0.53810143, NaN, NaN, NaN, -0.21912959, "- N/A -   "
20.1999990940094, 10.419134, 0.5400516, NaN, NaN, NaN, -0.20936337, "- N/A -   "
20.25000023841858, 10.384748, 0.54053915, NaN, NaN, NaN, -0.22279193, "- N/A -   "
20.299999475479126, 10.453521, 0.54342, NaN, NaN, NaN, -0.20081793, "- N/A -   "
20.350000619888306, 10.315974, 0.5444615, NaN, NaN, NaN, -0.20448026, "- N/A -   "
20.399999856948853, 10.7630005, 0.54472744, NaN, NaN, NaN, -0.24232437, "- N/A -   "
20.4499990940094, 10.212814, 0.5472759, NaN, NaN, NaN, -0.22645426, "- N/A -   "
20.50000023841858, 10.109656, 0.54814017, NaN, NaN, NaN, -0.22767504, "- N/A -   "
20.549999475479126, 10.178429, 0.55028975, NaN, NaN, NaN, -0.21790881, "- N/A -   "
20.600000619888306, 10.591067, 0.5518853, NaN, NaN, NaN, -0.21790881, "- N/A -   "
20.649999856948853, 10.040882, 0.5533257, NaN, NaN, NaN, -0.21424648, "- N/A -   "
20.6999990940094, 10.040882, 0.5549213, NaN, NaN, NaN, -0.20570104, "- N/A -   "
20.75000023841858, 9.972109, 0.5568936, NaN, NaN, NaN, -0.19471404, "- N/A -   "
20.799999475479126, 9.86895, 0.5568936, NaN, NaN, NaN, -0.21912959, "- N/A -   "
20.850000619888306, 9.834562, 0.55930907, NaN, NaN, NaN, -0.21790881, "- N/A -   "
20.899999856948853, 10.315974, 0.56035066, NaN, NaN, NaN, -0.22279193, "- N/A -   "
20.9499990940094, 9.765789, 0.5631871, NaN, NaN, NaN, -0.19227248, "- N/A -   "
21.00000023841858, 9.66263, 0.563298, NaN, NaN, NaN, -0.21058415, "- N/A -   "
21.049999475479126, 9.66263, 0.5652924, NaN, NaN, NaN, -0.21668804, "- N/A -   "
21.100000619888306, 9.55947, 0.56659985, NaN, NaN, NaN, -0.21912959, "- N/A -   "
21.149999856948853, 9.55947, 0.5682841, NaN, NaN, NaN, -0.21546726, "- N/A -   "
21.1999990940094, 9.55947, 0.5695694, NaN, NaN, NaN, -0.21790881, "- N/A -   "
21.25000023841858, 9.45631, 0.57180756, NaN, NaN, NaN, -0.2081426, "- N/A -   "
21.299999475479126, 9.45631, 0.57318157, NaN, NaN, NaN, -0.20448026, "- N/A -   "
21.350000619888306, 9.35315, 0.57548624, NaN, NaN, NaN, -0.19349326, "- N/A -   "
21.399999856948853, 9.284378, 0.5755749, NaN, NaN, NaN, -0.21424648, "- N/A -   "
21.4499990940094, 9.24999, 0.5775693, NaN, NaN, NaN, -0.20448026, "- N/A -   "
21.50000023841858, 9.146831, 0.5785001, NaN, NaN, NaN, -0.2130257, "- N/A -   "
21.549999475479126, 9.628243, 0.5796303, NaN, NaN, NaN, -0.24232437, "- N/A -   "
21.600000619888306, 9.181217, 0.582356, NaN, NaN, NaN, -0.2020387, "- N/A -   "
21.649999856948853, 9.628243, 0.5824225, NaN, NaN, NaN, -0.22645426, "- N/A -   "
21.6999990940094, 9.043672, 0.58477145, NaN, NaN, NaN, -0.21424648, "- N/A -   "
21.75000023841858, 8.974898, 0.58530337, NaN, NaN, NaN, -0.23622048, "- N/A -   "
21.799999475479126, 9.009285, 0.58853877, NaN, NaN, NaN, -0.20081793, "- N/A -   "
21.850000619888306, 8.940512, 0.58902633, NaN, NaN, NaN, -0.21424648, "- N/A -   "
21.899999856948853, 8.906125, 0.5902895, NaN, NaN, NaN, -0.24232437, "- N/A -   "
21.9499990940094, 8.871738, 0.5921731, NaN, NaN, NaN, -0.23255815, "- N/A -   "
22.00000023841858, 8.940512, 0.59430057, NaN, NaN, NaN, -0.22157115, "- N/A -   "
22.049999475479126, 9.35315, 0.5958518, NaN, NaN, NaN, -0.2240127, "- N/A -   "
22.100000619888306, 8.837352, 0.5977576, NaN, NaN, NaN, -0.2130257, "- N/A -   "
22.149999856948853, 8.837352, 0.5994639, NaN, NaN, NaN, -0.19959715, "- N/A -   "
22.1999990940094, 8.768579, 0.6013032, NaN, NaN, NaN, -0.19227248, "- N/A -   "
22.25000023841858, 8.699805, 0.6013032, NaN, NaN, NaN, -0.21424648, "- N/A -   "
22.299999475479126, 8.699805, 0.60327554, NaN, NaN, NaN, -0.20448026, "- N/A -   "
22.350000619888306, 8.631032, 0.60365224, NaN, NaN, NaN, -0.21912959, "- N/A -   "
22.399999856948853, 8.665419, 0.6062893, NaN, NaN, NaN, -0.19593482, "- N/A -   "
22.4499990940094, 8.56226, 0.6075747, NaN, NaN, NaN, -0.19837637, "- N/A -   "
22.50000023841858, 9.043672, 0.6078406, NaN, NaN, NaN, -0.23377892, "- N/A -   "
22.549999475479126, 8.493486, 0.6104334, NaN, NaN, NaN, -0.21424648, "- N/A -   "
22.600000619888306, 8.459099, 0.6113641, NaN, NaN, NaN, -0.21912959, "- N/A -   "
22.649999856948853, 8.424713, 0.61360234, NaN, NaN, NaN, -0.21180493, "- N/A -   "
22.6999990940094, 8.837352, 0.6150871, NaN, NaN, NaN, -0.21180493, "- N/A -   "
22.75000023841858, 8.3903265, 0.6163059, NaN, NaN, NaN, -0.2130257, "- N/A -   "
22.799999475479126, 8.424713, 0.6186549, NaN, NaN, NaN, -0.19593482, "- N/A -   "
22.850000619888306, 8.355939, 0.6199403, NaN, NaN, NaN, -0.19959715, "- N/A -   "
22.899999856948853, 8.802965, 0.62016183, NaN, NaN, NaN, -0.21790881, "- N/A -   "
22.9499990940094, 8.25278, 0.6224222, NaN, NaN, NaN, -0.20692182, "- N/A -   "
23.00000023841858, 8.184007, 0.6230205, NaN, NaN, NaN, -0.21424648, "- N/A -   "
23.049999475479126, 8.25278, 0.62521446, NaN, NaN, NaN, -0.22157115, "- N/A -   "
23.100000619888306, 8.218393, 0.6268322, NaN, NaN, NaN, -0.2130257, "- N/A -   "
23.149999856948853, 8.14962, 0.62858284, NaN, NaN, NaN, -0.20936337, "- N/A -   "
23.1999990940094, 8.115233, 0.62924767, NaN, NaN, NaN, -0.21912959, "- N/A -   "
23.25000023841858, 8.184007, 0.63153017, NaN, NaN, NaN, -0.21180493, "- N/A -   "
23.299999475479126, 8.080847, 0.6331257, NaN, NaN, NaN, -0.20081793, "- N/A -   "
23.350000619888306, 8.3903265, 0.63314784, NaN, NaN, NaN, -0.2349997, "- N/A -   "
23.399999856948853, 8.04646, 0.6358293, NaN, NaN, NaN, -0.22767504, "- N/A -   "
23.4499990940094, 8.04646, 0.6371146, NaN, NaN, NaN, -0.22889581, "- N/A -   "
23.50000023841858, 8.0120735, 0.6392642, NaN, NaN, NaN, -0.21668804, "- N/A -   "
23.549999475479126, 8.0120735, 0.64125866, NaN, NaN, NaN, -0.20570104, "- N/A -   "
23.600000619888306, 7.9433007, 0.6417018, NaN, NaN, NaN, -0.22157115, "- N/A -   "
23.649999856948853, 7.977687, 0.6441838, NaN, NaN, NaN, -0.1971556, "- N/A -   "
23.6999990940094, 7.9433007, 0.6456243, NaN, NaN, NaN, -0.19593482, "- N/A -   "
23.75000023841858, 8.321553, 0.64564645, NaN, NaN, NaN, -0.21790881, "- N/A -   "
23.799999475479126, 7.840141, 0.6477516, NaN, NaN, NaN, -0.20570104, "- N/A -   "
23.850000619888306, 8.355939, 0.648217, NaN, NaN, NaN, -0.24720748, "- N/A -   "
23.899999856948853, 7.874528, 0.65169626, NaN, NaN, NaN, -0.19959715, "- N/A -   "
23.9499990940094, 8.25278, 0.6520286, NaN, NaN, NaN, -0.21790881, "- N/A -   "
24.00000023841858, 7.7713675, 0.6544441, NaN, NaN, NaN, -0.20081793, "- N/A -   "
24.049999475479126, 7.7025948, 0.65530837, NaN, NaN, NaN, -0.20325948, "- N/A -   "
24.100000619888306, 7.7713675, 0.65657157, NaN, NaN, NaN, -0.20448026, "- N/A -   "
24.149999856948853, 7.7025948, 0.65818924, NaN, NaN, NaN, -0.20448026, "- N/A -   "
24.1999990940094, 8.14962, 0.6591865, NaN, NaN, NaN, -0.23255815, "- N/A -   "
24.25000023841858, 7.6338215, 0.6610701, NaN, NaN, NaN, -0.2240127, "- N/A -   "
24.299999475479126, 7.7025948, 0.66352993, NaN, NaN, NaN, -0.19349326, "- N/A -   "
24.350000619888306, 7.599435, 0.6643942, NaN, NaN, NaN, -0.19959715, "- N/A -   "
24.399999856948853, 8.04646, 0.66488177, NaN, NaN, NaN, -0.23744126, "- N/A -   "
24.4499990940094, 7.5650477, 0.6674524, NaN, NaN, NaN, -0.21546726, "- N/A -   "
24.50000023841858, 7.496275, 0.6686269, NaN, NaN, NaN, -0.21668804, "- N/A -   "
24.549999475479126, 7.5306616, 0.6708873, NaN, NaN, NaN, -0.20570104, "- N/A -   "
24.600000619888306, 7.977687, 0.67179585, NaN, NaN, NaN, -0.21424648, "- N/A -   "
24.649999856948853, 7.4618883, 0.6732806, NaN, NaN, NaN, -0.21058415, "- N/A -   "
24.6999990940094, 7.977687, 0.6737903, NaN, NaN, NaN, -0.24354514, "- N/A -   "
24.75000023841858, 7.4618883, 0.6773138, NaN, NaN, NaN, -0.18983093, "- N/A -   "
24.799999475479126, 7.3931155, 0.6775354, NaN, NaN, NaN, -0.2081426, "- N/A -   "
24.850000619888306, 7.874528, 0.6785769, NaN, NaN, NaN, -0.24720748, "- N/A -   "
24.899999856948853, 7.3587284, 0.68085945, NaN, NaN, NaN, -0.23255815, "- N/A -   "
24.9499990940094, 7.4275017, 0.68329716, NaN, NaN, NaN, -0.21790881, "- N/A -   "
25.00000023841858, 7.805754, 0.6849591, NaN, NaN, NaN, -0.21424648, "- N/A -   "
25.049999475479126, 7.3243423, 0.686045, NaN, NaN, NaN, -0.22035037, "- N/A -   "
25.100000619888306, 7.3587284, 0.6884162, NaN, NaN, NaN, -0.1971556, "- N/A -   "
25.149999856948853, 7.2555685, 0.6899231, NaN, NaN, NaN, -0.19349326, "- N/A -   "
25.1999990940094, 7.1867957, 0.6899231, NaN, NaN, NaN, -0.21546726, "- N/A -   "
25.25000023841858, 7.1867957, 0.6919619, NaN, NaN, NaN, -0.20570104, "- N/A -   "
25.299999475479126, 7.1524096, 0.6921835, NaN, NaN, NaN, -0.22157115, "- N/A -   "
25.350000619888306, 7.1867957, 0.69466543, NaN, NaN, NaN, -0.2081426, "- N/A -   "
25.389999628067017, 0.13754633, 0.6963275, NaN, NaN, NaN, -0.19349326, "- N/A -   "