File: BME243_Tues_FA21_LF_Letterman_10.csv
"Time", "Load (N)", "Position (mm)", "Strain(Axial) (in)", "Strain(Transverse) (in)", "Auxiliary ()", "Control Out (V)", "Stress (MPa)"
0.0, 0.4470256, 0.0010637044, NaN, NaN, NaN, -0.22767504, "- N/A -   "
0.050000011920928955, 0.0, 0.002481977, NaN, NaN, NaN, -0.20936337, "- N/A -   "
0.10000002384185791, 0.0, 0.0035013603, NaN, NaN, NaN, -0.2130257, "- N/A -   "
0.15000003576278687, 0.034386583, 0.0058060535, NaN, NaN, NaN, -0.1971556, "- N/A -   "
0.19999998807907104, 0.068773165, 0.006625992, NaN, NaN, NaN, -0.2081426, "- N/A -   "
0.2500000596046448, 0.034386583, 0.00782266, NaN, NaN, NaN, -0.2081426, "- N/A -   "
0.30000001192092896, 0.034386583, 0.009529019, NaN, NaN, NaN, -0.20570104, "- N/A -   "
0.34999996423721313, 0.10315975, 0.011745069, NaN, NaN, NaN, -0.1910517, "- N/A -   "
0.40000003576278687, 0.068773165, 0.012897416, NaN, NaN, NaN, -0.19349326, "- N/A -   "
0.44999998807907104, 0.10315975, 0.012897416, NaN, NaN, NaN, -0.21546726, "- N/A -   "
0.5000000596046448, 0.068773165, 0.014227047, NaN, NaN, NaN, -0.2130257, "- N/A -   "
0.550000011920929, 0.10315975, 0.015977727, NaN, NaN, NaN, -0.20936337, "- N/A -   "
0.5999999642372131, 0.17193292, 0.018636988, NaN, NaN, NaN, -0.18006471, "- N/A -   "
0.6500000357627869, 0.13754633, 0.019346125, NaN, NaN, NaN, -0.19227248, "- N/A -   "
0.699999988079071, 0.10315975, 0.019346125, NaN, NaN, NaN, -0.21424648, "- N/A -   "
0.7500000596046448, 0.13754633, 0.019479087, NaN, NaN, NaN, -0.2349997, "- N/A -   "
0.800000011920929, 0.10315975, 0.0200331, NaN, NaN, NaN, -0.24964903, "- N/A -   "
0.8499999642372131, 0.10315975, 0.021274088, NaN, NaN, NaN, -0.25331137, "- N/A -   "
0.9000000357627869, 0.10315975, 0.023091251, NaN, NaN, NaN, -0.24964903, "- N/A -   "
0.949999988079071, 0.13754633, 0.025816992, NaN, NaN, NaN, -0.22035037, "- N/A -   "
1.0000000596046448, 0.13754633, 0.027567673, NaN, NaN, NaN, -0.21058415, "- N/A -   "
1.050000011920929, 0.13754633, 0.02880866, NaN, NaN, NaN, -0.20936337, "- N/A -   "
1.0999999642372131, 0.2063195, 0.031002551, NaN, NaN, NaN, -0.19471404, "- N/A -   "
1.1500000357627869, 0.17193292, 0.03188897, NaN, NaN, NaN, -0.2020387, "- N/A -   "
1.199999988079071, 0.6877317, 0.0322657, NaN, NaN, NaN, -0.21790881, "- N/A -   "
1.2499999403953552, 0.13754633, 0.034237985, NaN, NaN, NaN, -0.20692182, "- N/A -   "
1.3000001311302185, 0.17193292, 0.034969285, NaN, NaN, NaN, -0.21424648, "- N/A -   "
1.3500000834465027, 0.24070609, 0.037052367, NaN, NaN, NaN, -0.20081793, "- N/A -   "
1.4000000357627869, 0.13754633, 0.038382, NaN, NaN, NaN, -0.2020387, "- N/A -   "
1.449999988079071, 0.75650483, 0.038603608, NaN, NaN, NaN, -0.22035037, "- N/A -   "
1.4999999403953552, 0.17193292, 0.041196387, NaN, NaN, NaN, -0.19837637, "- N/A -   "
1.5500001311302185, 0.24070609, 0.043767005, NaN, NaN, NaN, -0.18128549, "- N/A -   "
1.6000000834465027, 0.17193292, 0.04443182, NaN, NaN, NaN, -0.19471404, "- N/A -   "
1.6500000357627869, 0.17193292, 0.04443182, NaN, NaN, NaN, -0.21546726, "- N/A -   "
1.699999988079071, 0.17193292, 0.046537068, NaN, NaN, NaN, -0.20570104, "- N/A -   "
1.7499999403953552, 0.17193292, 0.04746781, NaN, NaN, NaN, -0.20936337, "- N/A -   "
1.8000001311302185, 0.17193292, 0.048465032, NaN, NaN, NaN, -0.2130257, "- N/A -   "
1.8500000834465027, 0.17193292, 0.050658923, NaN, NaN, NaN, -0.1971556, "- N/A -   "
1.9000000357627869, 0.2063195, 0.050725404, NaN, NaN, NaN, -0.21790881, "- N/A -   "
1.949999988079071, 0.17193292, 0.053096578, NaN, NaN, NaN, -0.20448026, "- N/A -   "
1.9999999403953552, 0.2063195, 0.05464781, NaN, NaN, NaN, -0.20448026, "- N/A -   "
2.0500001311302185, 0.17193292, 0.057041146, NaN, NaN, NaN, -0.18983093, "- N/A -   "
2.1000000834465027, 0.17193292, 0.05712979, NaN, NaN, NaN, -0.2081426, "- N/A -   "
2.150000035762787, 0.65334505, 0.057838928, NaN, NaN, NaN, -0.21790881, "- N/A -   "
2.199999988079071, 0.17193292, 0.05972257, NaN, NaN, NaN, -0.21180493, "- N/A -   "
2.2499999403953552, 0.17193292, 0.06111868, NaN, NaN, NaN, -0.2130257, "- N/A -   "
2.3000001311302185, 0.2063195, 0.06360067, NaN, NaN, NaN, -0.18738937, "- N/A -   "
2.3500000834465027, 0.17193292, 0.06364498, NaN, NaN, NaN, -0.20936337, "- N/A -   "
2.400000035762787, 0.7221182, 0.06397739, NaN, NaN, NaN, -0.22645426, "- N/A -   "
2.449999988079071, 0.2063195, 0.06628208, NaN, NaN, NaN, -0.21424648, "- N/A -   "
2.4999999403953552, 0.2063195, 0.06805492, NaN, NaN, NaN, -0.21058415, "- N/A -   "
2.5500001311302185, 0.2063195, 0.06971696, NaN, NaN, NaN, -0.20325948, "- N/A -   "
2.6000000834465027, 0.75650483, 0.0698056, NaN, NaN, NaN, -0.2240127, "- N/A -   "
2.650000035762787, 0.17193292, 0.07199949, NaN, NaN, NaN, -0.2081426, "- N/A -   "
2.699999988079071, 0.2063195, 0.07226542, NaN, NaN, NaN, -0.22279193, "- N/A -   "
2.7499999403953552, 0.2063195, 0.072664306, NaN, NaN, NaN, -0.23622048, "- N/A -   "
2.8000001311302185, 0.24070609, 0.07386098, NaN, NaN, NaN, -0.23866203, "- N/A -   "
2.8500000834465027, 0.2063195, 0.07640943, NaN, NaN, NaN, -0.21424648, "- N/A -   "
2.900000035762787, 0.2063195, 0.07800499, NaN, NaN, NaN, -0.21180493, "- N/A -   "
2.949999988079071, 0.17193292, 0.07931246, NaN, NaN, NaN, -0.2130257, "- N/A -   "
2.9999999403953552, 0.27509266, 0.08146203, NaN, NaN, NaN, -0.19959715, "- N/A -   "
3.0500001311302185, 0.17193292, 0.08259221, NaN, NaN, NaN, -0.20081793, "- N/A -   "
3.1000000834465027, 0.6877317, 0.08319055, NaN, NaN, NaN, -0.21180493, "- N/A -   "
3.150000035762787, 0.17193292, 0.08536228, NaN, NaN, NaN, -0.20081793, "- N/A -   "
3.199999988079071, 0.24070609, 0.0873124, NaN, NaN, NaN, -0.19471404, "- N/A -   "
3.2499999403953552, 0.2063195, 0.08864203, NaN, NaN, NaN, -0.19227248, "- N/A -   "
3.3000001311302185, 0.2063195, 0.08864203, NaN, NaN, NaN, -0.21424648, "- N/A -   "
3.3499998450279236, 0.2063195, 0.09059216, NaN, NaN, NaN, -0.20570104, "- N/A -   "
3.400000035762787, 0.17193292, 0.09123481, NaN, NaN, NaN, -0.21790881, "- N/A -   "
3.45000022649765, 0.24070609, 0.09311846, NaN, NaN, NaN, -0.20081793, "- N/A -   "
3.4999999403953552, 0.17193292, 0.09493562, NaN, NaN, NaN, -0.18983093, "- N/A -   "
3.5500001311302185, 0.2063195, 0.09493562, NaN, NaN, NaN, -0.21058415, "- N/A -   "
3.5999998450279236, 0.17193292, 0.09664198, NaN, NaN, NaN, -0.20570104, "- N/A -   "
3.650000035762787, 0.17193292, 0.09806025, NaN, NaN, NaN, -0.2081426, "- N/A -   "
3.70000022649765, 0.24070609, 0.099677965, NaN, NaN, NaN, -0.20325948, "- N/A -   "
3.7499999403953552, 0.17193292, 0.10129569, NaN, NaN, NaN, -0.19959715, "- N/A -   "
3.8000001311302185, 0.2063195, 0.10129569, NaN, NaN, NaN, -0.22157115, "- N/A -   "
3.8499998450279236, 0.17193292, 0.10342309, NaN, NaN, NaN, -0.21424648, "- N/A -   "
3.900000035762787, 0.2063195, 0.10433167, NaN, NaN, NaN, -0.22035037, "- N/A -   "
3.95000022649765, 0.24070609, 0.10590507, NaN, NaN, NaN, -0.21790881, "- N/A -   "
3.9999999403953552, 0.17193292, 0.10805464, NaN, NaN, NaN, -0.19959715, "- N/A -   "
4.0500001311302185, 0.2063195, 0.10805464, NaN, NaN, NaN, -0.22035037, "- N/A -   "
4.099999845027924, 0.2063195, 0.10949507, NaN, NaN, NaN, -0.21790881, "- N/A -   "
4.150000035762787, 0.2063195, 0.11117927, NaN, NaN, NaN, -0.21424648, "- N/A -   "
4.20000022649765, 0.27509266, 0.113483965, NaN, NaN, NaN, -0.20325948, "- N/A -   "
4.249999940395355, 0.24070609, 0.114037976, NaN, NaN, NaN, -0.21790881, "- N/A -   "
4.3000001311302185, 0.2063195, 0.116231866, NaN, NaN, NaN, -0.20692182, "- N/A -   "
4.349999845027924, 0.24070609, 0.116564274, NaN, NaN, NaN, -0.21668804, "- N/A -   "
4.400000035762787, 0.2063195, 0.11685236, NaN, NaN, NaN, -0.23133737, "- N/A -   "
4.45000022649765, 0.17193292, 0.11769446, NaN, NaN, NaN, -0.2349997, "- N/A -   "
4.499999940395355, 0.2063195, 0.12037588, NaN, NaN, NaN, -0.2130257, "- N/A -   "
4.5500001311302185, 0.75650483, 0.12130662, NaN, NaN, NaN, -0.21546726, "- N/A -   "
4.599999845027924, 0.2063195, 0.12294651, NaN, NaN, NaN, -0.2081426, "- N/A -   "
4.650000035762787, 0.2063195, 0.12325675, NaN, NaN, NaN, -0.2240127, "- N/A -   "
4.70000022649765, 0.2063195, 0.12423181, NaN, NaN, NaN, -0.22889581, "- N/A -   "
4.749999940395355, 0.2063195, 0.12684676, NaN, NaN, NaN, -0.20692182, "- N/A -   "
4.8000001311302185, 0.48141217, 0.127157, NaN, NaN, NaN, -0.22279193, "- N/A -   "
4.849999845027924, 0.17193292, 0.12961681, NaN, NaN, NaN, -0.2081426, "- N/A -   "
4.900000035762787, 0.24070609, 0.13187718, NaN, NaN, NaN, -0.19837637, "- N/A -   "
4.95000022649765, 0.2063195, 0.1330517, NaN, NaN, NaN, -0.2020387, "- N/A -   "
4.999999940395355, 0.7221182, 0.1334949, NaN, NaN, NaN, -0.21668804, "- N/A -   "
5.0500001311302185, 0.2063195, 0.1354007, NaN, NaN, NaN, -0.2081426, "- N/A -   "
5.099999845027924, 0.17193292, 0.13564448, NaN, NaN, NaN, -0.22279193, "- N/A -   "
5.150000035762787, 0.17193292, 0.13622065, NaN, NaN, NaN, -0.23011659, "- N/A -   "
5.20000022649765, 0.17193292, 0.13786054, NaN, NaN, NaN, -0.23011659, "- N/A -   "
5.249999940395355, 0.34386584, 0.13932312, NaN, NaN, NaN, -0.23133737, "- N/A -   "
5.3000001311302185, 0.17193292, 0.14196022, NaN, NaN, NaN, -0.2081426, "- N/A -   "
5.349999845027924, 0.24070609, 0.14388818, NaN, NaN, NaN, -0.2081426, "- N/A -   "
5.400000035762787, 0.2063195, 0.14570534, NaN, NaN, NaN, -0.2020387, "- N/A -   "
5.45000022649765, 0.24070609, 0.14570534, NaN, NaN, NaN, -0.22279193, "- N/A -   "
5.499999940395355, 0.2063195, 0.14789923, NaN, NaN, NaN, -0.21180493, "- N/A -   "
5.5500001311302185, 0.17193292, 0.14894079, NaN, NaN, NaN, -0.2130257, "- N/A -   "
5.599999845027924, 0.27509266, 0.15131196, NaN, NaN, NaN, -0.19349326, "- N/A -   "
5.650000035762787, 0.2063195, 0.15226486, NaN, NaN, NaN, -0.20081793, "- N/A -   "
5.70000022649765, 0.2063195, 0.15226486, NaN, NaN, NaN, -0.22279193, "- N/A -   "
5.749999940395355, 0.17193292, 0.15432577, NaN, NaN, NaN, -0.21180493, "- N/A -   "
5.8000001311302185, 0.17193292, 0.15569974, NaN, NaN, NaN, -0.21180493, "- N/A -   "
5.849999845027924, 0.24070609, 0.15809307, NaN, NaN, NaN, -0.1971556, "- N/A -   "
5.900000035762787, 0.2063195, 0.15831468, NaN, NaN, NaN, -0.21546726, "- N/A -   "
5.95000022649765, 0.17193292, 0.16022047, NaN, NaN, NaN, -0.20570104, "- N/A -   "
5.999999940395355, 0.2063195, 0.16053073, NaN, NaN, NaN, -0.22035037, "- N/A -   "
6.0500001311302185, 0.17193292, 0.16230357, NaN, NaN, NaN, -0.21180493, "- N/A -   "
6.099999845027924, 0.17193292, 0.16474122, NaN, NaN, NaN, -0.18983093, "- N/A -   "
6.150000035762787, 0.2063195, 0.16474122, NaN, NaN, NaN, -0.21180493, "- N/A -   "
6.20000022649765, 0.17193292, 0.1663811, NaN, NaN, NaN, -0.20570104, "- N/A -   "
6.249999940395355, 0.2063195, 0.16691294, NaN, NaN, NaN, -0.21790881, "- N/A -   "
6.3000001311302185, 0.17193292, 0.1672232, NaN, NaN, NaN, -0.23622048, "- N/A -   "
6.349999845027924, 0.13754633, 0.16804314, NaN, NaN, NaN, -0.23866203, "- N/A -   "
6.400000035762787, 0.24070609, 0.17052512, NaN, NaN, NaN, -0.21790881, "- N/A -   "
6.45000022649765, 0.2063195, 0.17152233, NaN, NaN, NaN, -0.2240127, "- N/A -   "
6.499999940395355, 0.17193292, 0.17364974, NaN, NaN, NaN, -0.21180493, "- N/A -   "
6.5500001311302185, 0.24070609, 0.17584363, NaN, NaN, NaN, -0.20570104, "- N/A -   "
6.599999845027924, 0.2063195, 0.1774392, NaN, NaN, NaN, -0.20081793, "- N/A -   "
6.650000035762787, 0.7221182, 0.17783807, NaN, NaN, NaN, -0.21912959, "- N/A -   "
6.70000022649765, 0.17193292, 0.17985469, NaN, NaN, NaN, -0.20570104, "- N/A -   "
6.749999940395355, 0.17193292, 0.18020925, NaN, NaN, NaN, -0.22035037, "- N/A -   "
6.8000001311302185, 0.17193292, 0.18096273, NaN, NaN, NaN, -0.22767504, "- N/A -   "
6.849999845027924, 0.17193292, 0.18317875, NaN, NaN, NaN, -0.21790881, "- N/A -   "
6.900000035762787, 0.4470256, 0.18461919, NaN, NaN, NaN, -0.2130257, "- N/A -   "
6.95000022649765, 0.17193292, 0.18670228, NaN, NaN, NaN, -0.20692182, "- N/A -   "
6.999999940395355, 0.24070609, 0.18869673, NaN, NaN, NaN, -0.19959715, "- N/A -   "
7.0500001311302185, 0.2063195, 0.19007067, NaN, NaN, NaN, -0.19959715, "- N/A -   "
7.099999845027924, 0.2063195, 0.19007067, NaN, NaN, NaN, -0.22157115, "- N/A -   "
7.150000035762787, 0.17193292, 0.19213161, NaN, NaN, NaN, -0.21058415, "- N/A -   "
7.20000022649765, 0.2063195, 0.193151, NaN, NaN, NaN, -0.21180493, "- N/A -   "
7.250000417232513, 0.24070609, 0.19527839, NaN, NaN, NaN, -0.19959715, "- N/A -   "
7.29999965429306, 0.2063195, 0.19665235, NaN, NaN, NaN, -0.19837637, "- N/A -   "
7.349999845027924, 0.2063195, 0.19665235, NaN, NaN, NaN, -0.22035037, "- N/A -   "
7.400000035762787, 0.17193292, 0.19835871, NaN, NaN, NaN, -0.21424648, "- N/A -   "
7.45000022649765, 0.2063195, 0.19990996, NaN, NaN, NaN, -0.21424648, "- N/A -   "
7.500000417232513, 0.24070609, 0.20232543, NaN, NaN, NaN, -0.19959715, "- N/A -   "
7.54999965429306, 0.24070609, 0.20263569, NaN, NaN, NaN, -0.21546726, "- N/A -   "
7.599999845027924, 0.17193292, 0.2046523, NaN, NaN, NaN, -0.20570104, "- N/A -   "
7.650000035762787, 0.2063195, 0.20489606, NaN, NaN, NaN, -0.22279193, "- N/A -   "
7.70000022649765, 0.24070609, 0.2071786, NaN, NaN, NaN, -0.20081793, "- N/A -   "
7.750000417232513, 0.2063195, 0.20906223, NaN, NaN, NaN, -0.18983093, "- N/A -   "
7.79999965429306, 0.17193292, 0.20906223, NaN, NaN, NaN, -0.21180493, "- N/A -   "
7.849999845027924, 0.17193292, 0.21070212, NaN, NaN, NaN, -0.20692182, "- N/A -   "
7.900000035762787, 0.17193292, 0.21130045, NaN, NaN, NaN, -0.22035037, "- N/A -   "
7.95000022649765, 0.2063195, 0.21165502, NaN, NaN, NaN, -0.2349997, "- N/A -   "
8.000000417232513, 0.17193292, 0.21265224, NaN, NaN, NaN, -0.23744126, "- N/A -   "
8.04999965429306, 0.17193292, 0.21540014, NaN, NaN, NaN, -0.2130257, "- N/A -   "
8.099999845027924, 0.17193292, 0.2160428, NaN, NaN, NaN, -0.22279193, "- N/A -   "
8.150000035762787, 0.17193292, 0.21657464, NaN, NaN, NaN, -0.23377892, "- N/A -   "
8.20000022649765, 0.17193292, 0.21808156, NaN, NaN, NaN, -0.2349997, "- N/A -   "
8.250000417232513, 0.2063195, 0.22038625, NaN, NaN, NaN, -0.22157115, "- N/A -   "
8.29999965429306, 0.17193292, 0.22200398, NaN, NaN, NaN, -0.21180493, "- N/A -   "
8.349999845027924, 0.17193292, 0.22364385, NaN, NaN, NaN, -0.20570104, "- N/A -   "
8.400000035762787, 0.17193292, 0.2243973, NaN, NaN, NaN, -0.21424648, "- N/A -   "
8.45000022649765, 0.17193292, 0.224907, NaN, NaN, NaN, -0.22767504, "- N/A -   "
8.500000417232513, 0.2063195, 0.22634743, NaN, NaN, NaN, -0.22523348, "- N/A -   "
8.54999965429306, 0.17193292, 0.22794299, NaN, NaN, NaN, -0.21912959, "- N/A -   "
8.599999845027924, 0.17193292, 0.230292, NaN, NaN, NaN, -0.20081793, "- N/A -   "
8.650000035762787, 0.17193292, 0.2316438, NaN, NaN, NaN, -0.2020387, "- N/A -   "
8.70000022649765, 0.2063195, 0.23392634, NaN, NaN, NaN, -0.1910517, "- N/A -   "
8.750000417232513, 0.13754633, 0.23425874, NaN, NaN, NaN, -0.20692182, "- N/A -   "
8.79999965429306, 0.7221182, 0.23459114, NaN, NaN, NaN, -0.2240127, "- N/A -   "
8.849999845027924, 0.13754633, 0.23667423, NaN, NaN, NaN, -0.21058415, "- N/A -   "
8.900000035762787, 0.17193292, 0.23731689, NaN, NaN, NaN, -0.22035037, "- N/A -   "
8.95000022649765, 0.2063195, 0.2388238, NaN, NaN, NaN, -0.22157115, "- N/A -   "
9.000000417232513, 0.17193292, 0.24092905, NaN, NaN, NaN, -0.20570104, "- N/A -   "
9.04999965429306, 0.7221182, 0.24097337, NaN, NaN, NaN, -0.22645426, "- N/A -   "
9.099999845027924, 0.13754633, 0.24323374, NaN, NaN, NaN, -0.2130257, "- N/A -   "
9.150000035762787, 0.17193292, 0.24423096, NaN, NaN, NaN, -0.21546726, "- N/A -   "
9.20000022649765, 0.24070609, 0.24642485, NaN, NaN, NaN, -0.20325948, "- N/A -   "
9.250000417232513, 0.7221182, 0.24708967, NaN, NaN, NaN, -0.21790881, "- N/A -   "
9.29999965429306, 0.17193292, 0.2491506, NaN, NaN, NaN, -0.21058415, "- N/A -   "
9.349999845027924, 0.6877317, 0.24990405, NaN, NaN, NaN, -0.22157115, "- N/A -   "
9.400000035762787, 0.2063195, 0.25296223, NaN, NaN, NaN, -0.18983093, "- N/A -   "
9.45000022649765, 0.17193292, 0.25338325, NaN, NaN, NaN, -0.20325948, "- N/A -   "
9.500000417232513, 0.6877317, 0.25393724, NaN, NaN, NaN, -0.21668804, "- N/A -   "
9.54999965429306, 0.17193292, 0.25564364, NaN, NaN, NaN, -0.21058415, "- N/A -   "
9.599999845027924, 0.17193292, 0.25597602, NaN, NaN, NaN, -0.22279193, "- N/A -   "
9.650000035762787, 0.17193292, 0.25659654, NaN, NaN, NaN, -0.23011659, "- N/A -   "
9.70000022649765, 0.2063195, 0.25872394, NaN, NaN, NaN, -0.21668804, "- N/A -   "
9.750000417232513, 0.17193292, 0.2600979, NaN, NaN, NaN, -0.21912959, "- N/A -   "
9.79999965429306, 0.6877317, 0.26091784, NaN, NaN, NaN, -0.22523348, "- N/A -   "
9.849999845027924, 0.17193292, 0.26331115, NaN, NaN, NaN, -0.2130257, "- N/A -   "
9.900000035762787, 0.13754633, 0.26597044, NaN, NaN, NaN, -0.19471404, "- N/A -   "
9.95000022649765, 0.17193292, 0.26619202, NaN, NaN, NaN, -0.21424648, "- N/A -   "
10.000000417232513, 0.13754633, 0.26818648, NaN, NaN, NaN, -0.20570104, "- N/A -   "
10.04999965429306, 0.17193292, 0.26876265, NaN, NaN, NaN, -0.21546726, "- N/A -   "
10.099999845027924, 0.13754633, 0.26927236, NaN, NaN, NaN, -0.22523348, "- N/A -   "
10.150000035762787, 0.17193292, 0.27077925, NaN, NaN, NaN, -0.22279193, "- N/A -   "
10.20000022649765, 0.17193292, 0.27226403, NaN, NaN, NaN, -0.21912959, "- N/A -   "
10.250000417232513, 0.13754633, 0.27461302, NaN, NaN, NaN, -0.20325948, "- N/A -   "
10.29999965429306, 0.17193292, 0.27605346, NaN, NaN, NaN, -0.20325948, "- N/A -   "
10.349999845027924, 0.17193292, 0.27846897, NaN, NaN, NaN, -0.18738937, "- N/A -   "
10.400000035762787, 0.17193292, 0.27869055, NaN, NaN, NaN, -0.20570104, "- N/A -   "
10.45000022649765, 0.7221182, 0.27880135, NaN, NaN, NaN, -0.2240127, "- N/A -   "
10.500000417232513, 0.13754633, 0.28108388, NaN, NaN, NaN, -0.21058415, "- N/A -   "
10.54999965429306, 0.13754633, 0.28210327, NaN, NaN, NaN, -0.21546726, "- N/A -   "
10.599999845027924, 0.17193292, 0.28476253, NaN, NaN, NaN, -0.1910517, "- N/A -   "
10.650000035762787, 0.13754633, 0.28529438, NaN, NaN, NaN, -0.20448026, "- N/A -   "
10.70000022649765, 0.17193292, 0.28529438, NaN, NaN, NaN, -0.22645426, "- N/A -   "
10.750000417232513, 0.13754633, 0.28755477, NaN, NaN, NaN, -0.2130257, "- N/A -   "
10.79999965429306, 0.17193292, 0.28912815, NaN, NaN, NaN, -0.2130257, "- N/A -   "
10.849999845027924, 0.13754633, 0.29129988, NaN, NaN, NaN, -0.20325948, "- N/A -   "
10.900000035762787, 0.65334505, 0.2917431, NaN, NaN, NaN, -0.21912959, "- N/A -   "
10.95000022649765, 0.13754633, 0.2935381, NaN, NaN, NaN, -0.21058415, "- N/A -   "
11.000000417232513, 0.13754633, 0.2936932, NaN, NaN, NaN, -0.22889581, "- N/A -   "
11.04999965429306, 0.13754633, 0.29413643, NaN, NaN, NaN, -0.23744126, "- N/A -   "
11.099999845027924, 0.13754633, 0.29513365, NaN, NaN, NaN, -0.23988281, "- N/A -   "
11.150000035762787, 0.13754633, 0.29785937, NaN, NaN, NaN, -0.21546726, "- N/A -   "
11.20000022649765, 0.13754633, 0.29927766, NaN, NaN, NaN, -0.21424648, "- N/A -   "
11.250000417232513, 0.13754633, 0.3007846, NaN, NaN, NaN, -0.21180493, "- N/A -   "
11.29999965429306, 0.17193292, 0.30257958, NaN, NaN, NaN, -0.20448026, "- N/A -   "
11.349999845027924, 0.13754633, 0.30419728, NaN, NaN, NaN, -0.19837637, "- N/A -   "
11.400000035762787, 0.7221182, 0.3043081, NaN, NaN, NaN, -0.21790881, "- N/A -   "
11.45000022649765, 0.10315975, 0.30674577, NaN, NaN, NaN, -0.20570104, "- N/A -   "
11.500000417232513, 0.17193292, 0.30869588, NaN, NaN, NaN, -0.19959715, "- N/A -   "
11.54999965429306, 0.13754633, 0.31042442, NaN, NaN, NaN, -0.19227248, "- N/A -   "
11.599999845027924, 0.13754633, 0.31042442, NaN, NaN, NaN, -0.21424648, "- N/A -   "
11.650000035762787, 0.10315975, 0.31241885, NaN, NaN, NaN, -0.2020387, "- N/A -   "
11.70000022649765, 0.10315975, 0.31297284, NaN, NaN, NaN, -0.21058415, "- N/A -   "
11.750000417232513, 0.10315975, 0.31343824, NaN, NaN, NaN, -0.22157115, "- N/A -   "
11.79999965429306, 0.17193292, 0.31476787, NaN, NaN, NaN, -0.22157115, "- N/A -   "
11.849999845027924, 0.10315975, 0.31658503, NaN, NaN, NaN, -0.21424648, "- N/A -   "
11.900000035762787, 0.13754633, 0.3185573, NaN, NaN, NaN, -0.2020387, "- N/A -   "
11.95000022649765, 0.13754633, 0.32004207, NaN, NaN, NaN, -0.2020387, "- N/A -   "
12.000000417232513, 0.17193292, 0.32241324, NaN, NaN, NaN, -0.18983093, "- N/A -   "
12.04999965429306, 0.10315975, 0.32301158, NaN, NaN, NaN, -0.2020387, "- N/A -   "
12.099999845027924, 0.17193292, 0.32301158, NaN, NaN, NaN, -0.2240127, "- N/A -   "
12.150000035762787, 0.10315975, 0.3252498, NaN, NaN, NaN, -0.21180493, "- N/A -   "
12.20000022649765, 0.10315975, 0.3265351, NaN, NaN, NaN, -0.2130257, "- N/A -   "
12.250000417232513, 0.13754633, 0.32926086, NaN, NaN, NaN, -0.18983093, "- N/A -   "
12.29999965429306, 0.10315975, 0.32963756, NaN, NaN, NaN, -0.20570104, "- N/A -   "
12.349999845027924, 0.10315975, 0.32963756, NaN, NaN, NaN, -0.22645426, "- N/A -   "
12.400000035762787, 0.10315975, 0.3319644, NaN, NaN, NaN, -0.20936337, "- N/A -   "
12.45000022649765, 0.13754633, 0.3338259, NaN, NaN, NaN, -0.20570104, "- N/A -   "
12.500000417232513, 0.10315975, 0.33564305, NaN, NaN, NaN, -0.19837637, "- N/A -   "
12.54999965429306, 0.10315975, 0.33564305, NaN, NaN, NaN, -0.22035037, "- N/A -   "
12.599999845027924, 0.068773165, 0.3375932, NaN, NaN, NaN, -0.2081426, "- N/A -   "
12.650000035762787, 0.10315975, 0.33805856, NaN, NaN, NaN, -0.21912959, "- N/A -   "
12.70000022649765, 0.068773165, 0.33839098, NaN, NaN, NaN, -0.2349997, "- N/A -   "
12.750000417232513, 0.068773165, 0.33929953, NaN, NaN, NaN, -0.23988281, "- N/A -   "
12.79999965429306, 0.068773165, 0.34209177, NaN, NaN, NaN, -0.2081426, "- N/A -   "
12.849999845027924, 0.10315975, 0.34249067, NaN, NaN, NaN, -0.22279193, "- N/A -   "
12.900000035762787, 0.068773165, 0.34477317, NaN, NaN, NaN, -0.20448026, "- N/A -   "
12.95000022649765, 0.10315975, 0.34674546, NaN, NaN, NaN, -0.19959715, "- N/A -   "
13.000000417232513, 0.068773165, 0.3485183, NaN, NaN, NaN, -0.19227248, "- N/A -   "
13.04999965429306, 0.068773165, 0.3485183, NaN, NaN, NaN, -0.21424648, "- N/A -   "
13.099999845027924, 0.068773165, 0.35069004, NaN, NaN, NaN, -0.19959715, "- N/A -   "
13.150000035762787, 0.10315975, 0.35252938, NaN, NaN, NaN, -0.19837637, "- N/A -   "
13.20000022649765, 0.068773165, 0.3547011, NaN, NaN, NaN, -0.1861686, "- N/A -   "
13.250000417232513, 0.068773165, 0.35472327, NaN, NaN, NaN, -0.20692182, "- N/A -   "
13.29999965429306, 0.034386583, 0.3559421, NaN, NaN, NaN, -0.20936337, "- N/A -   "
13.349999845027924, 0.034386583, 0.35736036, NaN, NaN, NaN, -0.20692182, "- N/A -   "
13.400000035762787, 0.034386583, 0.35804734, NaN, NaN, NaN, -0.21546726, "- N/A -   "
13.45000022649765, 0.068773165, 0.36001962, NaN, NaN, NaN, -0.2081426, "- N/A -   "
13.500000417232513, 0.068773165, 0.36090603, NaN, NaN, NaN, -0.21546726, "- N/A -   "
13.54999965429306, 0.034386583, 0.36309993, NaN, NaN, NaN, -0.20081793, "- N/A -   "
13.599999845027924, 0.034386583, 0.36467335, NaN, NaN, NaN, -0.20081793, "- N/A -   "
13.650000035762787, 0.034386583, 0.36713314, NaN, NaN, NaN, -0.18494782, "- N/A -   "
13.70000022649765, 0.034386583, 0.36733258, NaN, NaN, NaN, -0.20325948, "- N/A -   "
13.750000417232513, 0.48141217, 0.36735475, NaN, NaN, NaN, -0.2240127, "- N/A -   "
13.79999965429306, 0.034386583, 0.3696816, NaN, NaN, NaN, -0.21058415, "- N/A -   "
13.849999845027924, 0.0, 0.37098908, NaN, NaN, NaN, -0.21058415, "- N/A -   "
13.900000035762787, 0.0, 0.37360403, NaN, NaN, NaN, -0.18372704, "- N/A -   "
13.95000022649765, 0.034386583, 0.37380347, NaN, NaN, NaN, -0.19959715, "- N/A -   "
14.000000417232513, 0.034386583, 0.37380347, NaN, NaN, NaN, -0.22157115, "- N/A -   "
14.04999965429306, 0.0, 0.3758422, NaN, NaN, NaN, -0.20692182, "- N/A -   "
14.099999845027924, 0.034386583, 0.37712753, NaN, NaN, NaN, -0.20936337, "- N/A -   "
14.150000035762787, 0.068773165, 0.37941006, NaN, NaN, NaN, -0.1971556, "- N/A -   "
14.20000022649765, 0.0, 0.3798976, NaN, NaN, NaN, -0.21180493, "- N/A -   "
14.250000417232513, 0.51579875, 0.38104993, NaN, NaN, NaN, -0.2130257, "- N/A -   "
14.29999965429306, 0.0, 0.38218012, NaN, NaN, NaN, -0.21546726, "- N/A -   "
14.349999845027924, 0.0, 0.3833768, NaN, NaN, NaN, -0.21546726, "- N/A -   "
14.400000035762787, -0.034386583, 0.3861912, NaN, NaN, NaN, -0.18861015, "- N/A -   "
14.45000022649765, 0.0, 0.38636845, NaN, NaN, NaN, -0.20570104, "- N/A -   "
14.500000417232513, 0.13754633, 0.38745433, NaN, NaN, NaN, -0.21058415, "- N/A -   "
14.54999965429306, 0.0, 0.38898343, NaN, NaN, NaN, -0.2081426, "- N/A -   "
14.599999845027924, 0.0, 0.38962606, NaN, NaN, NaN, -0.21668804, "- N/A -   "
14.650000035762787, 0.068773165, 0.39168698, NaN, NaN, NaN, -0.20570104, "- N/A -   "
14.70000022649765, 0.0, 0.39292797, NaN, NaN, NaN, -0.20936337, "- N/A -   "
14.750000417232513, 0.0, 0.3943241, NaN, NaN, NaN, -0.20570104, "- N/A -   "
14.79999965429306, 0.0, 0.39591965, NaN, NaN, NaN, -0.20448026, "- N/A -   "
14.849999845027924, 0.0, 0.39815784, NaN, NaN, NaN, -0.19349326, "- N/A -   "
14.900000035762787, 0.0, 0.39891133, NaN, NaN, NaN, -0.20448026, "- N/A -   "
14.95000022649765, 0.34386584, 0.39988637, NaN, NaN, NaN, -0.21058415, "- N/A -   "
15.000000417232513, 0.0, 0.40134895, NaN, NaN, NaN, -0.21180493, "- N/A -   "
15.04999965429306, -0.034386583, 0.40272292, NaN, NaN, NaN, -0.20692182, "- N/A -   "
15.099999845027924, -0.034386583, 0.40511626, NaN, NaN, NaN, -0.19227248, "- N/A -   "
15.150000035762787, 0.0, 0.40513843, NaN, NaN, NaN, -0.2130257, "- N/A -   "
15.20000022649765, 0.0, 0.40704423, NaN, NaN, NaN, -0.20570104, "- N/A -   "
15.249999463558197, -0.034386583, 0.40852895, NaN, NaN, NaN, -0.20448026, "- N/A -   "
15.300000607967377, 0.034386583, 0.41063422, NaN, NaN, NaN, -0.19471404, "- N/A -   "
15.349999845027924, -0.034386583, 0.4116536, NaN, NaN, NaN, -0.20325948, "- N/A -   "
15.39999908208847, 0.5501853, 0.41169792, NaN, NaN, NaN, -0.2240127, "- N/A -   "
15.45000022649765, -0.034386583, 0.41393614, NaN, NaN, NaN, -0.21058415, "- N/A -   "
15.499999463558197, -0.034386583, 0.41484472, NaN, NaN, NaN, -0.21546726, "- N/A -   "
15.550000607967377, 0.034386583, 0.41723806, NaN, NaN, NaN, -0.1971556, "- N/A -   "
15.599999845027924, -0.034386583, 0.41819096, NaN, NaN, NaN, -0.2020387, "- N/A -   "
15.64999908208847, 0.0, 0.41819096, NaN, NaN, NaN, -0.2240127, "- N/A -   "
15.70000022649765, -0.034386583, 0.42027405, NaN, NaN, NaN, -0.21180493, "- N/A -   "
15.749999463558197, -0.034386583, 0.4215815, NaN, NaN, NaN, -0.21180493, "- N/A -   "
15.800000607967377, 0.034386583, 0.42393053, NaN, NaN, NaN, -0.1971556, "- N/A -   "
15.849999845027924, 0.0, 0.4242408, NaN, NaN, NaN, -0.2130257, "- N/A -   "
15.89999908208847, -0.068773165, 0.42568123, NaN, NaN, NaN, -0.2081426, "- N/A -   "
15.95000022649765, -0.034386583, 0.42643467, NaN, NaN, NaN, -0.21912959, "- N/A -   "
15.999999463558197, -0.034386583, 0.42807454, NaN, NaN, NaN, -0.2130257, "- N/A -   "
16.050000607967377, -0.034386583, 0.430623, NaN, NaN, NaN, -0.1861686, "- N/A -   "
16.099999845027924, -0.034386583, 0.4306673, NaN, NaN, NaN, -0.2081426, "- N/A -   "
16.14999908208847, 0.0, 0.43206343, NaN, NaN, NaN, -0.20692182, "- N/A -   "
16.20000022649765, -0.034386583, 0.4333266, NaN, NaN, NaN, -0.2081426, "- N/A -   "
16.249999463558197, -0.068773165, 0.4339471, NaN, NaN, NaN, -0.21668804, "- N/A -   "
16.300000607967377, 0.0, 0.4360745, NaN, NaN, NaN, -0.20570104, "- N/A -   "
16.349999845027924, -0.034386583, 0.4372047, NaN, NaN, NaN, -0.20570104, "- N/A -   "
16.39999908208847, -0.034386583, 0.4384678, NaN, NaN, NaN, -0.2081426, "- N/A -   "
16.45000022649765, -0.034386583, 0.44017416, NaN, NaN, NaN, -0.20692182, "- N/A -   "
16.499999463558197, 0.0, 0.44239023, NaN, NaN, NaN, -0.19593482, "- N/A -   "
16.550000607967377, -0.034386583, 0.44329882, NaN, NaN, NaN, -0.20081793, "- N/A -   "
16.599999845027924, 0.51579875, 0.44365337, NaN, NaN, NaN, -0.21912959, "- N/A -   "
16.64999908208847, -0.034386583, 0.44578078, NaN, NaN, NaN, -0.20570104, "- N/A -   "
16.70000022649765, 0.0, 0.44606888, NaN, NaN, NaN, -0.22035037, "- N/A -   "
16.749999463558197, -0.034386583, 0.4466672, NaN, NaN, NaN, -0.23133737, "- N/A -   "
16.800000607967377, -0.034386583, 0.44861734, NaN, NaN, NaN, -0.22523348, "- N/A -   "
16.849999845027924, 0.51579875, 0.4499913, NaN, NaN, NaN, -0.22767504, "- N/A -   "
16.89999908208847, -0.068773165, 0.45247328, NaN, NaN, NaN, -0.2081426, "- N/A -   "
16.95000022649765, -0.10315975, 0.4541353, NaN, NaN, NaN, -0.20570104, "- N/A -   "
16.999999463558197, -0.17193292, 0.45599678, NaN, NaN, NaN, -0.20081793, "- N/A -   "
17.050000607967377, -0.13754633, 0.45599678, NaN, NaN, NaN, -0.22279193, "- N/A -   "
17.099999845027924, -0.17193292, 0.45810205, NaN, NaN, NaN, -0.2130257, "- N/A -   "
17.14999908208847, -0.17193292, 0.45905492, NaN, NaN, NaN, -0.21668804, "- N/A -   "
17.20000022649765, -0.10315975, 0.46111587, NaN, NaN, NaN, -0.20570104, "- N/A -   "
17.249999463558197, -0.17193292, 0.46251196, NaN, NaN, NaN, -0.20325948, "- N/A -   "
17.300000607967377, -0.13754633, 0.46251196, NaN, NaN, NaN, -0.2240127, "- N/A -   "
17.349999845027924, -0.17193292, 0.46466154, NaN, NaN, NaN, -0.21180493, "- N/A -   "
17.39999908208847, -0.13754633, 0.46592468, NaN, NaN, NaN, -0.2130257, "- N/A -   "
17.45000022649765, -0.10315975, 0.46822938, NaN, NaN, NaN, -0.19959715, "- N/A -   "
17.499999463558197, -0.13754633, 0.46853963, NaN, NaN, NaN, -0.21668804, "- N/A -   "
17.550000607967377, -0.2063195, 0.47055623, NaN, NaN, NaN, -0.20448026, "- N/A -   "
17.599999845027924, -0.17193292, 0.47091082, NaN, NaN, NaN, -0.22157115, "- N/A -   "
17.64999908208847, -0.13754633, 0.47288308, NaN, NaN, NaN, -0.20325948, "- N/A -   "
17.70000022649765, -0.17193292, 0.47489968, NaN, NaN, NaN, -0.1910517, "- N/A -   "
17.749999463558197, -0.17193292, 0.47489968, NaN, NaN, NaN, -0.2130257, "- N/A -   "
17.800000607967377, -0.13754633, 0.47682768, NaN, NaN, NaN, -0.20448026, "- N/A -   "
17.849999845027924, -0.2063195, 0.4777141, NaN, NaN, NaN, -0.2130257, "- N/A -   "
17.89999908208847, -0.2063195, 0.47837892, NaN, NaN, NaN, -0.21912959, "- N/A -   "
17.95000022649765, -0.13754633, 0.4806836, NaN, NaN, NaN, -0.2020387, "- N/A -   "
17.999999463558197, -0.17193292, 0.48172513, NaN, NaN, NaN, -0.20692182, "- N/A -   "
18.050000607967377, -0.17193292, 0.48188025, NaN, NaN, NaN, -0.22645426, "- N/A -   "
18.099999845027924, -0.2063195, 0.4825229, NaN, NaN, NaN, -0.23744126, "- N/A -   "
18.14999908208847, -0.17193292, 0.48380822, NaN, NaN, NaN, -0.23744126, "- N/A -   "
18.20000022649765, -0.13754633, 0.48571405, NaN, NaN, NaN, -0.2349997, "- N/A -   "
18.249999463558197, -0.17193292, 0.48788577, NaN, NaN, NaN, -0.21912959, "- N/A -   "
18.300000607967377, -0.17193292, 0.48996884, NaN, NaN, NaN, -0.20692182, "- N/A -   "
18.349999845027924, -0.2063195, 0.49067798, NaN, NaN, NaN, -0.21180493, "- N/A -   "
18.39999908208847, -0.2063195, 0.4914536, NaN, NaN, NaN, -0.21668804, "- N/A -   "
18.45000022649765, -0.17193292, 0.49360314, NaN, NaN, NaN, -0.20692182, "- N/A -   "
18.499999463558197, 0.34386584, 0.49433446, NaN, NaN, NaN, -0.2130257, "- N/A -   "
18.550000607967377, -0.2063195, 0.4965062, NaN, NaN, NaN, -0.19959715, "- N/A -   "
18.599999845027924, -0.2063195, 0.497725, NaN, NaN, NaN, -0.20325948, "- N/A -   "
18.64999908208847, -0.2063195, 0.50016266, NaN, NaN, NaN, -0.18738937, "- N/A -   "
18.70000022649765, -0.17193292, 0.50034, NaN, NaN, NaN, -0.20570104, "- N/A -   "
18.749999463558197, 0.37825242, 0.50045073, NaN, NaN, NaN, -0.22523348, "- N/A -   "
18.800000607967377, -0.2063195, 0.5027998, NaN, NaN, NaN, -0.20692182, "- N/A -   "
18.849999845027924, -0.2063195, 0.5042624, NaN, NaN, NaN, -0.20692182, "- N/A -   "
18.89999908208847, -0.2063195, 0.50672215, NaN, NaN, NaN, -0.18861015, "- N/A -   "
18.95000022649765, -0.2063195, 0.5067665, NaN, NaN, NaN, -0.20936337, "- N/A -   "
18.999999463558197, 0.30947924, 0.5071211, NaN, NaN, NaN, -0.22645426, "- N/A -   "
19.050000607967377, -0.2063195, 0.5094258, NaN, NaN, NaN, -0.21180493, "- N/A -   "
19.099999845027924, -0.13754633, 0.5109327, NaN, NaN, NaN, -0.21180493, "- N/A -   "
19.14999908208847, -0.2063195, 0.5129493, NaN, NaN, NaN, -0.2020387, "- N/A -   "
19.20000022649765, 0.34386584, 0.5131266, NaN, NaN, NaN, -0.22157115, "- N/A -   "
19.249999463558197, -0.2063195, 0.5150988, NaN, NaN, NaN, -0.21058415, "- N/A -   "
19.300000607967377, -0.2063195, 0.5153205, NaN, NaN, NaN, -0.23133737, "- N/A -   "
19.349999845027924, -0.24070609, 0.515808, NaN, NaN, NaN, -0.23988281, "- N/A -   "
19.39999908208847, -0.17193292, 0.5171155, NaN, NaN, NaN, -0.23988281, "- N/A -   "
19.45000022649765, -0.24070609, 0.51964176, NaN, NaN, NaN, -0.21546726, "- N/A -   "
19.499999463558197, -0.24070609, 0.5212152, NaN, NaN, NaN, -0.20936337, "- N/A -   "
19.550000607967377, -0.24070609, 0.5226556, NaN, NaN, NaN, -0.20692182, "- N/A -   "
19.599999845027924, -0.2063195, 0.52493817, NaN, NaN, NaN, -0.1910517, "- N/A -   "
19.64999908208847, -0.24070609, 0.5258467, NaN, NaN, NaN, -0.19959715, "- N/A -   "
19.70000022649765, 0.30947924, 0.5259575, NaN, NaN, NaN, -0.21790881, "- N/A -   "
19.749999463558197, -0.27509266, 0.5283065, NaN, NaN, NaN, -0.20081793, "- N/A -   "
19.800000607967377, -0.2063195, 0.53021234, NaN, NaN, NaN, -0.19593482, "- N/A -   "
19.849999845027924, -0.27509266, 0.5319409, NaN, NaN, NaN, -0.1861686, "- N/A -   "
19.89999908208847, -0.24070609, 0.5319409, NaN, NaN, NaN, -0.2081426, "- N/A -   "
19.95000022649765, -0.2063195, 0.5333813, NaN, NaN, NaN, -0.20692182, "- N/A -   "
19.999999463558197, -0.27509266, 0.53471094, NaN, NaN, NaN, -0.20570104, "- N/A -   "
20.050000607967377, -0.27509266, 0.53530926, NaN, NaN, NaN, -0.21790881, "- N/A -   "
20.099999845027924, -0.27509266, 0.5372815, NaN, NaN, NaN, -0.2081426, "- N/A -   "
20.14999908208847, -0.27509266, 0.5382123, NaN, NaN, NaN, -0.21424648, "- N/A -   "
20.20000022649765, -0.24070609, 0.54018456, NaN, NaN, NaN, -0.2020387, "- N/A -   "
20.249999463558197, -0.30947924, 0.5415806, NaN, NaN, NaN, -0.20448026, "- N/A -   "
20.300000607967377, -0.2063195, 0.5438189, NaN, NaN, NaN, -0.19227248, "- N/A -   "
20.349999845027924, -0.27509266, 0.54461664, NaN, NaN, NaN, -0.19959715, "- N/A -   "
20.39999908208847, -0.24070609, 0.54461664, NaN, NaN, NaN, -0.22157115, "- N/A -   "
20.45000022649765, -0.30947924, 0.54678833, NaN, NaN, NaN, -0.2081426, "- N/A -   "
20.499999463558197, -0.30947924, 0.54780775, NaN, NaN, NaN, -0.20936337, "- N/A -   "
20.550000607967377, -0.24070609, 0.5502454, NaN, NaN, NaN, -0.19349326, "- N/A -   "
20.599999845027924, -0.30947924, 0.551154, NaN, NaN, NaN, -0.2020387, "- N/A -   "
20.64999908208847, -0.27509266, 0.551154, NaN, NaN, NaN, -0.22279193, "- N/A -   "
20.70000022649765, -0.30947924, 0.55325925, NaN, NaN, NaN, -0.2130257, "- N/A -   "
20.749999463558197, -0.34386584, 0.55467755, NaN, NaN, NaN, -0.2130257, "- N/A -   "
20.800000607967377, -0.34386584, 0.55711514, NaN, NaN, NaN, -0.19959715, "- N/A -   "
20.849999845027924, -0.27509266, 0.5572482, NaN, NaN, NaN, -0.21790881, "- N/A -   "
20.89999908208847, -0.34386584, 0.55922043, NaN, NaN, NaN, -0.2081426, "- N/A -   "
20.95000022649765, -0.30947924, 0.5594864, NaN, NaN, NaN, -0.2240127, "- N/A -   "
20.999999463558197, -0.068773165, 0.5598188, NaN, NaN, NaN, -0.25209057, "- N/A -   "
21.050000607967377, -0.34386584, 0.5635196, NaN, NaN, NaN, -0.1971556, "- N/A -   "
21.099999845027924, -0.34386584, 0.5639185, NaN, NaN, NaN, -0.2130257, "- N/A -   "
21.14999908208847, -0.34386584, 0.565514, NaN, NaN, NaN, -0.2081426, "- N/A -   "
21.20000022649765, -0.34386584, 0.5666442, NaN, NaN, NaN, -0.21180493, "- N/A -   "
21.249999463558197, -0.27509266, 0.5682619, NaN, NaN, NaN, -0.21058415, "- N/A -   "
21.300000607967377, -0.34386584, 0.5703007, NaN, NaN, NaN, -0.19837637, "- N/A -   "
21.349999845027924, -0.34386584, 0.57038933, NaN, NaN, NaN, -0.22157115, "- N/A -   "
21.39999908208847, -0.34386584, 0.5730043, NaN, NaN, NaN, -0.22035037, "- N/A -   "
21.45000022649765, -0.30947924, 0.5759073, NaN, NaN, NaN, -0.1910517, "- N/A -   "
21.499999463558197, -0.34386584, 0.5763948, NaN, NaN, NaN, -0.20448026, "- N/A -   "
21.550000607967377, 0.13754633, 0.5772148, NaN, NaN, NaN, -0.21424648, "- N/A -   "
21.599999845027924, -0.34386584, 0.5790098, NaN, NaN, NaN, -0.20692182, "- N/A -   "
21.64999908208847, -0.34386584, 0.5798075, NaN, NaN, NaN, -0.21180493, "- N/A -   "
21.70000022649765, -0.34386584, 0.58200145, NaN, NaN, NaN, -0.20448026, "- N/A -   "
21.749999463558197, -0.34386584, 0.5825555, NaN, NaN, NaN, -0.21668804, "- N/A -   "
21.800000607967377, -0.37825242, 0.58508176, NaN, NaN, NaN, -0.21424648, "- N/A -   "
21.849999845027924, -0.30947924, 0.5872978, NaN, NaN, NaN, -0.20570104, "- N/A -   "
21.89999908208847, -0.34386584, 0.58902633, NaN, NaN, NaN, -0.20081793, "- N/A -   "
21.95000022649765, -0.34386584, 0.58902633, NaN, NaN, NaN, -0.22157115, "- N/A -   "
21.999999463558197, -0.34386584, 0.59106505, NaN, NaN, NaN, -0.2081426, "- N/A -   "
22.050000607967377, -0.34386584, 0.59246117, NaN, NaN, NaN, -0.2081426, "- N/A -   "
22.099999845027924, -0.34386584, 0.59516484, NaN, NaN, NaN, -0.18250626, "- N/A -   "
22.14999908208847, -0.34386584, 0.5954972, NaN, NaN, NaN, -0.19837637, "- N/A -   "
22.20000022649765, 0.2063195, 0.59556365, NaN, NaN, NaN, -0.24110359, "- N/A -   "
22.249999463558197, -0.37825242, 0.59853315, NaN, NaN, NaN, -0.22279193, "- N/A -   "
22.300000607967377, -0.30947924, 0.60125893, NaN, NaN, NaN, -0.2020387, "- N/A -   "
22.349999845027924, -0.34386584, 0.6016578, NaN, NaN, NaN, -0.21912959, "- N/A -   "
22.39999908208847, -0.34386584, 0.6035415, NaN, NaN, NaN, -0.20936337, "- N/A -   "
22.45000022649765, -0.34386584, 0.60398465, NaN, NaN, NaN, -0.22523348, "- N/A -   "
22.499999463558197, -0.37825242, 0.605691, NaN, NaN, NaN, -0.22889581, "- N/A -   "
22.550000607967377, -0.37825242, 0.60815084, NaN, NaN, NaN, -0.1971556, "- N/A -   "
22.599999845027924, -0.34386584, 0.60815084, NaN, NaN, NaN, -0.21790881, "- N/A -   "
22.64999908208847, -0.37825242, 0.61032254, NaN, NaN, NaN, -0.21058415, "- N/A -   "
22.70000022649765, -0.37825242, 0.61123115, NaN, NaN, NaN, -0.21668804, "- N/A -   "
22.749999463558197, -0.30947924, 0.613425, NaN, NaN, NaN, -0.20081793, "- N/A -   "
22.800000607967377, -0.34386584, 0.6145995, NaN, NaN, NaN, -0.20325948, "- N/A -   "
22.849999845027924, -0.37825242, 0.6158405, NaN, NaN, NaN, -0.23133737, "- N/A -   "
22.89999908208847, -0.30947924, 0.61838895, NaN, NaN, NaN, -0.21668804, "- N/A -   "
22.95000022649765, -0.37825242, 0.62073797, NaN, NaN, NaN, -0.1971556, "- N/A -   "
22.999999463558197, -0.17193292, 0.62076014, NaN, NaN, NaN, -0.21912959, "- N/A -   "
23.050000607967377, -0.37825242, 0.6229762, NaN, NaN, NaN, -0.20325948, "- N/A -   "
23.099999845027924, -0.37825242, 0.62335294, NaN, NaN, NaN, -0.21790881, "- N/A -   "
23.14999908208847, -0.10315975, 0.62479335, NaN, NaN, NaN, -0.24842826, "- N/A -   "
23.20000022649765, -0.37825242, 0.627364, NaN, NaN, NaN, -0.2081426, "- N/A -   "
23.249999463558197, 0.17193292, 0.6278294, NaN, NaN, NaN, -0.2240127, "- N/A -   "
23.300000607967377, -0.412639, 0.6301562, NaN, NaN, NaN, -0.20936337, "- N/A -   "
23.349999845027924, -0.34386584, 0.6324609, NaN, NaN, NaN, -0.1971556, "- N/A -   "
23.39999908208847, -0.37825242, 0.6332809, NaN, NaN, NaN, -0.20570104, "- N/A -   "
23.45000022649765, 0.17193292, 0.63343596, NaN, NaN, NaN, -0.23622048, "- N/A -   "
23.499999463558197, -0.37825242, 0.63605094, NaN, NaN, NaN, -0.21668804, "- N/A -   "
23.550000607967377, -0.30947924, 0.63833344, NaN, NaN, NaN, -0.20325948, "- N/A -   "
23.599999845027924, -0.37825242, 0.63984036, NaN, NaN, NaN, -0.19959715, "- N/A -   "
23.64999908208847, -0.37825242, 0.63984036, NaN, NaN, NaN, -0.22157115, "- N/A -   "
23.70000022649765, -0.412639, 0.6419234, NaN, NaN, NaN, -0.21546726, "- N/A -   "
23.749999463558197, -0.412639, 0.6433417, NaN, NaN, NaN, -0.21546726, "- N/A -   "
23.800000607967377, -0.412639, 0.64580154, NaN, NaN, NaN, -0.20081793, "- N/A -   "
23.849999845027924, -0.13754633, 0.64591235, NaN, NaN, NaN, -0.21912959, "- N/A -   "
23.89999908208847, -0.412639, 0.64792895, NaN, NaN, NaN, -0.20692182, "- N/A -   "
23.95000022649765, 0.17193292, 0.64828354, NaN, NaN, NaN, -0.24232437, "- N/A -   "
23.999999463558197, -0.37825242, 0.6519179, NaN, NaN, NaN, -0.1910517, "- N/A -   "
24.050000607967377, -0.412639, 0.6524053, NaN, NaN, NaN, -0.2020387, "- N/A -   "
24.099999845027924, 0.13754633, 0.65293723, NaN, NaN, NaN, -0.24232437, "- N/A -   "
24.14999908208847, -0.412639, 0.6554635, NaN, NaN, NaN, -0.22035037, "- N/A -   "
24.20000022649765, -0.37825242, 0.658012, NaN, NaN, NaN, -0.1971556, "- N/A -   "
24.249999463558197, -0.412639, 0.65887624, NaN, NaN, NaN, -0.2081426, "- N/A -   "
24.300000607967377, -0.37825242, 0.66018367, NaN, NaN, NaN, -0.2081426, "- N/A -   "
24.349999845027924, -0.412639, 0.662156, NaN, NaN, NaN, -0.20448026, "- N/A -   "
24.39999908208847, -0.412639, 0.6647266, NaN, NaN, NaN, -0.18861015, "- N/A -   "
24.45000022649765, -0.412639, 0.6649925, NaN, NaN, NaN, -0.20692182, "- N/A -   "
24.499999463558197, -0.412639, 0.6662335, NaN, NaN, NaN, -0.20692182, "- N/A -   "
24.550000607967377, -0.37825242, 0.6676075, NaN, NaN, NaN, -0.20570104, "- N/A -   "
24.599999845027924, -0.4470256, 0.66811717, NaN, NaN, NaN, -0.21668804, "- N/A -   "
24.64999908208847, -0.37825242, 0.6698235, NaN, NaN, NaN, -0.24842826, "- N/A -   "
24.70000022649765, -0.412639, 0.67179585, NaN, NaN, NaN, -0.23866203, "- N/A -   "
24.749999463558197, -0.412639, 0.67254925, NaN, NaN, NaN, -0.2459867, "- N/A -   "
24.800000607967377, -0.4470256, 0.6742778, NaN, NaN, NaN, -0.27040225, "- N/A -   "
24.849999845027924, -0.412639, 0.677203, NaN, NaN, NaN, -0.2349997, "- N/A -   "
24.89999908208847, 0.13754633, 0.6785548, NaN, NaN, NaN, -0.23377892, "- N/A -   "
24.95000022649765, -0.412639, 0.6808373, NaN, NaN, NaN, -0.21546726, "- N/A -   "
24.999999463558197, -0.37825242, 0.68354094, NaN, NaN, NaN, -0.1910517, "- N/A -   "
25.050000607967377, -0.412639, 0.6842057, NaN, NaN, NaN, -0.20081793, "- N/A -   "
25.099999845027924, -0.412639, 0.6842057, NaN, NaN, NaN, -0.22279193, "- N/A -   "
25.14999908208847, -0.4470256, 0.68620014, NaN, NaN, NaN, -0.21058415, "- N/A -   "
25.20000022649765, -0.4470256, 0.68759626, NaN, NaN, NaN, -0.21058415, "- N/A -   "
25.249999463558197, -0.48141217, 0.69001174, NaN, NaN, NaN, -0.19959715, "- N/A -   "
25.300000607967377, -0.37825242, 0.69018906, NaN, NaN, NaN, -0.21668804, "- N/A -   "