File: BME243_Tues_FA21_RT_Letterman_10.csv
"Time", "Load (N)", "Position (mm)", "Strain(Axial) (in)", "Strain(Transverse) (in)", "Auxiliary ()", "Control Out (V)", "Stress (MPa)"
0.0, 0.24070609, 0.0030581502, NaN, NaN, NaN, -0.24232437, "- N/A -   "
0.029999971389770508, -0.13754633, 0.0051633986, NaN, NaN, NaN, -0.20936337, "- N/A -   "
0.06000000238418579, 0.0, 0.006825437, NaN, NaN, NaN, -0.1971556, "- N/A -   "
0.0899999737739563, 0.068773165, 0.0070913625, NaN, NaN, NaN, -0.20570104, "- N/A -   "
0.12000000476837158, 0.6189585, 1.1080254E-4, NaN, NaN, NaN, -0.21790881, "- N/A -   "
0.15000003576278687, 0.13754633, 0.0017285197, NaN, NaN, NaN, -0.20570104, "- N/A -   "
0.18000000715255737, 0.2063195, 0.002437656, NaN, NaN, NaN, -0.20936337, "- N/A -   "
0.20999997854232788, 0.24070609, 0.002659261, NaN, NaN, NaN, -0.21912959, "- N/A -   "
0.2399999499320984, 0.27509266, 0.0028143846, NaN, NaN, NaN, -0.22767504, "- N/A -   "
0.27000004053115845, 0.30947924, 0.0031024711, NaN, NaN, NaN, -0.23622048, "- N/A -   "
0.30000001192092896, 0.37825242, 0.0035678418, NaN, NaN, NaN, -0.24232437, "- N/A -   "
0.32999998331069946, 0.48141217, 0.0044099414, NaN, NaN, NaN, -0.24110359, "- N/A -   "
0.35999995470046997, 0.51579875, 0.0062049422, NaN, NaN, NaN, -0.22279193, "- N/A -   "
0.39000004529953003, 0.6189585, 0.006736795, NaN, NaN, NaN, -0.22767504, "- N/A -   "
0.42000001668930054, 0.6189585, 0.008221549, NaN, NaN, NaN, -0.21424648, "- N/A -   "
0.44999998807907104, 0.75650483, 0.008975006, NaN, NaN, NaN, -0.21668804, "- N/A -   "
0.47999995946884155, 0.99721086, 0.00913013, NaN, NaN, NaN, -0.22523348, "- N/A -   "
0.5099999308586121, 0.9284377, 0.011013773, NaN, NaN, NaN, -0.20081793, "- N/A -   "
0.5400000214576721, 1.065984, 0.012697971, NaN, NaN, NaN, -0.18250626, "- N/A -   "
0.5699999928474426, 1.065984, 0.0128309345, NaN, NaN, NaN, -0.19227248, "- N/A -   "
0.5999999642372131, 1.1003706, 0.0128309345, NaN, NaN, NaN, -0.20570104, "- N/A -   "
0.6299999356269836, 1.065984, 0.0128309345, NaN, NaN, NaN, -0.21790881, "- N/A -   "
0.6600000262260437, 1.5473962, 0.013407108, NaN, NaN, NaN, -0.22157115, "- N/A -   "
0.6899999976158142, 1.1347572, 0.01484754, NaN, NaN, NaN, -0.20936337, "- N/A -   "
0.7199999690055847, 1.2035304, 0.015268591, NaN, NaN, NaN, -0.21546726, "- N/A -   "
0.7499999403953552, 1.237917, 0.015401553, NaN, NaN, NaN, -0.22767504, "- N/A -   "
0.7800000309944153, 1.2723036, 0.01566748, NaN, NaN, NaN, -0.23377892, "- N/A -   "
0.8100000023841858, 1.237917, 0.016044209, NaN, NaN, NaN, -0.23744126, "- N/A -   "
0.8399999737739563, 1.3066901, 0.016620383, NaN, NaN, NaN, -0.23866203, "- N/A -   "
0.8699999451637268, 1.4098499, 0.01786137, NaN, NaN, NaN, -0.23377892, "- N/A -   "
0.9000000357627869, 1.4098499, 0.01912452, NaN, NaN, NaN, -0.22767504, "- N/A -   "
0.9300000071525574, 1.9944217, 0.02009958, NaN, NaN, NaN, -0.22523348, "- N/A -   "
0.9599999785423279, 1.6161695, 0.021517854, NaN, NaN, NaN, -0.2130257, "- N/A -   "
0.9899999499320984, 1.650556, 0.021650817, NaN, NaN, NaN, -0.22157115, "- N/A -   "
1.0200000405311584, 2.1663547, 0.022559399, NaN, NaN, NaN, -0.21912959, "- N/A -   "
1.050000011920929, 1.8912619, 0.024509523, NaN, NaN, NaN, -0.19593482, "- N/A -   "
1.0799999833106995, 1.8912619, 0.025484584, NaN, NaN, NaN, -0.19471404, "- N/A -   "
1.10999995470047, 1.9256487, 0.025484584, NaN, NaN, NaN, -0.20692182, "- N/A -   "
1.14000004529953, 2.475834, 0.02561755, NaN, NaN, NaN, -0.21912959, "- N/A -   "
1.169999897480011, 1.9600352, 0.027213104, NaN, NaN, NaN, -0.20692182, "- N/A -   "
1.2000001072883606, 1.9944217, 0.027656315, NaN, NaN, NaN, -0.2130257, "- N/A -   "
1.230000078678131, 2.5789936, 0.027789278, NaN, NaN, NaN, -0.2240127, "- N/A -   "
1.2600000500679016, 2.0975816, 0.0296286, NaN, NaN, NaN, -0.20325948, "- N/A -   "
1.2900000214576721, 2.0975816, 0.031246318, NaN, NaN, NaN, -0.19227248, "- N/A -   "
1.3199999928474426, 2.063195, 0.03175601, NaN, NaN, NaN, -0.1971556, "- N/A -   "
1.3499999642372131, 1.9944217, 0.03175601, NaN, NaN, NaN, -0.21058415, "- N/A -   "
1.3799999356269836, 2.475834, 0.032442983, NaN, NaN, NaN, -0.2130257, "- N/A -   "
1.4099999070167542, 2.0288084, 0.033839095, NaN, NaN, NaN, -0.20692182, "- N/A -   "
1.4399998784065247, 1.9944217, 0.034348786, NaN, NaN, NaN, -0.21180493, "- N/A -   "
1.4700000882148743, 1.9944217, 0.034592554, NaN, NaN, NaN, -0.22157115, "- N/A -   "
1.5000000596046448, 1.9944217, 0.03488064, NaN, NaN, NaN, -0.23011659, "- N/A -   "
1.5300000309944153, 1.9944217, 0.035346013, NaN, NaN, NaN, -0.23744126, "- N/A -   "
1.5600000023841858, 2.063195, 0.036343236, NaN, NaN, NaN, -0.23622048, "- N/A -   "
1.5899999737739563, 2.0975816, 0.03796095, NaN, NaN, NaN, -0.22279193, "- N/A -   "
1.6199999451637268, 2.6477668, 0.038603608, NaN, NaN, NaN, -0.22889581, "- N/A -   "
1.6499999165534973, 2.131968, 0.040265642, NaN, NaN, NaN, -0.21180493, "- N/A -   "
1.6799998879432678, 2.1663547, 0.04055373, NaN, NaN, NaN, -0.21912959, "- N/A -   "
1.7100000977516174, 2.1663547, 0.04221577, NaN, NaN, NaN, -0.2020387, "- N/A -   "
1.740000069141388, 2.2695143, 0.043767005, NaN, NaN, NaN, -0.1971556, "- N/A -   "
1.7700000405311584, 2.0975816, 0.044188052, NaN, NaN, NaN, -0.20325948, "- N/A -   "
1.800000011920929, 1.7881024, 0.044188052, NaN, NaN, NaN, -0.21546726, "- N/A -   "
1.8299999833106995, 1.650556, 0.0454512, NaN, NaN, NaN, -0.20570104, "- N/A -   "
1.85999995470047, 1.4786232, 0.046537068, NaN, NaN, NaN, -0.20448026, "- N/A -   "
1.8899999260902405, 1.3066901, 0.046891633, NaN, NaN, NaN, -0.20936337, "- N/A -   "
1.919999897480011, 1.065984, 0.046935957, NaN, NaN, NaN, -0.22035037, "- N/A -   "
1.9500001072883606, 1.3066901, 0.047401328, NaN, NaN, NaN, -0.22767504, "- N/A -   "
1.980000078678131, 0.5501853, 0.04950658, NaN, NaN, NaN, -0.19471404, "- N/A -   "
2.0100000500679016, -0.412639, 0.050703242, NaN, NaN, NaN, -0.18983093, "- N/A -   "
2.040000021457672, -1.5817828, 0.050725404, NaN, NaN, NaN, -0.2020387, "- N/A -   "
2.0699999928474426, -2.0975816, 0.050725404, NaN, NaN, NaN, -0.21546726, "- N/A -   "
2.099999964237213, -1.8568754, 0.051633984, NaN, NaN, NaN, -0.21790881, "- N/A -   "
2.1299999356269836, -2.5102205, 0.052897133, NaN, NaN, NaN, -0.20936337, "- N/A -   "
2.159999907016754, -2.6477668, 0.0531409, NaN, NaN, NaN, -0.21912959, "- N/A -   "
2.1899998784065247, -2.5789936, 0.053229544, NaN, NaN, NaN, -0.22889581, "- N/A -   "
2.2200000882148743, -2.7853131, 0.055113185, NaN, NaN, NaN, -0.20570104, "- N/A -   "
2.2500000596046448, -2.8196998, 0.05695251, NaN, NaN, NaN, -0.18494782, "- N/A -   "
2.2800000309944153, -2.9916327, 0.057240594, NaN, NaN, NaN, -0.19227248, "- N/A -   "
2.310000002384186, -3.0947924, 0.057240594, NaN, NaN, NaN, -0.20570104, "- N/A -   "
2.3399999737739563, -3.1635656, 0.057240594, NaN, NaN, NaN, -0.21790881, "- N/A -   "
2.369999945163727, -2.7853131, 0.058149174, NaN, NaN, NaN, -0.21546726, "- N/A -   "
2.3999999165534973, -3.2667255, 0.059368003, NaN, NaN, NaN, -0.20936337, "- N/A -   "
2.429999887943268, -3.301112, 0.05974473, NaN, NaN, NaN, -0.21546726, "- N/A -   "
2.4600000977516174, -3.3698852, 0.059922017, NaN, NaN, NaN, -0.22523348, "- N/A -   "
2.490000069141388, -3.4730446, 0.06018794, NaN, NaN, NaN, -0.23133737, "- N/A -   "
2.5200000405311584, -3.5418181, 0.060631152, NaN, NaN, NaN, -0.23377892, "- N/A -   "
2.550000011920929, -3.5074315, 0.061451092, NaN, NaN, NaN, -0.23255815, "- N/A -   "
2.5799999833106995, -3.4730446, 0.063090965, NaN, NaN, NaN, -0.21790881, "- N/A -   "
2.60999995470047, -2.9572463, 0.06353418, NaN, NaN, NaN, -0.2240127, "- N/A -   "
2.6399999260902405, -3.5762048, 0.065196216, NaN, NaN, NaN, -0.2081426, "- N/A -   "
2.669999897480011, -3.5762048, 0.06577239, NaN, NaN, NaN, -0.21180493, "- N/A -   "
2.7000001072883606, -3.6449778, 0.06577239, NaN, NaN, NaN, -0.22523348, "- N/A -   "
2.730000078678131, -3.7137508, 0.06730146, NaN, NaN, NaN, -0.21180493, "- N/A -   "
2.7600000500679016, -3.6105912, 0.069140784, NaN, NaN, NaN, -0.19593482, "- N/A -   "
2.790000021457672, -3.7137508, 0.0698056, NaN, NaN, NaN, -0.19837637, "- N/A -   "
2.8199999928474426, -3.7825239, 0.0698056, NaN, NaN, NaN, -0.21180493, "- N/A -   "
2.849999964237213, -3.3698852, 0.07060338, NaN, NaN, NaN, -0.2130257, "- N/A -   "
2.8799999356269836, -3.8856838, 0.07184437, NaN, NaN, NaN, -0.20325948, "- N/A -   "
2.909999907016754, -3.9200704, 0.072021656, NaN, NaN, NaN, -0.21180493, "- N/A -   "
2.9399998784065247, -3.4730446, 0.072198935, NaN, NaN, NaN, -0.22157115, "- N/A -   "
2.9700000882148743, -3.9888434, 0.07406042, NaN, NaN, NaN, -0.20081793, "- N/A -   "
3.0000000596046448, -3.9888434, 0.0757003, NaN, NaN, NaN, -0.18861015, "- N/A -   "
3.0300000309944153, -4.0920033, 0.0761435, NaN, NaN, NaN, -0.19593482, "- N/A -   "
3.060000002384186, -4.2295494, 0.0761435, NaN, NaN, NaN, -0.20936337, "- N/A -   "
3.0899999737739563, -3.8169107, 0.0766532, NaN, NaN, NaN, -0.21424648, "- N/A -   "
3.119999945163727, -4.4014826, 0.07818227, NaN, NaN, NaN, -0.20325948, "- N/A -   "
3.1499999165534973, -4.435869, 0.078935735, NaN, NaN, NaN, -0.20325948, "- N/A -   "
3.180000126361847, -4.5390286, 0.07953406, NaN, NaN, NaN, -0.20692182, "- N/A -   "
3.2099998593330383, -4.5046425, 0.080509126, NaN, NaN, NaN, -0.20448026, "- N/A -   "
3.240000069141388, -4.5390286, 0.08214901, NaN, NaN, NaN, -0.1910517, "- N/A -   "
3.2699998021125793, -4.607802, 0.082481414, NaN, NaN, NaN, -0.19837637, "- N/A -   "
3.300000011920929, -4.710962, 0.082481414, NaN, NaN, NaN, -0.21180493, "- N/A -   "
3.3300002217292786, -4.263936, 0.08316839, NaN, NaN, NaN, -0.2130257, "- N/A -   "
3.35999995470047, -4.8141217, 0.0845645, NaN, NaN, NaN, -0.20570104, "- N/A -   "
3.3900001645088196, -4.848508, 0.08483043, NaN, NaN, NaN, -0.2130257, "- N/A -   "
3.419999897480011, -4.951668, 0.086004935, NaN, NaN, NaN, -0.20325948, "- N/A -   "
3.4500001072883606, -4.8828945, 0.087666966, NaN, NaN, NaN, -0.19471404, "- N/A -   "
3.479999840259552, -5.020441, 0.08848691, NaN, NaN, NaN, -0.1971556, "- N/A -   "
3.5100000500679016, -5.0892143, 0.08848691, NaN, NaN, NaN, -0.20936337, "- N/A -   "
3.539999783039093, -4.642189, 0.0888858, NaN, NaN, NaN, -0.21790881, "- N/A -   "
3.5699999928474426, -5.157987, 0.0904592, NaN, NaN, NaN, -0.20325948, "- N/A -   "
3.6000002026557922, -5.261147, 0.09123481, NaN, NaN, NaN, -0.20570104, "- N/A -   "
3.6299999356269836, -5.2955337, 0.09158938, NaN, NaN, NaN, -0.21424648, "- N/A -   "
3.6600001454353333, -5.364307, 0.09192179, NaN, NaN, NaN, -0.22035037, "- N/A -   "
3.6899998784065247, -5.43308, 0.09238716, NaN, NaN, NaN, -0.22279193, "- N/A -   "
3.7200000882148743, -5.364307, 0.09349518, NaN, NaN, NaN, -0.21912959, "- N/A -   "
3.7499998211860657, -5.364307, 0.09509075, NaN, NaN, NaN, -0.20448026, "- N/A -   "
3.7800000309944153, -5.4674664, 0.095290184, NaN, NaN, NaN, -0.21424648, "- N/A -   "
3.8099997639656067, -4.951668, 0.09544531, NaN, NaN, NaN, -0.22523348, "- N/A -   "
3.8399999737739563, -5.5362396, 0.09710735, NaN, NaN, NaN, -0.21180493, "- N/A -   "
3.870000183582306, -5.5362396, 0.097772166, NaN, NaN, NaN, -0.2130257, "- N/A -   "
3.8999999165534973, -5.605013, 0.0981489, NaN, NaN, NaN, -0.21668804, "- N/A -   "
3.930000126361847, -5.6393995, 0.098725066, NaN, NaN, NaN, -0.21912959, "- N/A -   "
3.9599998593330383, -5.5706263, 0.10012118, NaN, NaN, NaN, -0.20692182, "- N/A -   "
3.990000069141388, -5.6393995, 0.10158377, NaN, NaN, NaN, -0.19593482, "- N/A -   "
4.019999802112579, -5.673786, 0.10167242, NaN, NaN, NaN, -0.20692182, "- N/A -   "
4.050000011920929, -5.7425594, 0.10167242, NaN, NaN, NaN, -0.21912959, "- N/A -   "
4.080000221729279, -5.2955337, 0.10240371, NaN, NaN, NaN, -0.22035037, "- N/A -   "
4.10999995470047, -5.7769456, 0.10379983, NaN, NaN, NaN, -0.20936337, "- N/A -   "
4.14000016450882, -5.8113327, 0.10433167, NaN, NaN, NaN, -0.21180493, "- N/A -   "
4.169999897480011, -5.845719, 0.1045976, NaN, NaN, NaN, -0.22035037, "- N/A -   "
4.200000107288361, -5.9144926, 0.10497433, NaN, NaN, NaN, -0.22645426, "- N/A -   "
4.229999840259552, -5.845719, 0.10574995, NaN, NaN, NaN, -0.22889581, "- N/A -   "
4.260000050067902, -5.8113327, 0.10738982, NaN, NaN, NaN, -0.21790881, "- N/A -   "
4.289999783039093, -5.2955337, 0.10785519, NaN, NaN, NaN, -0.22523348, "- N/A -   "
4.319999992847443, -5.8801055, 0.109561555, NaN, NaN, NaN, -0.21058415, "- N/A -   "
4.350000202655792, -5.9144926, 0.11009341, NaN, NaN, NaN, -0.2130257, "- N/A -   "
4.379999935626984, -5.6393995, 0.110115565, NaN, NaN, NaN, -0.22645426, "- N/A -   "
4.410000145435333, -5.948879, 0.1117776, NaN, NaN, NaN, -0.2081426, "- N/A -   "
4.439999878406525, -5.8801055, 0.11350612, NaN, NaN, NaN, -0.18983093, "- N/A -   "
4.470000088214874, -5.9832654, 0.11410446, NaN, NaN, NaN, -0.1971556, "- N/A -   "
4.499999821186066, -6.0520387, 0.11410446, NaN, NaN, NaN, -0.20936337, "- N/A -   "
4.530000030994415, -5.5706263, 0.11468063, NaN, NaN, NaN, -0.21424648, "- N/A -   "
4.559999763965607, -6.0520387, 0.116165385, NaN, NaN, NaN, -0.20570104, "- N/A -   "
4.589999973773956, -6.086425, 0.11665292, NaN, NaN, NaN, -0.21058415, "- N/A -   "
4.620000183582306, -6.155198, 0.11676372, NaN, NaN, NaN, -0.21912959, "- N/A -   "
4.649999916553497, -6.223972, 0.116941005, NaN, NaN, NaN, -0.22645426, "- N/A -   "
4.680000126361847, -6.258358, 0.11727341, NaN, NaN, NaN, -0.2349997, "- N/A -   "
4.709999859333038, -6.2927446, 0.117893904, NaN, NaN, NaN, -0.23622048, "- N/A -   "
4.740000069141388, -6.223972, 0.1193565, NaN, NaN, NaN, -0.2240127, "- N/A -   "
4.769999802112579, -6.223972, 0.12075261, NaN, NaN, NaN, -0.21668804, "- N/A -   "
4.800000011920929, -6.223972, 0.12097421, NaN, NaN, NaN, -0.2240127, "- N/A -   "
4.830000221729279, -6.258358, 0.12239248, NaN, NaN, NaN, -0.21180493, "- N/A -   "
4.85999995470047, -6.258358, 0.123567, NaN, NaN, NaN, -0.20936337, "- N/A -   "
4.89000016450882, -6.2927446, 0.12445342, NaN, NaN, NaN, -0.20936337, "- N/A -   "
4.919999897480011, -6.258358, 0.12604898, NaN, NaN, NaN, -0.19959715, "- N/A -   "
4.950000107288361, -6.2927446, 0.12680243, NaN, NaN, NaN, -0.20081793, "- N/A -   "
4.979999840259552, -6.361518, 0.12680243, NaN, NaN, NaN, -0.2130257, "- N/A -   "
5.010000050067902, -5.9144926, 0.12775533, NaN, NaN, NaN, -0.21058415, "- N/A -   "
5.039999783039093, -6.395904, 0.12897415, NaN, NaN, NaN, -0.20570104, "- N/A -   "
5.069999992847443, -6.258358, 0.12915145, NaN, NaN, NaN, -0.21790881, "- N/A -   "
5.100000202655792, -6.395904, 0.1308578, NaN, NaN, NaN, -0.2020387, "- N/A -   "
5.129999935626984, -6.3271313, 0.13245335, NaN, NaN, NaN, -0.19227248, "- N/A -   "
5.160000145435333, -6.430291, 0.13289657, NaN, NaN, NaN, -0.19959715, "- N/A -   "
5.189999878406525, -6.464678, 0.13289657, NaN, NaN, NaN, -0.21180493, "- N/A -   "
5.220000088214874, -5.9832654, 0.13365002, NaN, NaN, NaN, -0.21058415, "- N/A -   "
5.249999821186066, -6.464678, 0.1350683, NaN, NaN, NaN, -0.20325948, "- N/A -   "
5.280000030994415, -6.533451, 0.13573311, NaN, NaN, NaN, -0.20448026, "- N/A -   "
5.309999763965607, -6.602224, 0.13604335, NaN, NaN, NaN, -0.21180493, "- N/A -   "
5.339999973773956, -6.602224, 0.13639793, NaN, NaN, NaN, -0.21790881, "- N/A -   "
5.370000183582306, -6.670997, 0.13695194, NaN, NaN, NaN, -0.22035037, "- N/A -   "
5.399999916553497, -6.533451, 0.13839237, NaN, NaN, NaN, -0.2130257, "- N/A -   "
5.430000126361847, -6.602224, 0.13958904, NaN, NaN, NaN, -0.20692182, "- N/A -   "
5.459999859333038, -6.63661, 0.13963336, NaN, NaN, NaN, -0.21790881, "- N/A -   "
5.490000069141388, -6.1895847, 0.14027601, NaN, NaN, NaN, -0.22279193, "- N/A -   "
5.519999802112579, -6.670997, 0.14169429, NaN, NaN, NaN, -0.21058415, "- N/A -   "
5.550000011920929, -6.7053833, 0.1421375, NaN, NaN, NaN, -0.21546726, "- N/A -   "
5.580000221729279, -6.7397704, 0.14240344, NaN, NaN, NaN, -0.22523348, "- N/A -   "
5.60999995470047, -6.774157, 0.14289096, NaN, NaN, NaN, -0.23133737, "- N/A -   "
5.64000016450882, -6.7397704, 0.14397682, NaN, NaN, NaN, -0.22889581, "- N/A -   "
5.669999897480011, -6.7397704, 0.14574966, NaN, NaN, NaN, -0.20692182, "- N/A -   "
5.700000107288361, -6.808543, 0.14603774, NaN, NaN, NaN, -0.21546726, "- N/A -   "
5.729999840259552, -6.2927446, 0.14628153, NaN, NaN, NaN, -0.22523348, "- N/A -   "
5.760000050067902, -6.8429303, 0.14794356, NaN, NaN, NaN, -0.2130257, "- N/A -   "
5.789999783039093, -6.8429303, 0.148697, NaN, NaN, NaN, -0.2130257, "- N/A -   "
5.819999992847443, -6.9460893, 0.14905158, NaN, NaN, NaN, -0.22035037, "- N/A -   "
5.850000202655792, -6.9804764, 0.14953911, NaN, NaN, NaN, -0.22523348, "- N/A -   "
5.879999935626984, -6.911703, 0.15071362, NaN, NaN, NaN, -0.22279193, "- N/A -   "
5.910000145435333, -6.911703, 0.15206541, NaN, NaN, NaN, -0.21790881, "- N/A -   "
5.939999878406525, -6.430291, 0.15264158, NaN, NaN, NaN, -0.22157115, "- N/A -   "
5.970000088214874, -6.9460893, 0.15423714, NaN, NaN, NaN, -0.20936337, "- N/A -   "
5.999999821186066, -7.014863, 0.15445875, NaN, NaN, NaN, -0.21790881, "- N/A -   "
6.030000030994415, -6.567837, 0.15492412, NaN, NaN, NaN, -0.22523348, "- N/A -   "
6.059999763965607, -7.014863, 0.15685208, NaN, NaN, NaN, -0.2020387, "- N/A -   "
6.089999973773956, -7.0836363, 0.15831468, NaN, NaN, NaN, -0.19349326, "- N/A -   "
6.120000183582306, -7.0836363, 0.1584033, NaN, NaN, NaN, -0.20570104, "- N/A -   "
6.149999916553497, -6.602224, 0.15855843, NaN, NaN, NaN, -0.21668804, "- N/A -   "
6.180000126361847, -7.0836363, 0.16017616, NaN, NaN, NaN, -0.20325948, "- N/A -   "
6.209999859333038, -7.1524096, 0.16086313, NaN, NaN, NaN, -0.20570104, "- N/A -   "
6.240000069141388, -7.1867957, 0.1609296, NaN, NaN, NaN, -0.21668804, "- N/A -   "
6.269999802112579, -6.7053833, 0.16174956, NaN, NaN, NaN, -0.2130257, "- N/A -   "
6.300000011920929, -7.1180224, 0.16369969, NaN, NaN, NaN, -0.19227248, "- N/A -   "
6.330000221729279, -7.1867957, 0.16478555, NaN, NaN, NaN, -0.18738937, "- N/A -   "
6.35999995470047, -7.2555685, 0.1648077, NaN, NaN, NaN, -0.19837637, "- N/A -   "
6.39000016450882, -7.2899556, 0.1648077, NaN, NaN, NaN, -0.21180493, "- N/A -   "
6.419999897480011, -6.8773165, 0.1656498, NaN, NaN, NaN, -0.21180493, "- N/A -   "
6.450000107288361, -7.2555685, 0.16693512, NaN, NaN, NaN, -0.2081426, "- N/A -   "
6.479999840259552, -7.2899556, 0.1675556, NaN, NaN, NaN, -0.20936337, "- N/A -   "
6.510000050067902, -7.3243423, 0.16802098, NaN, NaN, NaN, -0.21180493, "- N/A -   "
6.539999783039093, -7.3243423, 0.16870795, NaN, NaN, NaN, -0.2130257, "- N/A -   "
6.569999992847443, -7.2555685, 0.17021486, NaN, NaN, NaN, -0.20448026, "- N/A -   "
6.600000202655792, -7.3243423, 0.17110129, NaN, NaN, NaN, -0.2020387, "- N/A -   "
6.629999935626984, -7.3587284, 0.17110129, NaN, NaN, NaN, -0.21546726, "- N/A -   "
6.660000145435333, -7.3587284, 0.17234229, NaN, NaN, NaN, -0.20448026, "- N/A -   "
6.689999878406525, -7.3931155, 0.17331733, NaN, NaN, NaN, -0.2020387, "- N/A -   "
6.720000088214874, -7.3931155, 0.17342815, NaN, NaN, NaN, -0.2130257, "- N/A -   "
6.749999821186066, -7.2555685, 0.17451401, NaN, NaN, NaN, -0.20448026, "- N/A -   "
6.780000030994415, -7.3587284, 0.17622037, NaN, NaN, NaN, -0.19349326, "- N/A -   "
6.809999763965607, -7.3931155, 0.17719543, NaN, NaN, NaN, -0.19227248, "- N/A -   "
6.839999973773956, -7.4618883, 0.17721759, NaN, NaN, NaN, -0.20448026, "- N/A -   "
6.870000183582306, -7.3587284, 0.17721759, NaN, NaN, NaN, -0.21790881, "- N/A -   "
6.899999916553497, -7.496275, 0.17876883, NaN, NaN, NaN, -0.2020387, "- N/A -   "
6.930000126361847, -7.496275, 0.17976604, NaN, NaN, NaN, -0.20081793, "- N/A -   "
6.959999859333038, -7.496275, 0.18020925, NaN, NaN, NaN, -0.20448026, "- N/A -   "
6.990000069141388, -7.5306616, 0.18049735, NaN, NaN, NaN, -0.2130257, "- N/A -   "
7.019999802112579, -7.5306616, 0.18087406, NaN, NaN, NaN, -0.21668804, "- N/A -   "
7.050000011920929, -7.496275, 0.18162753, NaN, NaN, NaN, -0.21790881, "- N/A -   "
7.080000221729279, -7.4618883, 0.18331173, NaN, NaN, NaN, -0.20692182, "- N/A -   "
7.10999995470047, -7.496275, 0.18393223, NaN, NaN, NaN, -0.21058415, "- N/A -   "
7.14000016450882, -7.014863, 0.1839987, NaN, NaN, NaN, -0.22279193, "- N/A -   "
7.169999897480011, -7.599435, 0.18563859, NaN, NaN, NaN, -0.20936337, "- N/A -   "
7.199999630451202, -7.5650477, 0.18639204, NaN, NaN, NaN, -0.21058415, "- N/A -   "
7.23000031709671, -7.599435, 0.18679093, NaN, NaN, NaN, -0.21424648, "- N/A -   "
7.260000050067902, -7.599435, 0.18725629, NaN, NaN, NaN, -0.21912959, "- N/A -   "
7.289999783039093, -7.5650477, 0.18834215, NaN, NaN, NaN, -0.21668804, "- N/A -   "
7.319999516010284, -7.599435, 0.19007067, NaN, NaN, NaN, -0.20081793, "- N/A -   "
7.350000202655792, -7.6338215, 0.19033661, NaN, NaN, NaN, -0.20936337, "- N/A -   "
7.379999935626984, -7.6338215, 0.19033661, NaN, NaN, NaN, -0.22157115, "- N/A -   "
7.409999668598175, -7.6338215, 0.19177705, NaN, NaN, NaN, -0.20936337, "- N/A -   "
7.440000355243683, -7.6682076, 0.19281858, NaN, NaN, NaN, -0.20692182, "- N/A -   "
7.470000088214874, -7.7025948, 0.19330612, NaN, NaN, NaN, -0.21058415, "- N/A -   "
7.499999821186066, -7.7025948, 0.1937715, NaN, NaN, NaN, -0.21180493, "- N/A -   "
7.529999554157257, -7.6682076, 0.19481303, NaN, NaN, NaN, -0.20936337, "- N/A -   "
7.560000240802765, -7.6682076, 0.1962313, NaN, NaN, NaN, -0.2020387, "- N/A -   "
7.589999973773956, -7.736981, 0.19636427, NaN, NaN, NaN, -0.21180493, "- N/A -   "
7.619999706745148, -7.2555685, 0.19709557, NaN, NaN, NaN, -0.21546726, "- N/A -   "
7.6500003933906555, -7.7713675, 0.19849168, NaN, NaN, NaN, -0.20570104, "- N/A -   "
7.680000126361847, -7.7713675, 0.19858031, NaN, NaN, NaN, -0.21546726, "- N/A -   "
7.709999859333038, -7.2211823, 0.1987576, NaN, NaN, NaN, -0.22645426, "- N/A -   "
7.73999959230423, -7.805754, 0.20053044, NaN, NaN, NaN, -0.21058415, "- N/A -   "
7.7700002789497375, -7.7025948, 0.20221464, NaN, NaN, NaN, -0.19349326, "- N/A -   "
7.800000011920929, -7.805754, 0.20276865, NaN, NaN, NaN, -0.19959715, "- N/A -   "
7.82999974489212, -7.840141, 0.20276865, NaN, NaN, NaN, -0.21180493, "- N/A -   "
7.860000431537628, -7.3587284, 0.2036994, NaN, NaN, NaN, -0.20936337, "- N/A -   "
7.89000016450882, -7.874528, 0.20496254, NaN, NaN, NaN, -0.20081793, "- N/A -   "
7.919999897480011, -7.874528, 0.20527278, NaN, NaN, NaN, -0.20570104, "- N/A -   "
7.949999630451202, -7.908914, 0.20533927, NaN, NaN, NaN, -0.21912959, "- N/A -   "
7.98000031709671, -7.9433007, 0.20549439, NaN, NaN, NaN, -0.23011659, "- N/A -   "
8.010000050067902, -7.977687, 0.20584896, NaN, NaN, NaN, -0.23377892, "- N/A -   "
8.039999783039093, -7.977687, 0.20638081, NaN, NaN, NaN, -0.23622048, "- N/A -   "
8.069999516010284, -7.908914, 0.20764396, NaN, NaN, NaN, -0.23011659, "- N/A -   "
8.100000202655792, -7.908914, 0.20921735, NaN, NaN, NaN, -0.21790881, "- N/A -   "
8.129999935626984, -7.5650477, 0.2095276, NaN, NaN, NaN, -0.22767504, "- N/A -   "
8.159999668598175, -7.9433007, 0.21118966, NaN, NaN, NaN, -0.2130257, "- N/A -   "
8.190000355243683, -7.908914, 0.21214256, NaN, NaN, NaN, -0.21180493, "- N/A -   "
8.220000088214874, -7.9433007, 0.21298465, NaN, NaN, NaN, -0.21180493, "- N/A -   "
8.249999821186066, -7.908914, 0.21455804, NaN, NaN, NaN, -0.20081793, "- N/A -   "
8.279999554157257, -7.9433007, 0.2154223, NaN, NaN, NaN, -0.2020387, "- N/A -   "
8.310000240802765, -7.977687, 0.2154223, NaN, NaN, NaN, -0.21424648, "- N/A -   "
8.339999973773956, -7.6338215, 0.21659681, NaN, NaN, NaN, -0.20570104, "- N/A -   "
8.369999706745148, -8.0120735, 0.21772699, NaN, NaN, NaN, -0.19837637, "- N/A -   "
8.400000393390656, -8.0120735, 0.2178378, NaN, NaN, NaN, -0.2081426, "- N/A -   "
8.430000126361847, -7.496275, 0.21830316, NaN, NaN, NaN, -0.21546726, "- N/A -   "
8.459999859333038, -7.9433007, 0.2201425, NaN, NaN, NaN, -0.19593482, "- N/A -   "
8.48999959230423, -7.977687, 0.22144996, NaN, NaN, NaN, -0.19349326, "- N/A -   "
8.520000278949738, -8.04646, 0.2215386, NaN, NaN, NaN, -0.20325948, "- N/A -   "
8.550000011920929, -8.0120735, 0.2215386, NaN, NaN, NaN, -0.21668804, "- N/A -   "
8.57999974489212, -8.04646, 0.2230012, NaN, NaN, NaN, -0.20692182, "- N/A -   "
8.610000431537628, -8.0120735, 0.22413138, NaN, NaN, NaN, -0.20325948, "- N/A -   "
8.64000016450882, -8.04646, 0.22466324, NaN, NaN, NaN, -0.20448026, "- N/A -   "
8.669999897480011, -8.080847, 0.22499564, NaN, NaN, NaN, -0.21058415, "- N/A -   "
8.699999630451202, -8.080847, 0.2255275, NaN, NaN, NaN, -0.2130257, "- N/A -   "
8.73000031709671, -8.0120735, 0.2268793, NaN, NaN, NaN, -0.20570104, "- N/A -   "
8.760000050067902, -8.04646, 0.22812028, NaN, NaN, NaN, -0.19959715, "- N/A -   "
8.789999783039093, -8.115233, 0.22818676, NaN, NaN, NaN, -0.21058415, "- N/A -   "
8.819999516010284, -7.5306616, 0.22825325, NaN, NaN, NaN, -0.22279193, "- N/A -   "
8.850000202655792, -8.080847, 0.2298488, NaN, NaN, NaN, -0.20936337, "- N/A -   "
8.879999935626984, -8.115233, 0.23042497, NaN, NaN, NaN, -0.2130257, "- N/A -   "
8.909999668598175, -8.115233, 0.23062442, NaN, NaN, NaN, -0.22157115, "- N/A -   "
8.940000355243683, -8.115233, 0.23089033, NaN, NaN, NaN, -0.22889581, "- N/A -   "
8.970000088214874, -8.14962, 0.23135571, NaN, NaN, NaN, -0.23377892, "- N/A -   "
8.999999821186066, -8.080847, 0.23235294, NaN, NaN, NaN, -0.23377892, "- N/A -   "
9.029999554157257, -8.115233, 0.23430306, NaN, NaN, NaN, -0.21180493, "- N/A -   "
9.060000240802765, -8.080847, 0.23483491, NaN, NaN, NaN, -0.21546726, "- N/A -   "
9.089999973773956, -7.5650477, 0.23494571, NaN, NaN, NaN, -0.22767504, "- N/A -   "
9.119999706745148, -8.115233, 0.23665206, NaN, NaN, NaN, -0.21058415, "- N/A -   "
9.150000393390656, -8.115233, 0.23751633, NaN, NaN, NaN, -0.20936337, "- N/A -   "
9.180000126361847, -8.14962, 0.23811467, NaN, NaN, NaN, -0.21058415, "- N/A -   "
9.209999859333038, -8.04646, 0.23920053, NaN, NaN, NaN, -0.2081426, "- N/A -   "
9.23999959230423, -8.080847, 0.24057448, NaN, NaN, NaN, -0.20081793, "- N/A -   "
9.270000278949738, -8.115233, 0.24068528, NaN, NaN, NaN, -0.2130257, "- N/A -   "
9.300000011920929, -7.6338215, 0.24157171, NaN, NaN, NaN, -0.20936337, "- N/A -   "
9.32999974489212, -8.115233, 0.24279054, NaN, NaN, NaN, -0.20325948, "- N/A -   "
9.360000431537628, -8.14962, 0.24285702, NaN, NaN, NaN, -0.21546726, "- N/A -   "
9.39000016450882, -7.599435, 0.24298997, NaN, NaN, NaN, -0.22645426, "- N/A -   "
9.419999897480011, -8.14962, 0.2448293, NaN, NaN, NaN, -0.2081426, "- N/A -   "
9.449999630451202, -8.04646, 0.24657997, NaN, NaN, NaN, -0.19227248, "- N/A -   "
9.48000031709671, -8.115233, 0.2470675, NaN, NaN, NaN, -0.1971556, "- N/A -   "
9.510000050067902, -8.14962, 0.2470675, NaN, NaN, NaN, -0.21058415, "- N/A -   "
9.539999783039093, -7.6682076, 0.247688, NaN, NaN, NaN, -0.21546726, "- N/A -   "
9.569999516010284, -8.184007, 0.24917275, NaN, NaN, NaN, -0.2081426, "- N/A -   "
9.600000202655792, -8.184007, 0.24968244, NaN, NaN, NaN, -0.2130257, "- N/A -   "
9.629999935626984, -8.184007, 0.24990405, NaN, NaN, NaN, -0.22279193, "- N/A -   "
9.659999668598175, -8.218393, 0.25025862, NaN, NaN, NaN, -0.23133737, "- N/A -   "
9.690000355243683, -8.218393, 0.25090128, NaN, NaN, NaN, -0.23255815, "- N/A -   "
9.720000088214874, -8.115233, 0.25247467, NaN, NaN, NaN, -0.22035037, "- N/A -   "
9.749999821186066, -8.184007, 0.25369352, NaN, NaN, NaN, -0.2130257, "- N/A -   "
9.779999554157257, -7.599435, 0.25389296, NaN, NaN, NaN, -0.22279193, "- N/A -   "
9.810000240802765, -8.14962, 0.25557715, NaN, NaN, NaN, -0.21058415, "- N/A -   "
9.839999973773956, -8.14962, 0.25653005, NaN, NaN, NaN, -0.21058415, "- N/A -   "
9.869999706745148, -8.184007, 0.25741646, NaN, NaN, NaN, -0.21180493, "- N/A -   "
9.900000393390656, -8.115233, 0.25905636, NaN, NaN, NaN, -0.19837637, "- N/A -   "
9.930000126361847, -8.14962, 0.2598098, NaN, NaN, NaN, -0.19837637, "- N/A -   "
9.959999859333038, -8.218393, 0.2598098, NaN, NaN, NaN, -0.21180493, "- N/A -   "
9.98999959230423, -7.6682076, 0.26051894, NaN, NaN, NaN, -0.2130257, "- N/A -   "
10.020000278949738, -8.218393, 0.26198152, NaN, NaN, NaN, -0.20692182, "- N/A -   "
10.050000011920929, -8.25278, 0.26240256, NaN, NaN, NaN, -0.21180493, "- N/A -   "
10.07999974489212, -8.218393, 0.2625134, NaN, NaN, NaN, -0.22279193, "- N/A -   "
10.110000431537628, -8.218393, 0.26371005, NaN, NaN, NaN, -0.21546726, "- N/A -   "
10.14000016450882, -8.184007, 0.26561585, NaN, NaN, NaN, -0.1910517, "- N/A -   "
10.169999897480011, -8.25278, 0.26605907, NaN, NaN, NaN, -0.19471404, "- N/A -   "
10.199999630451202, -8.287167, 0.26605907, NaN, NaN, NaN, -0.2081426, "- N/A -   "
10.23000031709671, -7.736981, 0.26630282, NaN, NaN, NaN, -0.21790881, "- N/A -   "
10.260000050067902, -8.25278, 0.26792052, NaN, NaN, NaN, -0.20570104, "- N/A -   "
10.289999783039093, -8.25278, 0.26871833, NaN, NaN, NaN, -0.20570104, "- N/A -   "
10.319999516010284, -8.287167, 0.26922804, NaN, NaN, NaN, -0.20936337, "- N/A -   "
10.350000202655792, -8.321553, 0.26984853, NaN, NaN, NaN, -0.21424648, "- N/A -   "
10.379999935626984, -8.218393, 0.27128896, NaN, NaN, NaN, -0.20692182, "- N/A -   "
10.409999668598175, -8.25278, 0.2725521, NaN, NaN, NaN, -0.19837637, "- N/A -   "
10.440000355243683, -8.287167, 0.27261856, NaN, NaN, NaN, -0.21058415, "- N/A -   "
10.470000088214874, -8.287167, 0.27261856, NaN, NaN, NaN, -0.22279193, "- N/A -   "
10.499999821186066, -8.355939, 0.27399254, NaN, NaN, NaN, -0.2130257, "- N/A -   "
10.529999554157257, -8.287167, 0.27501193, NaN, NaN, NaN, -0.2130257, "- N/A -   "
10.560000240802765, -8.321553, 0.2755216, NaN, NaN, NaN, -0.21668804, "- N/A -   "
10.589999973773956, -8.321553, 0.27620858, NaN, NaN, NaN, -0.21668804, "- N/A -   "
10.619999706745148, -8.218393, 0.27795926, NaN, NaN, NaN, -0.19837637, "- N/A -   "
10.650000393390656, -8.25278, 0.27897865, NaN, NaN, NaN, -0.19593482, "- N/A -   "
10.680000126361847, -8.321553, 0.2790008, NaN, NaN, NaN, -0.2081426, "- N/A -   "
10.709999859333038, -8.321553, 0.2790008, NaN, NaN, NaN, -0.22035037, "- N/A -   "
10.73999959230423, -8.25278, 0.28006452, NaN, NaN, NaN, -0.21546726, "- N/A -   "
10.770000278949738, -8.321553, 0.28134984, NaN, NaN, NaN, -0.21058415, "- N/A -   "
10.800000011920929, -8.321553, 0.2820146, NaN, NaN, NaN, -0.21424648, "- N/A -   "
10.82999974489212, -8.355939, 0.28279024, NaN, NaN, NaN, -0.21424648, "- N/A -   "
10.860000431537628, -8.25278, 0.28436366, NaN, NaN, NaN, -0.2020387, "- N/A -   "
10.89000016450882, -8.287167, 0.28509495, NaN, NaN, NaN, -0.2020387, "- N/A -   "
10.919999897480011, -8.321553, 0.28509495, NaN, NaN, NaN, -0.21424648, "- N/A -   "
10.949999630451202, -7.840141, 0.28562677, NaN, NaN, NaN, -0.21912959, "- N/A -   "
10.98000031709671, -8.355939, 0.28713372, NaN, NaN, NaN, -0.2081426, "- N/A -   "
11.010000050067902, -8.355939, 0.2873553, NaN, NaN, NaN, -0.21912959, "- N/A -   "
11.039999783039093, -7.805754, 0.28802013, NaN, NaN, NaN, -0.22279193, "- N/A -   "
11.069999516010284, -8.287167, 0.29005888, NaN, NaN, NaN, -0.19593482, "- N/A -   "
11.100000202655792, -8.287167, 0.29141068, NaN, NaN, NaN, -0.1861686, "- N/A -   "
11.129999935626984, -8.355939, 0.291455, NaN, NaN, NaN, -0.19837637, "- N/A -   "
11.159999668598175, -8.321553, 0.291455, NaN, NaN, NaN, -0.21058415, "- N/A -   "
11.190000355243683, -7.874528, 0.292142, NaN, NaN, NaN, -0.21424648, "- N/A -   "
11.220000088214874, -8.25278, 0.29356027, NaN, NaN, NaN, -0.20570104, "- N/A -   "
11.249999821186066, -8.3903265, 0.29402563, NaN, NaN, NaN, -0.21180493, "- N/A -   "
11.279999554157257, -8.906125, 0.2942472, NaN, NaN, NaN, -0.22035037, "- N/A -   "
11.310000240802765, -8.631032, 0.29457965, NaN, NaN, NaN, -0.22767504, "- N/A -   "
11.339999973773956, -8.940512, 0.29520014, NaN, NaN, NaN, -0.22889581, "- N/A -   "
11.369999706745148, -8.459099, 0.29670703, NaN, NaN, NaN, -0.21912959, "- N/A -   "
11.400000393390656, -8.596645, 0.29799235, NaN, NaN, NaN, -0.21180493, "- N/A -   "
11.430000126361847, -7.9433007, 0.29830262, NaN, NaN, NaN, -0.22279193, "- N/A -   "
11.459999859333038, -8.493486, 0.30000895, NaN, NaN, NaN, -0.20570104, "- N/A -   "
11.48999959230423, -8.699805, 0.30096188, NaN, NaN, NaN, -0.20570104, "- N/A -   "
11.520000278949738, -8.424713, 0.3019591, NaN, NaN, NaN, -0.20448026, "- N/A -   "
11.550000011920929, -8.527872, 0.30359897, NaN, NaN, NaN, -0.18983093, "- N/A -   "
11.57999974489212, -8.3903265, 0.30404216, NaN, NaN, NaN, -0.19593482, "- N/A -   "
11.610000431537628, -8.631032, 0.30404216, NaN, NaN, NaN, -0.20936337, "- N/A -   "
11.64000016450882, -8.0120735, 0.3043081, NaN, NaN, NaN, -0.21912959, "- N/A -   "
11.669999897480011, -8.493486, 0.30597016, NaN, NaN, NaN, -0.20448026, "- N/A -   "
11.699999630451202, -8.493486, 0.30659065, NaN, NaN, NaN, -0.20692182, "- N/A -   "
11.73000031709671, -8.459099, 0.30667928, NaN, NaN, NaN, -0.21668804, "- N/A -   "
11.760000050067902, -8.287167, 0.3077208, NaN, NaN, NaN, -0.21180493, "- N/A -   "
11.789999783039093, -8.424713, 0.30960447, NaN, NaN, NaN, -0.18983093, "- N/A -   "
11.819999516010284, -8.493486, 0.31029144, NaN, NaN, NaN, -0.19227248, "- N/A -   "
11.850000202655792, -8.493486, 0.31029144, NaN, NaN, NaN, -0.20448026, "- N/A -   "
11.879999935626984, -8.184007, 0.31029144, NaN, NaN, NaN, -0.21790881, "- N/A -   "
11.909999668598175, -8.56226, 0.31186485, NaN, NaN, NaN, -0.20448026, "- N/A -   "
11.940000355243683, -8.493486, 0.31286207, NaN, NaN, NaN, -0.20448026, "- N/A -   "
11.970000088214874, -8.56226, 0.3134604, NaN, NaN, NaN, -0.20692182, "- N/A -   "
11.999999821186066, -8.527872, 0.31405872, NaN, NaN, NaN, -0.20936337, "- N/A -   "
12.029999554157257, -8.459099, 0.31534404, NaN, NaN, NaN, -0.20448026, "- N/A -   "
12.060000240802765, -8.527872, 0.3166958, NaN, NaN, NaN, -0.1971556, "- N/A -   "
12.089999973773956, -8.527872, 0.3168066, NaN, NaN, NaN, -0.2081426, "- N/A -   "
12.119999706745148, -8.527872, 0.3168066, NaN, NaN, NaN, -0.22157115, "- N/A -   "
12.150000393390656, -8.527872, 0.3182249, NaN, NaN, NaN, -0.20692182, "- N/A -   "
12.180000126361847, -8.527872, 0.3191335, NaN, NaN, NaN, -0.2081426, "- N/A -   "
12.209999859333038, -8.56226, 0.31955454, NaN, NaN, NaN, -0.21180493, "- N/A -   "
12.23999959230423, -8.596645, 0.31999773, NaN, NaN, NaN, -0.21424648, "- N/A -   "
12.270000278949738, -8.527872, 0.32092848, NaN, NaN, NaN, -0.21424648, "- N/A -   "
12.300000011920929, -8.493486, 0.32278997, NaN, NaN, NaN, -0.19349326, "- N/A -   "
12.32999974489212, -8.56226, 0.32332182, NaN, NaN, NaN, -0.19837637, "- N/A -   "
12.360000431537628, -8.56226, 0.32332182, NaN, NaN, NaN, -0.21180493, "- N/A -   "
12.39000016450882, -8.355939, 0.32332182, NaN, NaN, NaN, -0.2240127, "- N/A -   "
12.419999897480011, -8.527872, 0.3248509, NaN, NaN, NaN, -0.20936337, "- N/A -   "
12.449999630451202, -8.56226, 0.32584813, NaN, NaN, NaN, -0.20936337, "- N/A -   "
12.48000031709671, -8.56226, 0.32644644, NaN, NaN, NaN, -0.21058415, "- N/A -   "
12.510000050067902, -8.631032, 0.32717773, NaN, NaN, NaN, -0.21180493, "- N/A -   "
12.539999783039093, -8.527872, 0.32866248, NaN, NaN, NaN, -0.20325948, "- N/A -   "
12.569999516010284, -8.56226, 0.32934946, NaN, NaN, NaN, -0.20448026, "- N/A -   "
12.600000202655792, -8.527872, 0.32934946, NaN, NaN, NaN, -0.21790881, "- N/A -   "
12.629999935626984, -8.184007, 0.33074558, NaN, NaN, NaN, -0.20936337, "- N/A -   "
12.659999668598175, -8.631032, 0.33165416, NaN, NaN, NaN, -0.20692182, "- N/A -   "
12.690000355243683, -8.631032, 0.3316985, NaN, NaN, NaN, -0.21912959, "- N/A -   "
12.720000088214874, -8.115233, 0.33211952, NaN, NaN, NaN, -0.2240127, "- N/A -   "
12.749999821186066, -8.56226, 0.33413613, NaN, NaN, NaN, -0.19959715, "- N/A -   "
12.779999554157257, -8.596645, 0.3356209, NaN, NaN, NaN, -0.18738937, "- N/A -   "
12.810000240802765, -8.631032, 0.3357539, NaN, NaN, NaN, -0.1971556, "- N/A -   "
12.839999973773956, -8.631032, 0.3357539, NaN, NaN, NaN, -0.21058415, "- N/A -   "
12.869999706745148, -8.115233, 0.33637437, NaN, NaN, NaN, -0.21424648, "- N/A -   "
12.900000393390656, -8.631032, 0.33783695, NaN, NaN, NaN, -0.20570104, "- N/A -   "
12.930000126361847, -8.665419, 0.33839098, NaN, NaN, NaN, -0.21058415, "- N/A -   "
12.959999859333038, -8.631032, 0.3386126, NaN, NaN, NaN, -0.21546726, "- N/A -   "
12.98999959230423, -8.699805, 0.33890066, NaN, NaN, NaN, -0.21912959, "- N/A -   "
13.020000278949738, -8.734192, 0.33945465, NaN, NaN, NaN, -0.22035037, "- N/A -   "
13.050000011920929, -8.665419, 0.34085077, NaN, NaN, NaN, -0.2130257, "- N/A -   "
13.07999974489212, -8.631032, 0.34222475, NaN, NaN, NaN, -0.20448026, "- N/A -   "
13.110000431537628, -8.631032, 0.34237987, NaN, NaN, NaN, -0.21424648, "- N/A -   "
13.14000016450882, -8.665419, 0.34348786, NaN, NaN, NaN, -0.2081426, "- N/A -   "
13.169999897480011, -8.631032, 0.34479538, NaN, NaN, NaN, -0.20325948, "- N/A -   "
13.199999630451202, -8.665419, 0.3456596, NaN, NaN, NaN, -0.20325948, "- N/A -   "
13.23000031709671, -8.596645, 0.3470557, NaN, NaN, NaN, -0.1971556, "- N/A -   "
13.260000050067902, -8.631032, 0.34831887, NaN, NaN, NaN, -0.18983093, "- N/A -   "
13.289999783039093, -8.665419, 0.34838533, NaN, NaN, NaN, -0.2020387, "- N/A -   "
13.319999516010284, -8.665419, 0.34838533, NaN, NaN, NaN, -0.21424648, "- N/A -   "
13.350000202655792, -8.734192, 0.3495377, NaN, NaN, NaN, -0.20692182, "- N/A -   "
13.379999935626984, -8.665419, 0.35066786, NaN, NaN, NaN, -0.20448026, "- N/A -   "
13.409999668598175, -8.665419, 0.35093382, NaN, NaN, NaN, -0.2130257, "- N/A -   "
13.440000355243683, -8.699805, 0.35106677, NaN, NaN, NaN, -0.22279193, "- N/A -   "
13.470000088214874, -8.699805, 0.35135487, NaN, NaN, NaN, -0.23011659, "- N/A -   "
13.499999821186066, -8.734192, 0.3517759, NaN, NaN, NaN, -0.23377892, "- N/A -   "
13.529999554157257, -8.699805, 0.35255152, NaN, NaN, NaN, -0.2349997, "- N/A -   "
13.560000240802765, -8.665419, 0.35419142, NaN, NaN, NaN, -0.22035037, "- N/A -   "
13.589999973773956, -8.665419, 0.3548784, NaN, NaN, NaN, -0.22523348, "- N/A -   "
13.619999706745148, -8.699805, 0.35631883, NaN, NaN, NaN, -0.2130257, "- N/A -   "
13.650000393390656, -8.665419, 0.35747117, NaN, NaN, NaN, -0.21058415, "- N/A -   "
13.680000126361847, -8.665419, 0.35813597, NaN, NaN, NaN, -0.21058415, "- N/A -   "
13.709999859333038, -8.631032, 0.35922185, NaN, NaN, NaN, -0.21180493, "- N/A -   "
13.73999959230423, -8.631032, 0.36083958, NaN, NaN, NaN, -0.19837637, "- N/A -   "
13.770000278949738, -8.665419, 0.36114982, NaN, NaN, NaN, -0.20692182, "- N/A -   "
13.800000011920929, -8.734192, 0.36114982, NaN, NaN, NaN, -0.21912959, "- N/A -   "
13.82999974489212, -8.25278, 0.36212486, NaN, NaN, NaN, -0.21790881, "- N/A -   "
13.860000431537628, -8.699805, 0.36341017, NaN, NaN, NaN, -0.21180493, "- N/A -   "
13.89000016450882, -8.699805, 0.36398634, NaN, NaN, NaN, -0.2130257, "- N/A -   "
13.919999897480011, -8.699805, 0.36460683, NaN, NaN, NaN, -0.21546726, "- N/A -   "
13.949999630451202, -8.631032, 0.36602512, NaN, NaN, NaN, -0.20692182, "- N/A -   "
13.98000031709671, -8.631032, 0.36753204, NaN, NaN, NaN, -0.19593482, "- N/A -   "
14.010000050067902, -8.699805, 0.367665, NaN, NaN, NaN, -0.20692182, "- N/A -   "
14.039999783039093, -8.734192, 0.367665, NaN, NaN, NaN, -0.21912959, "- N/A -   "
14.069999516010284, -8.218393, 0.36835197, NaN, NaN, NaN, -0.22157115, "- N/A -   "
14.100000202655792, -8.699805, 0.3697924, NaN, NaN, NaN, -0.21180493, "- N/A -   "
14.110000431537628, -8.699805, 0.37005833, NaN, NaN, NaN, -0.21180493, "- N/A -   "