File: BME243_Tues_FA21_LT_Letterman_10.csv
"Time", "Load (N)", "Position (mm)", "Strain(Axial) (in)", "Strain(Transverse) (in)", "Auxiliary ()", "Control Out (V)", "Stress (MPa)"
0.0, 0.13754633, 0.0053850035, NaN, NaN, NaN, -0.22767504, "- N/A -   "
0.029999971389770508, 0.24070609, 0.007312968, NaN, NaN, NaN, -0.20325948, "- N/A -   "
0.06000000238418579, 0.27509266, 0.007977784, NaN, NaN, NaN, -0.20692182, "- N/A -   "
0.0899999737739563, 0.30947924, 0.007999944, NaN, NaN, NaN, -0.22035037, "- N/A -   "
0.12000000476837158, 0.7908914, 7.091363E-4, NaN, NaN, NaN, -0.22157115, "- N/A -   "
0.1499999761581421, 0.412639, 0.0021052482, NaN, NaN, NaN, -0.21058415, "- N/A -   "
0.18000000715255737, 0.4470256, 0.0028587056, NaN, NaN, NaN, -0.21058415, "- N/A -   "
0.20999997854232788, 0.5845719, 0.004188336, NaN, NaN, NaN, -0.2020387, "- N/A -   "
0.24000000953674316, 0.65334505, 0.0058725346, NaN, NaN, NaN, -0.18494782, "- N/A -   "
0.27000004053115845, 0.7221182, 0.006071979, NaN, NaN, NaN, -0.19227248, "- N/A -   "
0.30000001192092896, 0.6877317, 0.006071979, NaN, NaN, NaN, -0.20448026, "- N/A -   "
0.32999998331069946, 0.7221182, 0.006071979, NaN, NaN, NaN, -0.21790881, "- N/A -   "
0.35999995470046997, 1.237917, 0.006360066, NaN, NaN, NaN, -0.22645426, "- N/A -   "
0.39000004529953003, 0.75650483, 0.008088585, NaN, NaN, NaN, -0.21058415, "- N/A -   "
0.42000001668930054, 0.825278, 0.008975006, NaN, NaN, NaN, -0.21180493, "- N/A -   "
0.44999998807907104, 0.8940512, 0.009794945, NaN, NaN, NaN, -0.21180493, "- N/A -   "
0.47999995946884155, 1.0315975, 0.011390501, NaN, NaN, NaN, -0.19837637, "- N/A -   "
0.5100000500679016, 1.0315975, 0.012099638, NaN, NaN, NaN, -0.20081793, "- N/A -   "
0.5400000214576721, 1.065984, 0.012099638, NaN, NaN, NaN, -0.2130257, "- N/A -   "
0.5699999928474426, 1.5473962, 0.01265365, NaN, NaN, NaN, -0.21668804, "- N/A -   "
0.5999999642372131, 1.1347572, 0.014071924, NaN, NaN, NaN, -0.20448026, "- N/A -   "
0.6299999356269836, 1.1347572, 0.014271367, NaN, NaN, NaN, -0.2130257, "- N/A -   "
0.6600000262260437, 1.1691438, 0.014293528, NaN, NaN, NaN, -0.22645426, "- N/A -   "
0.6899999976158142, 1.1691438, 0.014448651, NaN, NaN, NaN, -0.2349997, "- N/A -   "
0.7199999690055847, 1.2035304, 0.01613285, NaN, NaN, NaN, -0.21546726, "- N/A -   "
0.7499999403953552, 1.3754634, 0.018127296, NaN, NaN, NaN, -0.18861015, "- N/A -   "
0.7800000309944153, 1.3754634, 0.018592667, NaN, NaN, NaN, -0.19349326, "- N/A -   "
0.8100000023841858, 1.4098499, 0.018592667, NaN, NaN, NaN, -0.20692182, "- N/A -   "
0.8399999737739563, 1.8568754, 0.018614827, NaN, NaN, NaN, -0.22035037, "- N/A -   "
0.8699999451637268, 1.4786232, 0.020232543, NaN, NaN, NaN, -0.2081426, "- N/A -   "
0.9000000357627869, 1.5130097, 0.021096803, NaN, NaN, NaN, -0.21058415, "- N/A -   "
0.9300000071525574, 1.5130097, 0.021384891, NaN, NaN, NaN, -0.21912959, "- N/A -   "
0.9599999785423279, 1.5473962, 0.021739459, NaN, NaN, NaN, -0.22523348, "- N/A -   "
0.9899999499320984, 1.5817828, 0.022448594, NaN, NaN, NaN, -0.22767504, "- N/A -   "
1.0200000405311584, 1.7193291, 0.024154954, NaN, NaN, NaN, -0.21058415, "- N/A -   "
1.050000011920929, 1.7537158, 0.025107857, NaN, NaN, NaN, -0.2081426, "- N/A -   "
1.0799999833106995, 1.8912619, 0.025174337, NaN, NaN, NaN, -0.22035037, "- N/A -   "
1.10999995470047, 1.7881024, 0.026725573, NaN, NaN, NaN, -0.2081426, "- N/A -   "
1.14000004529953, 1.8912619, 0.027700635, NaN, NaN, NaN, -0.2081426, "- N/A -   "
1.1700000166893005, 1.9256487, 0.028587056, NaN, NaN, NaN, -0.2081426, "- N/A -   "
1.199999988079071, 2.0288084, 0.030182613, NaN, NaN, NaN, -0.19837637, "- N/A -   "
1.2299999594688416, 2.063195, 0.031179834, NaN, NaN, NaN, -0.1971556, "- N/A -   "
1.2600000500679016, 2.063195, 0.031201998, NaN, NaN, NaN, -0.21058415, "- N/A -   "
1.2899999022483826, 2.6133802, 0.031778168, NaN, NaN, NaN, -0.21546726, "- N/A -   "
1.3200001120567322, 2.1663547, 0.033285085, NaN, NaN, NaN, -0.20325948, "- N/A -   "
1.3500000834465027, 2.2007413, 0.033728294, NaN, NaN, NaN, -0.20570104, "- N/A -   "
1.3800000548362732, 2.2007413, 0.033839095, NaN, NaN, NaN, -0.21790881, "- N/A -   "
1.4100000262260437, 2.2007413, 0.03408286, NaN, NaN, NaN, -0.2240127, "- N/A -   "
1.4399999976158142, 2.2007413, 0.03445959, NaN, NaN, NaN, -0.22767504, "- N/A -   "
1.4699999690055847, 2.235128, 0.035190888, NaN, NaN, NaN, -0.23133737, "- N/A -   "
1.4999999403953552, 2.3382876, 0.036786444, NaN, NaN, NaN, -0.21912959, "- N/A -   "
1.5299999117851257, 2.3726742, 0.03747342, NaN, NaN, NaN, -0.2240127, "- N/A -   "
1.5599998831748962, 2.3726742, 0.03878089, NaN, NaN, NaN, -0.21180493, "- N/A -   "
1.5900000929832458, 2.475834, 0.04004404, NaN, NaN, NaN, -0.2081426, "- N/A -   "
1.6200000643730164, 2.5102205, 0.040819656, NaN, NaN, NaN, -0.2081426, "- N/A -   "
1.6500000357627869, 2.6477668, 0.041949846, NaN, NaN, NaN, -0.20570104, "- N/A -   "
1.6800000071525574, 2.6821535, 0.04361188, NaN, NaN, NaN, -0.18983093, "- N/A -   "
1.7099999785423279, 2.7509267, 0.04396645, NaN, NaN, NaN, -0.19837637, "- N/A -   "
1.7399999499320984, 2.7509267, 0.04396645, NaN, NaN, NaN, -0.21180493, "- N/A -   "
1.769999921321869, 3.129179, 0.043988608, NaN, NaN, NaN, -0.2240127, "- N/A -   "
1.7999998927116394, 2.7509267, 0.04558417, NaN, NaN, NaN, -0.21180493, "- N/A -   "
1.830000102519989, 2.8196998, 0.046470586, NaN, NaN, NaN, -0.21180493, "- N/A -   "
1.8600000739097595, 2.8540864, 0.047113243, NaN, NaN, NaN, -0.2130257, "- N/A -   "
1.89000004529953, 2.9916327, 0.04833207, NaN, NaN, NaN, -0.21058415, "- N/A -   "
1.9200000166893005, 3.0260193, 0.05008275, NaN, NaN, NaN, -0.18983093, "- N/A -   "
1.949999988079071, 3.060406, 0.050415155, NaN, NaN, NaN, -0.1971556, "- N/A -   "
1.9799999594688416, 3.060406, 0.050415155, NaN, NaN, NaN, -0.21058415, "- N/A -   "
2.009999930858612, 3.060406, 0.050415155, NaN, NaN, NaN, -0.22279193, "- N/A -   "
2.0399999022483826, 3.060406, 0.051633984, NaN, NaN, NaN, -0.21424648, "- N/A -   "
2.070000112056732, 3.1635656, 0.052852813, NaN, NaN, NaN, -0.21058415, "- N/A -   "
2.1000000834465027, 3.232339, 0.05360627, NaN, NaN, NaN, -0.21180493, "- N/A -   "
2.130000054836273, 3.301112, 0.05475862, NaN, NaN, NaN, -0.20936337, "- N/A -   "
2.1600000262260437, 3.3354986, 0.056309853, NaN, NaN, NaN, -0.19959715, "- N/A -   "
2.189999997615814, 3.4042716, 0.056464974, NaN, NaN, NaN, -0.2081426, "- N/A -   "
2.2199999690055847, 3.5762048, 0.056464974, NaN, NaN, NaN, -0.22157115, "- N/A -   "
2.2499999403953552, 3.3698852, 0.05799405, NaN, NaN, NaN, -0.2081426, "- N/A -   "
2.2799999117851257, 3.5074315, 0.058636706, NaN, NaN, NaN, -0.21180493, "- N/A -   "
2.3099998831748962, 3.5074315, 0.058658864, NaN, NaN, NaN, -0.22523348, "- N/A -   "
2.340000092983246, 3.7825239, 0.059811212, NaN, NaN, NaN, -0.21424648, "- N/A -   "
2.3700000643730164, 3.7137508, 0.061739177, NaN, NaN, NaN, -0.1910517, "- N/A -   "
2.400000035762787, 3.7481375, 0.06280288, NaN, NaN, NaN, -0.18738937, "- N/A -   "
2.4300000071525574, 3.7481375, 0.06280288, NaN, NaN, NaN, -0.20081793, "- N/A -   "
2.459999978542328, 3.7481375, 0.06280288, NaN, NaN, NaN, -0.21424648, "- N/A -   "
2.4899999499320984, 3.7825239, 0.063955225, NaN, NaN, NaN, -0.20448026, "- N/A -   "
2.519999921321869, 3.7825239, 0.065041095, NaN, NaN, NaN, -0.20081793, "- N/A -   "
2.5499998927116394, 3.8512974, 0.06541782, NaN, NaN, NaN, -0.20570104, "- N/A -   "
2.580000102519989, 3.8512974, 0.06555079, NaN, NaN, NaN, -0.21546726, "- N/A -   "
2.6100000739097595, 3.8856838, 0.06579455, NaN, NaN, NaN, -0.22645426, "- N/A -   "
2.64000004529953, 3.9200704, 0.066304244, NaN, NaN, NaN, -0.22889581, "- N/A -   "
2.6700000166893005, 3.9888434, 0.067478746, NaN, NaN, NaN, -0.22523348, "- N/A -   "
2.699999988079071, 4.02323, 0.069140784, NaN, NaN, NaN, -0.21058415, "- N/A -   "
2.7299999594688416, 4.0920033, 0.069517516, NaN, NaN, NaN, -0.21668804, "- N/A -   "
2.759999930858612, 4.4014826, 0.07035961, NaN, NaN, NaN, -0.21546726, "- N/A -   "
2.7899999022483826, 4.1951632, 0.07173357, NaN, NaN, NaN, -0.20448026, "- N/A -   "
2.820000112056732, 4.2295494, 0.072575666, NaN, NaN, NaN, -0.20570104, "- N/A -   "
2.8500000834465027, 4.367096, 0.07379449, NaN, NaN, NaN, -0.2020387, "- N/A -   "
2.880000054836273, 4.4014826, 0.07523493, NaN, NaN, NaN, -0.18983093, "- N/A -   "
2.9100000262260437, 4.4014826, 0.07539005, NaN, NaN, NaN, -0.2020387, "- N/A -   "
2.939999997615814, 4.4014826, 0.07539005, NaN, NaN, NaN, -0.21424648, "- N/A -   "
2.9699999690055847, 4.5046425, 0.07652024, NaN, NaN, NaN, -0.20936337, "- N/A -   "
2.9999999403953552, 4.5046425, 0.0777169, NaN, NaN, NaN, -0.20570104, "- N/A -   "
3.0299999117851257, 4.5390286, 0.07793851, NaN, NaN, NaN, -0.21424648, "- N/A -   "
3.0599998831748962, 5.0892143, 0.07871413, NaN, NaN, NaN, -0.21424648, "- N/A -   "
3.090000092983246, 4.7453485, 0.080664255, NaN, NaN, NaN, -0.1910517, "- N/A -   "
3.1200000643730164, 4.7453485, 0.08157283, NaN, NaN, NaN, -0.1910517, "- N/A -   "
3.150000035762787, 4.779735, 0.08157283, NaN, NaN, NaN, -0.20448026, "- N/A -   "
3.1800000071525574, 4.848508, 0.08157283, NaN, NaN, NaN, -0.21668804, "- N/A -   "
3.209999978542328, 4.7453485, 0.083124064, NaN, NaN, NaN, -0.20325948, "- N/A -   "
3.2399999499320984, 4.779735, 0.083988324, NaN, NaN, NaN, -0.20325948, "- N/A -   "
3.269999921321869, 4.8141217, 0.084453695, NaN, NaN, NaN, -0.2081426, "- N/A -   "
3.3000001311302185, 4.8828945, 0.08487475, NaN, NaN, NaN, -0.21058415, "- N/A -   "
3.32999986410141, 4.917281, 0.085473076, NaN, NaN, NaN, -0.2130257, "- N/A -   "
3.3600000739097595, 5.020441, 0.08682487, NaN, NaN, NaN, -0.20570104, "- N/A -   "
3.389999806880951, 5.0892143, 0.088065855, NaN, NaN, NaN, -0.20081793, "- N/A -   "
3.4200000166893005, 5.0892143, 0.088132344, NaN, NaN, NaN, -0.21180493, "- N/A -   "
3.45000022649765, 5.5706263, 0.08875284, NaN, NaN, NaN, -0.21668804, "- N/A -   "
3.4799999594688416, 5.157987, 0.09014895, NaN, NaN, NaN, -0.2081426, "- N/A -   "
3.510000169277191, 5.192374, 0.090569995, NaN, NaN, NaN, -0.2130257, "- N/A -   "
3.5399999022483826, 5.192374, 0.09076945, NaN, NaN, NaN, -0.22279193, "- N/A -   "
3.570000112056732, 5.192374, 0.09105753, NaN, NaN, NaN, -0.22645426, "- N/A -   "
3.5999998450279236, 5.261147, 0.09158938, NaN, NaN, NaN, -0.22889581, "- N/A -   "
3.630000054836273, 5.3986936, 0.09291901, NaN, NaN, NaN, -0.22157115, "- N/A -   "
3.6599997878074646, 5.3986936, 0.094558895, NaN, NaN, NaN, -0.20570104, "- N/A -   "
3.689999997615814, 5.4674664, 0.09475833, NaN, NaN, NaN, -0.21424648, "- N/A -   "
3.720000207424164, 5.845719, 0.0947805, NaN, NaN, NaN, -0.22645426, "- N/A -   "
3.7499999403953552, 5.4674664, 0.09639821, NaN, NaN, NaN, -0.21180493, "- N/A -   "
3.780000150203705, 5.5362396, 0.09730679, NaN, NaN, NaN, -0.2130257, "- N/A -   "
3.8099998831748962, 5.5706263, 0.097772166, NaN, NaN, NaN, -0.21668804, "- N/A -   "
3.840000092983246, 5.6393995, 0.0983705, NaN, NaN, NaN, -0.21912959, "- N/A -   "
3.8699998259544373, 5.7769456, 0.099833086, NaN, NaN, NaN, -0.21058415, "- N/A -   "
3.900000035762787, 5.7769456, 0.10074168, NaN, NaN, NaN, -0.2130257, "- N/A -   "
3.9299997687339783, 6.3271313, 0.10151729, NaN, NaN, NaN, -0.21790881, "- N/A -   "
3.959999978542328, 5.8801055, 0.10289124, NaN, NaN, NaN, -0.2081426, "- N/A -   "
3.9900001883506775, 5.9144926, 0.10300205, NaN, NaN, NaN, -0.21790881, "- N/A -   "
4.019999921321869, 6.430291, 0.10346741, NaN, NaN, NaN, -0.2240127, "- N/A -   "
4.0500001311302185, 6.086425, 0.10546186, NaN, NaN, NaN, -0.19593482, "- N/A -   "
4.07999986410141, 6.120812, 0.10692446, NaN, NaN, NaN, -0.18861015, "- N/A -   "
4.1100000739097595, 6.120812, 0.1070131, NaN, NaN, NaN, -0.19959715, "- N/A -   "
4.139999806880951, 6.155198, 0.1070131, NaN, NaN, NaN, -0.2130257, "- N/A -   "
4.1700000166893005, 6.602224, 0.10809896, NaN, NaN, NaN, -0.20570104, "- N/A -   "
4.20000022649765, 6.223972, 0.109251305, NaN, NaN, NaN, -0.20325948, "- N/A -   "
4.2299999594688416, 6.258358, 0.10951724, NaN, NaN, NaN, -0.20936337, "- N/A -   "
4.260000169277191, 6.258358, 0.109561555, NaN, NaN, NaN, -0.22157115, "- N/A -   "
4.289999902248383, 6.258358, 0.11075822, NaN, NaN, NaN, -0.21058415, "- N/A -   "
4.320000112056732, 6.430291, 0.11266403, NaN, NaN, NaN, -0.18738937, "- N/A -   "
4.349999845027924, 6.430291, 0.113483965, NaN, NaN, NaN, -0.18861015, "- N/A -   "
4.380000054836273, 6.464678, 0.113483965, NaN, NaN, NaN, -0.2020387, "- N/A -   "
4.409999787807465, 6.499064, 0.113483965, NaN, NaN, NaN, -0.21424648, "- N/A -   "
4.439999997615814, 6.464678, 0.11476928, NaN, NaN, NaN, -0.20692182, "- N/A -   "
4.470000207424164, 6.567837, 0.11585514, NaN, NaN, NaN, -0.20570104, "- N/A -   "
4.499999940395355, 6.602224, 0.11645347, NaN, NaN, NaN, -0.20570104, "- N/A -   "
4.530000150203705, 6.602224, 0.117029645, NaN, NaN, NaN, -0.2081426, "- N/A -   "
4.559999883174896, 6.7053833, 0.118204154, NaN, NaN, NaN, -0.20325948, "- N/A -   "
4.590000092983246, 6.774157, 0.119622424, NaN, NaN, NaN, -0.19471404, "- N/A -   "
4.619999825954437, 6.774157, 0.11975539, NaN, NaN, NaN, -0.20448026, "- N/A -   "
4.650000035762787, 6.808543, 0.11975539, NaN, NaN, NaN, -0.21668804, "- N/A -   "
4.679999768733978, 6.8429303, 0.121262304, NaN, NaN, NaN, -0.20692182, "- N/A -   "
4.709999978542328, 6.8773165, 0.12208224, NaN, NaN, NaN, -0.21058415, "- N/A -   "
4.7400001883506775, 7.4618883, 0.12248114, NaN, NaN, NaN, -0.21668804, "- N/A -   "
4.769999921321869, 7.049249, 0.12436478, NaN, NaN, NaN, -0.19227248, "- N/A -   "
4.8000001311302185, 7.049249, 0.12569441, NaN, NaN, NaN, -0.18738937, "- N/A -   "
4.82999986410141, 7.0836363, 0.1258052, NaN, NaN, NaN, -0.1971556, "- N/A -   "
4.8600000739097595, 7.0836363, 0.1258052, NaN, NaN, NaN, -0.21058415, "- N/A -   "
4.889999806880951, 7.599435, 0.12640354, NaN, NaN, NaN, -0.21180493, "- N/A -   "
4.9200000166893005, 7.1867957, 0.12779966, NaN, NaN, NaN, -0.2020387, "- N/A -   "
4.95000022649765, 7.2211823, 0.1283315, NaN, NaN, NaN, -0.20448026, "- N/A -   "
4.9799999594688416, 7.2211823, 0.12853095, NaN, NaN, NaN, -0.2130257, "- N/A -   "
5.010000169277191, 7.2555685, 0.12875256, NaN, NaN, NaN, -0.2240127, "- N/A -   "
5.039999902248383, 7.2555685, 0.12912928, NaN, NaN, NaN, -0.23133737, "- N/A -   "
5.070000112056732, 7.2555685, 0.12974977, NaN, NaN, NaN, -0.23133737, "- N/A -   "
5.099999845027924, 7.3931155, 0.13114588, NaN, NaN, NaN, -0.2240127, "- N/A -   "
5.130000054836273, 7.3931155, 0.13249768, NaN, NaN, NaN, -0.21790881, "- N/A -   "
5.159999787807465, 8.0120735, 0.13280793, NaN, NaN, NaN, -0.22523348, "- N/A -   "
5.189999997615814, 7.4618883, 0.13446997, NaN, NaN, NaN, -0.21180493, "- N/A -   "
5.220000207424164, 7.5306616, 0.13504614, NaN, NaN, NaN, -0.21668804, "- N/A -   "
5.249999940395355, 7.599435, 0.13531207, NaN, NaN, NaN, -0.21912959, "- N/A -   "
5.280000150203705, 7.6338215, 0.13562232, NaN, NaN, NaN, -0.2240127, "- N/A -   "
5.309999883174896, 7.6338215, 0.13619849, NaN, NaN, NaN, -0.2240127, "- N/A -   "
5.340000092983246, 7.7713675, 0.13779405, NaN, NaN, NaN, -0.20936337, "- N/A -   "
5.369999825954437, 7.7025948, 0.13892423, NaN, NaN, NaN, -0.20325948, "- N/A -   "
5.400000035762787, 7.7713675, 0.1389464, NaN, NaN, NaN, -0.21668804, "- N/A -   "
5.429999768733978, 8.287167, 0.13927878, NaN, NaN, NaN, -0.22523348, "- N/A -   "
5.459999978542328, 7.805754, 0.14089651, NaN, NaN, NaN, -0.21546726, "- N/A -   "
5.4900001883506775, 7.874528, 0.14147268, NaN, NaN, NaN, -0.21912959, "- N/A -   "
5.519999921321869, 7.9433007, 0.14169429, NaN, NaN, NaN, -0.23133737, "- N/A -   "
5.5500001311302185, 7.977687, 0.14202671, NaN, NaN, NaN, -0.23988281, "- N/A -   "
5.57999986410141, 8.04646, 0.14266935, NaN, NaN, NaN, -0.24232437, "- N/A -   "
5.6100000739097595, 8.080847, 0.14413196, NaN, NaN, NaN, -0.23622048, "- N/A -   "
5.639999806880951, 8.080847, 0.1450627, NaN, NaN, NaN, -0.23255815, "- N/A -   "
5.6700000166893005, 8.631032, 0.14656961, NaN, NaN, NaN, -0.21546726, "- N/A -   "
5.70000022649765, 8.14962, 0.14756683, NaN, NaN, NaN, -0.2130257, "- N/A -   "
5.7299999594688416, 8.768579, 0.14783275, NaN, NaN, NaN, -0.22157115, "- N/A -   "
5.760000169277191, 8.424713, 0.14980504, NaN, NaN, NaN, -0.19837637, "- N/A -   "
5.789999902248383, 8.493486, 0.15126763, NaN, NaN, NaN, -0.1910517, "- N/A -   "
5.820000112056732, 8.493486, 0.15137842, NaN, NaN, NaN, -0.2020387, "- N/A -   "
5.849999845027924, 8.493486, 0.15137842, NaN, NaN, NaN, -0.21546726, "- N/A -   "
5.880000054836273, 8.493486, 0.15273023, NaN, NaN, NaN, -0.20692182, "- N/A -   "
5.909999787807465, 8.56226, 0.15363881, NaN, NaN, NaN, -0.20448026, "- N/A -   "
5.939999997615814, 8.56226, 0.15368313, NaN, NaN, NaN, -0.21668804, "- N/A -   "
5.970000207424164, 9.078057, 0.15417065, NaN, NaN, NaN, -0.22035037, "- N/A -   "
5.999999940395355, 8.699805, 0.15605429, NaN, NaN, NaN, -0.1971556, "- N/A -   "
6.030000150203705, 8.802965, 0.15742826, NaN, NaN, NaN, -0.18738937, "- N/A -   "
6.059999883174896, 8.802965, 0.15762769, NaN, NaN, NaN, -0.19593482, "- N/A -   "
6.090000092983246, 8.837352, 0.15762769, NaN, NaN, NaN, -0.20936337, "- N/A -   "
6.119999825954437, 9.318764, 0.15813738, NaN, NaN, NaN, -0.21546726, "- N/A -   "
6.150000035762787, 8.906125, 0.15962215, NaN, NaN, NaN, -0.20448026, "- N/A -   "
6.179999768733978, 8.906125, 0.16035344, NaN, NaN, NaN, -0.20570104, "- N/A -   "
6.209999978542328, 8.871738, 0.16064152, NaN, NaN, NaN, -0.21058415, "- N/A -   "
6.2400001883506775, 8.871738, 0.1608853, NaN, NaN, NaN, -0.21668804, "- N/A -   "
6.269999921321869, 8.940512, 0.1612177, NaN, NaN, NaN, -0.22279193, "- N/A -   "
6.3000001311302185, 9.009285, 0.16190468, NaN, NaN, NaN, -0.2240127, "- N/A -   "
6.32999986410141, 9.078057, 0.16347808, NaN, NaN, NaN, -0.21424648, "- N/A -   "
6.3600000739097595, 9.387537, 0.16394344, NaN, NaN, NaN, -0.22157115, "- N/A -   "
6.389999806880951, 9.181217, 0.165539, NaN, NaN, NaN, -0.2081426, "- N/A -   "
6.4200000166893005, 9.215604, 0.16629246, NaN, NaN, NaN, -0.21058415, "- N/A -   "
6.45000022649765, 9.731403, 0.16691294, NaN, NaN, NaN, -0.21424648, "- N/A -   "
6.4799999594688416, 9.35315, 0.16873012, NaN, NaN, NaN, -0.19471404, "- N/A -   "
6.510000169277191, 9.387537, 0.17001541, NaN, NaN, NaN, -0.1910517, "- N/A -   "
6.539999902248383, 9.387537, 0.17010407, NaN, NaN, NaN, -0.2020387, "- N/A -   "
6.570000112056732, 9.421924, 0.17010407, NaN, NaN, NaN, -0.21424648, "- N/A -   "
6.599999845027924, 9.45631, 0.17141153, NaN, NaN, NaN, -0.20692182, "- N/A -   "
6.630000054836273, 9.525084, 0.17238659, NaN, NaN, NaN, -0.20570104, "- N/A -   "
6.659999787807465, 9.525084, 0.17265253, NaN, NaN, NaN, -0.21180493, "- N/A -   "
6.689999997615814, 9.525084, 0.17278549, NaN, NaN, NaN, -0.21912959, "- N/A -   "
6.720000207424164, 9.490697, 0.17296277, NaN, NaN, NaN, -0.23011659, "- N/A -   "
6.749999940395355, 9.525084, 0.17327303, NaN, NaN, NaN, -0.2349997, "- N/A -   "
6.780000150203705, 9.525084, 0.17376053, NaN, NaN, NaN, -0.23866203, "- N/A -   "
6.809999883174896, 9.628243, 0.17451401, NaN, NaN, NaN, -0.23866203, "- N/A -   "
6.840000092983246, 9.628243, 0.17617604, NaN, NaN, NaN, -0.22767504, "- N/A -   "
6.869999825954437, 10.144042, 0.17673007, NaN, NaN, NaN, -0.23133737, "- N/A -   "
6.900000035762787, 9.765789, 0.17841426, NaN, NaN, NaN, -0.21546726, "- N/A -   "
6.929999768733978, 9.86895, 0.17916772, NaN, NaN, NaN, -0.21790881, "- N/A -   "
6.959999978542328, 9.86895, 0.17941147, NaN, NaN, NaN, -0.22889581, "- N/A -   "
6.9900001883506775, 9.86895, 0.18076327, NaN, NaN, NaN, -0.21180493, "- N/A -   "
7.019999921321869, 10.075269, 0.18275772, NaN, NaN, NaN, -0.18738937, "- N/A -   "
7.0500001311302185, 10.006495, 0.18311228, NaN, NaN, NaN, -0.19471404, "- N/A -   "
7.07999986410141, 10.040882, 0.18311228, NaN, NaN, NaN, -0.2081426, "- N/A -   "
7.1100000739097595, 10.040882, 0.18311228, NaN, NaN, NaN, -0.22157115, "- N/A -   "
7.139999806880951, 10.040882, 0.18455271, NaN, NaN, NaN, -0.20936337, "- N/A -   "
7.1700000166893005, 10.109656, 0.1854613, NaN, NaN, NaN, -0.20936337, "- N/A -   "
7.20000022649765, 10.144042, 0.18566075, NaN, NaN, NaN, -0.21546726, "- N/A -   "
7.2299999594688416, 10.144042, 0.18577154, NaN, NaN, NaN, -0.22645426, "- N/A -   "
7.260000169277191, 10.109656, 0.18599313, NaN, NaN, NaN, -0.23622048, "- N/A -   "
7.289999902248383, 10.144042, 0.18643637, NaN, NaN, NaN, -0.24476592, "- N/A -   "
7.319999635219574, 10.212814, 0.18723415, NaN, NaN, NaN, -0.24476592, "- N/A -   "
7.350000321865082, 10.315974, 0.18898481, NaN, NaN, NaN, -0.23133737, "- N/A -   "
7.380000054836273, 10.86616, 0.18962747, NaN, NaN, NaN, -0.2349997, "- N/A -   "
7.409999787807465, 10.384748, 0.19142248, NaN, NaN, NaN, -0.2130257, "- N/A -   "
7.439999520778656, 10.419134, 0.19210944, NaN, NaN, NaN, -0.21546726, "- N/A -   "
7.470000207424164, 10.934933, 0.19277427, NaN, NaN, NaN, -0.21790881, "- N/A -   "
7.499999940395355, 10.591067, 0.19479087, NaN, NaN, NaN, -0.18983093, "- N/A -   "
7.529999673366547, 10.591067, 0.19565514, NaN, NaN, NaN, -0.18861015, "- N/A -   "
7.560000360012054, 10.556681, 0.19565514, NaN, NaN, NaN, -0.2020387, "- N/A -   "
7.590000092983246, 10.591067, 0.19565514, NaN, NaN, NaN, -0.21424648, "- N/A -   "
7.619999825954437, 11.003707, 0.1969626, NaN, NaN, NaN, -0.20936337, "- N/A -   "
7.649999558925629, 10.625454, 0.19798198, NaN, NaN, NaN, -0.20692182, "- N/A -   "
7.6800002455711365, 10.694227, 0.19809279, NaN, NaN, NaN, -0.21790881, "- N/A -   "
7.709999978542328, 11.210026, 0.19891272, NaN, NaN, NaN, -0.21668804, "- N/A -   "
7.739999711513519, 10.831773, 0.20081852, NaN, NaN, NaN, -0.19593482, "- N/A -   "
7.770000398159027, 10.86616, 0.20197088, NaN, NaN, NaN, -0.19349326, "- N/A -   "
7.8000001311302185, 10.86616, 0.20199303, NaN, NaN, NaN, -0.20570104, "- N/A -   "
7.82999986410141, 11.416346, 0.20208168, NaN, NaN, NaN, -0.21790881, "- N/A -   "
7.859999597072601, 10.934933, 0.20372155, NaN, NaN, NaN, -0.20692182, "- N/A -   "
7.890000283718109, 10.934933, 0.2046523, NaN, NaN, NaN, -0.20692182, "- N/A -   "
7.9200000166893005, 10.934933, 0.20505118, NaN, NaN, NaN, -0.2130257, "- N/A -   "
7.949999749660492, 10.934933, 0.20536144, NaN, NaN, NaN, -0.21912959, "- N/A -   "
7.980000436306, 10.934933, 0.20591544, NaN, NaN, NaN, -0.22035037, "- N/A -   "
8.010000169277191, 11.038093, 0.20733371, NaN, NaN, NaN, -0.21424648, "- N/A -   "
8.039999902248383, 11.072479, 0.20837526, NaN, NaN, NaN, -0.21058415, "- N/A -   "
8.069999635219574, 11.622665, 0.20884064, NaN, NaN, NaN, -0.21546726, "- N/A -   "
8.100000321865082, 11.210026, 0.2103697, NaN, NaN, NaN, -0.20570104, "- N/A -   "
8.130000054836273, 11.175639, 0.21061347, NaN, NaN, NaN, -0.2130257, "- N/A -   "
8.159999787807465, 11.691438, 0.21163286, NaN, NaN, NaN, -0.20936337, "- N/A -   "
8.189999520778656, 11.313186, 0.21327274, NaN, NaN, NaN, -0.19471404, "- N/A -   "
8.220000207424164, 11.313186, 0.21433644, NaN, NaN, NaN, -0.18983093, "- N/A -   "
8.249999940395355, 11.313186, 0.21433644, NaN, NaN, NaN, -0.2020387, "- N/A -   "
8.279999673366547, 11.313186, 0.21433644, NaN, NaN, NaN, -0.21424648, "- N/A -   "
8.310000360012054, 11.5195055, 0.21562174, NaN, NaN, NaN, -0.20692182, "- N/A -   "
8.340000092983246, 11.416346, 0.21655248, NaN, NaN, NaN, -0.2081426, "- N/A -   "
8.369999825954437, 11.416346, 0.21677409, NaN, NaN, NaN, -0.21546726, "- N/A -   "
8.399999558925629, 11.381959, 0.21686274, NaN, NaN, NaN, -0.22645426, "- N/A -   "
8.430000245571136, 11.381959, 0.21706218, NaN, NaN, NaN, -0.2349997, "- N/A -   "
8.459999978542328, 11.416346, 0.21854694, NaN, NaN, NaN, -0.21912959, "- N/A -   "
8.48999971151352, 11.553891, 0.22045274, NaN, NaN, NaN, -0.19593482, "- N/A -   "
8.520000398159027, 11.553891, 0.22089595, NaN, NaN, NaN, -0.2020387, "- N/A -   "
8.550000131130219, 11.553891, 0.22089595, NaN, NaN, NaN, -0.21546726, "- N/A -   "
8.57999986410141, 11.725825, 0.22213694, NaN, NaN, NaN, -0.2081426, "- N/A -   "
8.609999597072601, 11.622665, 0.22308984, NaN, NaN, NaN, -0.20570104, "- N/A -   "
8.64000028371811, 11.622665, 0.2232893, NaN, NaN, NaN, -0.21790881, "- N/A -   "
8.6700000166893, 12.138464, 0.22359954, NaN, NaN, NaN, -0.22645426, "- N/A -   "
8.699999749660492, 11.760211, 0.2256383, NaN, NaN, NaN, -0.19837637, "- N/A -   "
8.730000436306, 11.794598, 0.22725601, NaN, NaN, NaN, -0.18494782, "- N/A -   "
8.760000169277191, 11.760211, 0.22741114, NaN, NaN, NaN, -0.19471404, "- N/A -   "
8.789999902248383, 11.760211, 0.22741114, NaN, NaN, NaN, -0.2081426, "- N/A -   "
8.819999635219574, 11.794598, 0.22741114, NaN, NaN, NaN, -0.22035037, "- N/A -   "
8.850000321865082, 11.760211, 0.22885157, NaN, NaN, NaN, -0.20570104, "- N/A -   "
8.880000054836273, 11.794598, 0.22956072, NaN, NaN, NaN, -0.20570104, "- N/A -   "
8.909999787807465, 11.794598, 0.22958286, NaN, NaN, NaN, -0.21790881, "- N/A -   "
8.939999520778656, 12.000917, 0.22964935, NaN, NaN, NaN, -0.23011659, "- N/A -   "
8.970000207424164, 11.863371, 0.23140003, NaN, NaN, NaN, -0.20936337, "- N/A -   "
8.999999940395355, 12.000917, 0.2330399, NaN, NaN, NaN, -0.19593482, "- N/A -   "
9.029999673366547, 11.966531, 0.23352744, NaN, NaN, NaN, -0.20081793, "- N/A -   "
9.060000360012054, 11.932144, 0.23352744, NaN, NaN, NaN, -0.2130257, "- N/A -   "
9.090000092983246, 12.447944, 0.23467979, NaN, NaN, NaN, -0.20692182, "- N/A -   "
9.119999825954437, 12.000917, 0.23589861, NaN, NaN, NaN, -0.19593482, "- N/A -   "
9.149999558925629, 11.966531, 0.23592077, NaN, NaN, NaN, -0.2081426, "- N/A -   "
9.180000245571136, 11.966531, 0.23592077, NaN, NaN, NaN, -0.22157115, "- N/A -   "
9.209999978542328, 12.482329, 0.23698448, NaN, NaN, NaN, -0.21546726, "- N/A -   "
9.23999971151352, 12.17285, 0.2388238, NaN, NaN, NaN, -0.19471404, "- N/A -   "
9.270000398159027, 12.138464, 0.23993182, NaN, NaN, NaN, -0.19349326, "- N/A -   "
9.300000131130219, 12.138464, 0.23995398, NaN, NaN, NaN, -0.20570104, "- N/A -   "
9.32999986410141, 12.688649, 0.24008694, NaN, NaN, NaN, -0.21790881, "- N/A -   "
9.359999597072601, 12.17285, 0.2416825, NaN, NaN, NaN, -0.2020387, "- N/A -   "
9.39000028371811, 12.17285, 0.24203707, NaN, NaN, NaN, -0.20936337, "- N/A -   "
9.4200000166893, 12.138464, 0.24203707, NaN, NaN, NaN, -0.22279193, "- N/A -   "
9.449999749660492, 12.27601, 0.24323374, NaN, NaN, NaN, -0.21668804, "- N/A -   "
9.480000436306, 12.310396, 0.2449401, NaN, NaN, NaN, -0.19837637, "- N/A -   "
9.510000169277191, 12.310396, 0.24624759, NaN, NaN, NaN, -0.18983093, "- N/A -   "
9.539999902248383, 12.310396, 0.2463362, NaN, NaN, NaN, -0.2020387, "- N/A -   "
9.569999635219574, 12.310396, 0.2463362, NaN, NaN, NaN, -0.21546726, "- N/A -   "
9.600000321865082, 12.27601, 0.24771017, NaN, NaN, NaN, -0.20570104, "- N/A -   "
9.630000054836273, 12.310396, 0.24872956, NaN, NaN, NaN, -0.20325948, "- N/A -   "
9.659999787807465, 12.344784, 0.2490841, NaN, NaN, NaN, -0.20692182, "- N/A -   "
9.689999520778656, 12.310396, 0.24921708, NaN, NaN, NaN, -0.21668804, "- N/A -   "
9.720000207424164, 12.27601, 0.24941653, NaN, NaN, NaN, -0.22279193, "- N/A -   "
9.749999940395355, 12.27601, 0.24972677, NaN, NaN, NaN, -0.22889581, "- N/A -   "
9.779999673366547, 12.310396, 0.2502808, NaN, NaN, NaN, -0.23255815, "- N/A -   "
9.810000360012054, 12.413556, 0.25169906, NaN, NaN, NaN, -0.22279193, "- N/A -   "
9.840000092983246, 12.379169, 0.2527406, NaN, NaN, NaN, -0.22157115, "- N/A -   "
9.869999825954437, 12.826196, 0.25393724, NaN, NaN, NaN, -0.21424648, "- N/A -   "
9.899999558925629, 12.413556, 0.25500098, NaN, NaN, NaN, -0.20936337, "- N/A -   "
9.930000245571136, 12.963742, 0.25524473, NaN, NaN, NaN, -0.22035037, "- N/A -   "
9.959999978542328, 12.551102, 0.25715056, NaN, NaN, NaN, -0.19837637, "- N/A -   "
9.98999971151352, 12.585489, 0.2585688, NaN, NaN, NaN, -0.19227248, "- N/A -   "
10.020000398159027, 12.551102, 0.25876826, NaN, NaN, NaN, -0.20081793, "- N/A -   "
10.050000131130219, 12.516716, 0.25876826, NaN, NaN, NaN, -0.21424648, "- N/A -   "
10.07999986410141, 12.826196, 0.25994277, NaN, NaN, NaN, -0.21058415, "- N/A -   "
10.109999597072601, 12.585489, 0.2610951, NaN, NaN, NaN, -0.20448026, "- N/A -   "
10.14000028371811, 12.619876, 0.261494, NaN, NaN, NaN, -0.21424648, "- N/A -   "
10.1700000166893, 12.585489, 0.26167127, NaN, NaN, NaN, -0.22523348, "- N/A -   "
10.199999749660492, 12.551102, 0.2619372, NaN, NaN, NaN, -0.22889581, "- N/A -   "
10.230000436306, 12.516716, 0.2623361, NaN, NaN, NaN, -0.2349997, "- N/A -   "
10.260000169277191, 12.516716, 0.26302308, NaN, NaN, NaN, -0.23622048, "- N/A -   "
10.289999902248383, 12.585489, 0.26461864, NaN, NaN, NaN, -0.22279193, "- N/A -   "
10.319999635219574, 12.619876, 0.26539424, NaN, NaN, NaN, -0.22279193, "- N/A -   "
10.350000321865082, 12.654263, 0.2666574, NaN, NaN, NaN, -0.21546726, "- N/A -   "
10.380000054836273, 12.723036, 0.26763245, NaN, NaN, NaN, -0.2130257, "- N/A -   "
10.409999787807465, 12.723036, 0.26780975, NaN, NaN, NaN, -0.22279193, "- N/A -   "
10.439999520778656, 12.723036, 0.26922804, NaN, NaN, NaN, -0.20936337, "- N/A -   "
10.470000207424164, 12.860582, 0.27115598, NaN, NaN, NaN, -0.18372704, "- N/A -   "
10.499999940395355, 12.791808, 0.27171, NaN, NaN, NaN, -0.18738937, "- N/A -   "
10.529999673366547, 12.757422, 0.27171, NaN, NaN, NaN, -0.19959715, "- N/A -   "
10.560000360012054, 12.757422, 0.27171, NaN, NaN, NaN, -0.2130257, "- N/A -   "
10.590000092983246, 13.27322, 0.27202025, NaN, NaN, NaN, -0.22279193, "- N/A -   "
10.619999825954437, 12.826196, 0.27363795, NaN, NaN, NaN, -0.20936337, "- N/A -   "
10.649999558925629, 12.860582, 0.27414766, NaN, NaN, NaN, -0.2130257, "- N/A -   "
10.680000245571136, 12.826196, 0.27428064, NaN, NaN, NaN, -0.22279193, "- N/A -   "
10.709999978542328, 12.791808, 0.27443576, NaN, NaN, NaN, -0.2349997, "- N/A -   "
10.73999971151352, 12.826196, 0.27592048, NaN, NaN, NaN, -0.21546726, "- N/A -   "
10.770000398159027, 12.929356, 0.27769333, NaN, NaN, NaN, -0.1971556, "- N/A -   "
10.800000131130219, 12.894968, 0.27793708, NaN, NaN, NaN, -0.20570104, "- N/A -   "
10.82999986410141, 13.445154, 0.2780922, NaN, NaN, NaN, -0.21668804, "- N/A -   "
10.859999597072601, 12.929356, 0.27975428, NaN, NaN, NaN, -0.20448026, "- N/A -   "
10.89000028371811, 12.998128, 0.28026396, NaN, NaN, NaN, -0.21058415, "- N/A -   "
10.9200000166893, 12.998128, 0.28026396, NaN, NaN, NaN, -0.22279193, "- N/A -   "
10.949999749660492, 12.963742, 0.2817487, NaN, NaN, NaN, -0.21058415, "- N/A -   "
10.980000436306, 13.101288, 0.28352156, NaN, NaN, NaN, -0.1910517, "- N/A -   "
11.010000169277191, 13.101288, 0.28429717, NaN, NaN, NaN, -0.19227248, "- N/A -   "
11.039999902248383, 13.066902, 0.28429717, NaN, NaN, NaN, -0.20570104, "- N/A -   "
11.069999635219574, 13.651473, 0.2843858, NaN, NaN, NaN, -0.21668804, "- N/A -   "
11.100000321865082, 13.101288, 0.28600353, NaN, NaN, NaN, -0.20325948, "- N/A -   "
11.130000054836273, 13.135674, 0.28651324, NaN, NaN, NaN, -0.20936337, "- N/A -   "
11.159999787807465, 13.135674, 0.28651324, NaN, NaN, NaN, -0.22157115, "- N/A -   "
11.189999520778656, 13.101288, 0.28779852, NaN, NaN, NaN, -0.21058415, "- N/A -   "
11.220000207424164, 13.27322, 0.28952706, NaN, NaN, NaN, -0.19349326, "- N/A -   "
11.249999940395355, 13.27322, 0.2905686, NaN, NaN, NaN, -0.19349326, "- N/A -   "
11.279999673366547, 13.238834, 0.2905686, NaN, NaN, NaN, -0.20692182, "- N/A -   "
11.310000360012054, 13.754633, 0.29076803, NaN, NaN, NaN, -0.21668804, "- N/A -   "
11.340000092983246, 13.307608, 0.29243007, NaN, NaN, NaN, -0.20448026, "- N/A -   "
11.369999825954437, 13.307608, 0.29322785, NaN, NaN, NaN, -0.20570104, "- N/A -   "
11.399999558925629, 13.307608, 0.2935381, NaN, NaN, NaN, -0.21546726, "- N/A -   "
11.430000245571136, 13.27322, 0.29378185, NaN, NaN, NaN, -0.22523348, "- N/A -   "
11.459999978542328, 13.27322, 0.2941586, NaN, NaN, NaN, -0.23011659, "- N/A -   "
11.48999971151352, 13.341994, 0.2948899, NaN, NaN, NaN, -0.23133737, "- N/A -   "
11.520000398159027, 13.410767, 0.29648545, NaN, NaN, NaN, -0.21912959, "- N/A -   "
11.550000131130219, 13.926566, 0.2970173, NaN, NaN, NaN, -0.22523348, "- N/A -   "
11.57999986410141, 13.479541, 0.29874584, NaN, NaN, NaN, -0.21058415, "- N/A -   "
11.609999597072601, 13.445154, 0.29936633, NaN, NaN, NaN, -0.21546726, "- N/A -   "
11.64000028371811, 13.685861, 0.30051866, NaN, NaN, NaN, -0.2081426, "- N/A -   "
11.6700000166893, 13.5139265, 0.30220288, NaN, NaN, NaN, -0.19227248, "- N/A -   "
11.699999749660492, 13.5139265, 0.3028455, NaN, NaN, NaN, -0.19593482, "- N/A -   "
11.730000436306, 13.5139265, 0.3028455, NaN, NaN, NaN, -0.20936337, "- N/A -   "
11.760000169277191, 13.995338, 0.3032444, NaN, NaN, NaN, -0.21668804, "- N/A -   "
11.789999902248383, 13.5139265, 0.3048178, NaN, NaN, NaN, -0.20325948, "- N/A -   "
11.819999635219574, 13.479541, 0.3055048, NaN, NaN, NaN, -0.20325948, "- N/A -   "
11.850000321865082, 13.445154, 0.30565992, NaN, NaN, NaN, -0.21424648, "- N/A -   "
11.880000054836273, 13.720246, 0.30574852, NaN, NaN, NaN, -0.22523348, "- N/A -   "
11.909999787807465, 13.5139265, 0.30761, NaN, NaN, NaN, -0.20325948, "- N/A -   "
11.939999520778656, 13.548314, 0.30922773, NaN, NaN, NaN, -0.18738937, "- N/A -   "
11.970000207424164, 13.445154, 0.30949366, NaN, NaN, NaN, -0.19593482, "- N/A -   "
11.999999940395355, 13.410767, 0.30949366, NaN, NaN, NaN, -0.2081426, "- N/A -   "
12.029999673366547, 13.857793, 0.3097596, NaN, NaN, NaN, -0.21790881, "- N/A -   "
12.060000360012054, 13.376381, 0.31133297, NaN, NaN, NaN, -0.20448026, "- N/A -   "
12.090000092983246, 13.376381, 0.31168756, NaN, NaN, NaN, -0.20936337, "- N/A -   "
12.119999825954437, 13.307608, 0.31168756, NaN, NaN, NaN, -0.22279193, "- N/A -   "
12.149999558925629, 13.307608, 0.31299505, NaN, NaN, NaN, -0.21180493, "- N/A -   "
12.180000245571136, 13.445154, 0.31479, NaN, NaN, NaN, -0.19227248, "- N/A -   "
12.209999978542328, 13.410767, 0.3159867, NaN, NaN, NaN, -0.18861015, "- N/A -   "
12.23999971151352, 13.376381, 0.31600887, NaN, NaN, NaN, -0.20081793, "- N/A -   "
12.270000398159027, 13.376381, 0.31600887, NaN, NaN, NaN, -0.21424648, "- N/A -   "
12.300000131130219, 13.857793, 0.3164521, NaN, NaN, NaN, -0.22035037, "- N/A -   "
12.32999986410141, 13.341994, 0.31798112, NaN, NaN, NaN, -0.20692182, "- N/A -   "
12.359999597072601, 13.376381, 0.31831357, NaN, NaN, NaN, -0.21424648, "- N/A -   "
12.39000028371811, 13.341994, 0.3183357, NaN, NaN, NaN, -0.22645426, "- N/A -   "
12.4200000166893, 13.307608, 0.3196875, NaN, NaN, NaN, -0.21424648, "- N/A -   "
12.449999749660492, 13.5139265, 0.32146034, NaN, NaN, NaN, -0.19227248, "- N/A -   "
12.480000436306, 13.410767, 0.322103, NaN, NaN, NaN, -0.19593482, "- N/A -   "
12.510000169277191, 13.376381, 0.322103, NaN, NaN, NaN, -0.20936337, "- N/A -   "
12.539999902248383, 13.892179, 0.32272348, NaN, NaN, NaN, -0.21424648, "- N/A -   "
12.569999635219574, 13.376381, 0.32438552, NaN, NaN, NaN, -0.20081793, "- N/A -   "
12.600000321865082, 13.410767, 0.32467362, NaN, NaN, NaN, -0.20936337, "- N/A -   "
12.630000054836273, 13.376381, 0.32467362, NaN, NaN, NaN, -0.22157115, "- N/A -   "
12.659999787807465, 13.5139265, 0.32598108, NaN, NaN, NaN, -0.21180493, "- N/A -   "
12.689999520778656, 13.445154, 0.32775393, NaN, NaN, NaN, -0.19227248, "- N/A -   "
12.720000207424164, 13.376381, 0.3285517, NaN, NaN, NaN, -0.19349326, "- N/A -   "
12.749999940395355, 13.341994, 0.3285517, NaN, NaN, NaN, -0.20692182, "- N/A -   "
12.779999673366547, 13.789021, 0.3287733, NaN, NaN, NaN, -0.21546726, "- N/A -   "
12.810000360012054, 13.204448, 0.33039102, NaN, NaN, NaN, -0.2020387, "- N/A -   "
12.840000092983246, 13.135674, 0.33072343, NaN, NaN, NaN, -0.2081426, "- N/A -   "
12.869999825954437, 13.101288, 0.33072343, NaN, NaN, NaN, -0.22035037, "- N/A -   "
12.899999558925629, 13.548314, 0.3316985, NaN, NaN, NaN, -0.21790881, "- N/A -   "
12.930000245571136, 13.135674, 0.33347133, NaN, NaN, NaN, -0.19959715, "- N/A -   "
12.959999978542328, 13.066902, 0.3348231, NaN, NaN, NaN, -0.19227248, "- N/A -   "
12.98999971151352, 12.998128, 0.33493394, NaN, NaN, NaN, -0.20570104, "- N/A -   "
13.020000398159027, 13.479541, 0.33502257, NaN, NaN, NaN, -0.21668804, "- N/A -   "
13.050000131130219, 12.929356, 0.3366403, NaN, NaN, NaN, -0.20448026, "- N/A -   "
13.07999986410141, 12.860582, 0.33754885, NaN, NaN, NaN, -0.20570104, "- N/A -   "
13.109999597072601, 12.654263, 0.33801422, NaN, NaN, NaN, -0.21180493, "- N/A -   "
13.14000028371811, 12.619876, 0.33850178, NaN, NaN, NaN, -0.21546726, "- N/A -   "
13.1700000166893, 12.654263, 0.33941033, NaN, NaN, NaN, -0.2130257, "- N/A -   "
13.199999749660492, 12.585489, 0.34098375, NaN, NaN, NaN, -0.20570104, "- N/A -   "
13.230000436306, 12.619876, 0.341294, NaN, NaN, NaN, -0.21180493, "- N/A -   "
13.260000169277191, 13.066902, 0.34213609, NaN, NaN, NaN, -0.2130257, "- N/A -   "
13.289999902248383, 12.551102, 0.3434214, NaN, NaN, NaN, -0.20325948, "- N/A -   "
13.319999635219574, 12.482329, 0.34351006, NaN, NaN, NaN, -0.21424648, "- N/A -   "
13.350000321865082, 12.998128, 0.3444851, NaN, NaN, NaN, -0.21180493, "- N/A -   "
13.380000054836273, 12.551102, 0.3462136, NaN, NaN, NaN, -0.19837637, "- N/A -   "
13.409999787807465, 12.482329, 0.34707788, NaN, NaN, NaN, -0.19471404, "- N/A -   "
13.439999520778656, 12.447944, 0.34707788, NaN, NaN, NaN, -0.2081426, "- N/A -   "
13.470000207424164, 12.929356, 0.347233, NaN, NaN, NaN, -0.21790881, "- N/A -   "
13.499999940395355, 12.413556, 0.34891722, NaN, NaN, NaN, -0.20081793, "- N/A -   "
13.529999673366547, 12.379169, 0.34969285, NaN, NaN, NaN, -0.20081793, "- N/A -   "
13.560000360012054, 12.344784, 0.34989226, NaN, NaN, NaN, -0.20936337, "- N/A -   "
13.590000092983246, 12.310396, 0.34993657, NaN, NaN, NaN, -0.22279193, "- N/A -   "
13.619999825954437, 12.27601, 0.35013604, NaN, NaN, NaN, -0.23133737, "- N/A -   "
13.649999558925629, 12.241624, 0.35157648, NaN, NaN, NaN, -0.21546726, "- N/A -   "
13.680000245571136, 12.379169, 0.35348228, NaN, NaN, NaN, -0.1910517, "- N/A -   "
13.709999978542328, 12.27601, 0.35394764, NaN, NaN, NaN, -0.19593482, "- N/A -   "
13.73999971151352, 12.241624, 0.35394764, NaN, NaN, NaN, -0.20936337, "- N/A -   "
13.770000398159027, 12.723036, 0.35419142, NaN, NaN, NaN, -0.21790881, "- N/A -   "
13.800000131130219, 12.207237, 0.35574266, NaN, NaN, NaN, -0.20448026, "- N/A -   "
13.82999986410141, 12.17285, 0.35609722, NaN, NaN, NaN, -0.21180493, "- N/A -   "
13.859999597072601, 12.17285, 0.35611936, NaN, NaN, NaN, -0.2240127, "- N/A -   "
13.89000028371811, 12.551102, 0.3571609, NaN, NaN, NaN, -0.21790881, "- N/A -   "
13.9200000166893, 12.241624, 0.35913318, NaN, NaN, NaN, -0.19349326, "- N/A -   "
13.949999749660492, 12.17285, 0.36035204, NaN, NaN, NaN, -0.18738937, "- N/A -   "
13.980000436306, 12.138464, 0.36037418, NaN, NaN, NaN, -0.20081793, "- N/A -   "
14.010000169277191, 12.069691, 0.36037418, NaN, NaN, NaN, -0.2130257, "- N/A -   "
14.039999902248383, 12.585489, 0.3605958, NaN, NaN, NaN, -0.22279193, "- N/A -   "
14.069999635219574, 12.035304, 0.36225784, NaN, NaN, NaN, -0.21058415, "- N/A -   "
14.100000321865082, 11.932144, 0.36285618, NaN, NaN, NaN, -0.21058415, "- N/A -   "
14.130000054836273, 11.794598, 0.36298913, NaN, NaN, NaN, -0.22035037, "- N/A -   "
14.159999787807465, 11.725825, 0.36314425, NaN, NaN, NaN, -0.23011659, "- N/A -   "
14.189999520778656, 11.725825, 0.36471766, NaN, NaN, NaN, -0.21058415, "- N/A -   "
14.220000207424164, 11.725825, 0.3663797, NaN, NaN, NaN, -0.19593482, "- N/A -   "
14.249999940395355, 11.588279, 0.36653483, NaN, NaN, NaN, -0.20448026, "- N/A -   "
14.279999673366547, 12.069691, 0.3666456, NaN, NaN, NaN, -0.21668804, "- N/A -   "
14.310000360012054, 11.657051, 0.3682855, NaN, NaN, NaN, -0.20448026, "- N/A -   "
14.340000092983246, 11.416346, 0.36886168, NaN, NaN, NaN, -0.20936337, "- N/A -   "
14.369999825954437, 11.381959, 0.36886168, NaN, NaN, NaN, -0.22279193, "- N/A -   "
14.399999558925629, 11.725825, 0.37010264, NaN, NaN, NaN, -0.21424648, "- N/A -   "
14.430000245571136, 11.347572, 0.3719198, NaN, NaN, NaN, -0.19593482, "- N/A -   "
14.459999978542328, 11.278799, 0.37291703, NaN, NaN, NaN, -0.19349326, "- N/A -   "
14.48999971151352, 11.210026, 0.37291703, NaN, NaN, NaN, -0.20570104, "- N/A -   "
14.520000398159027, 11.725825, 0.37305, NaN, NaN, NaN, -0.21668804, "- N/A -   "
14.550000131130219, 11.175639, 0.3746677, NaN, NaN, NaN, -0.20325948, "- N/A -   "
14.57999986410141, 11.1412525, 0.37515524, NaN, NaN, NaN, -0.2081426, "- N/A -   "
14.609999597072601, 11.072479, 0.37515524, NaN, NaN, NaN, -0.22157115, "- N/A -   "
14.64000028371811, 11.003707, 0.3765735, NaN, NaN, NaN, -0.20448026, "- N/A -   "
14.6700000166893, 11.072479, 0.37825772, NaN, NaN, NaN, -0.18983093, "- N/A -   "
14.699999749660492, 11.038093, 0.37925494, NaN, NaN, NaN, -0.18983093, "- N/A -   "
14.730000436306, 10.96932, 0.3792771, NaN, NaN, NaN, -0.20325948, "- N/A -   "
14.760000169277191, 11.106867, 0.3792771, NaN, NaN, NaN, -0.21668804, "- N/A -   "
14.789999902248383, 10.86616, 0.38080618, NaN, NaN, NaN, -0.20692182, "- N/A -   "
14.819999635219574, 10.831773, 0.38175908, NaN, NaN, NaN, -0.20570104, "- N/A -   "
14.850000321865082, 10.831773, 0.38220227, NaN, NaN, NaN, -0.2130257, "- N/A -   "
14.880000054836273, 10.7630005, 0.38251254, NaN, NaN, NaN, -0.22035037, "- N/A -   "
14.909999787807465, 10.728614, 0.38300008, NaN, NaN, NaN, -0.22157115, "- N/A -   "
14.939999520778656, 10.7630005, 0.3841081, NaN, NaN, NaN, -0.21668804, "- N/A -   "
14.970000207424164, 10.728614, 0.3855264, NaN, NaN, NaN, -0.21058415, "- N/A -   "
14.999999940395355, 11.244412, 0.38581446, NaN, NaN, NaN, -0.21790881, "- N/A -   "
15.029999673366547, 10.728614, 0.38749865, NaN, NaN, NaN, -0.20570104, "- N/A -   "
15.060000360012054, 10.625454, 0.3879197, NaN, NaN, NaN, -0.21180493, "- N/A -   "
15.090000092983246, 11.106867, 0.3883186, NaN, NaN, NaN, -0.21912959, "- N/A -   "
15.119999825954437, 10.659841, 0.3902244, NaN, NaN, NaN, -0.19837637, "- N/A -   "
15.149999558925629, 10.591067, 0.3913989, NaN, NaN, NaN, -0.19471404, "- N/A -   "
15.180000245571136, 10.556681, 0.39148754, NaN, NaN, NaN, -0.20570104, "- N/A -   "
15.209999978542328, 10.934933, 0.3915097, NaN, NaN, NaN, -0.21912959, "- N/A -   "
15.23999971151352, 10.453521, 0.39314958, NaN, NaN, NaN, -0.20081793, "- N/A -   "
15.26999944448471, 10.419134, 0.39403602, NaN, NaN, NaN, -0.20081793, "- N/A -   "
15.300000131130219, 10.384748, 0.3943684, NaN, NaN, NaN, -0.20692182, "- N/A -   "
15.330000817775726, 10.315974, 0.39447922, NaN, NaN, NaN, -0.21668804, "- N/A -   "
15.359999597072601, 10.247202, 0.39463434, NaN, NaN, NaN, -0.22645426, "- N/A -   "
15.39000028371811, 10.212814, 0.39492244, NaN, NaN, NaN, -0.2349997, "- N/A -   "
15.419999063014984, 10.144042, 0.3953878, NaN, NaN, NaN, -0.23744126, "- N/A -   "
15.449999749660492, 10.212814, 0.3961634, NaN, NaN, NaN, -0.23866203, "- N/A -   "
15.480000436306, 10.212814, 0.3978476, NaN, NaN, NaN, -0.2240127, "- N/A -   "
15.509999215602875, 10.625454, 0.39844593, NaN, NaN, NaN, -0.22889581, "- N/A -   "
15.539999902248383, 10.144042, 0.40010798, NaN, NaN, NaN, -0.21424648, "- N/A -   "
15.57000058889389, 10.144042, 0.40077278, NaN, NaN, NaN, -0.21668804, "- N/A -   "
15.599999368190765, 10.109656, 0.40092793, NaN, NaN, NaN, -0.22645426, "- N/A -   "
15.630000054836273, 10.075269, 0.4025678, NaN, NaN, NaN, -0.2020387, "- N/A -   "
15.660000741481781, 10.109656, 0.40434062, NaN, NaN, NaN, -0.18372704, "- N/A -   "
15.689999520778656, 10.006495, 0.40465087, NaN, NaN, NaN, -0.19227248, "- N/A -   "
15.720000207424164, 9.903336, 0.40465087, NaN, NaN, NaN, -0.20448026, "- N/A -   "
15.750000894069672, 9.86895, 0.40465087, NaN, NaN, NaN, -0.21790881, "- N/A -   "
15.779999673366547, 10.315974, 0.40536, NaN, NaN, NaN, -0.22157115, "- N/A -   "
15.810000360012054, 9.765789, 0.40680045, NaN, NaN, NaN, -0.21424648, "- N/A -   "
15.83999913930893, 9.765789, 0.40713286, NaN, NaN, NaN, -0.22035037, "- N/A -   "
15.869999825954437, 10.247202, 0.40735447, NaN, NaN, NaN, -0.22889581, "- N/A -   "
15.900000512599945, 9.765789, 0.4094154, NaN, NaN, NaN, -0.20081793, "- N/A -   "
15.92999929189682, 9.66263, 0.41072288, NaN, NaN, NaN, -0.1910517, "- N/A -   "
15.959999978542328, 9.628243, 0.41078934, NaN, NaN, NaN, -0.2020387, "- N/A -   "
15.990000665187836, 9.731403, 0.41078934, NaN, NaN, NaN, -0.21546726, "- N/A -   "
16.01999944448471, 10.040882, 0.41222978, NaN, NaN, NaN, -0.20325948, "- N/A -   "
16.05000013113022, 9.525084, 0.413227, NaN, NaN, NaN, -0.19959715, "- N/A -   "
16.080000817775726, 9.490697, 0.413227, NaN, NaN, NaN, -0.2130257, "- N/A -   "
16.1099995970726, 9.765789, 0.41324916, NaN, NaN, NaN, -0.22523348, "- N/A -   "
16.14000028371811, 9.421924, 0.41497767, NaN, NaN, NaN, -0.20570104, "- N/A -   "
16.169999063014984, 9.490697, 0.41668403, NaN, NaN, NaN, -0.19227248, "- N/A -   "
16.199999749660492, 9.421924, 0.41723806, NaN, NaN, NaN, -0.19837637, "- N/A -   "
16.230000436306, 9.35315, 0.41723806, NaN, NaN, NaN, -0.21180493, "- N/A -   "
16.259999215602875, 9.800176, 0.41801366, NaN, NaN, NaN, -0.21180493, "- N/A -   "
16.289999902248383, 9.318764, 0.41940978, NaN, NaN, NaN, -0.20570104, "- N/A -   "
16.32000058889389, 9.284378, 0.41960922, NaN, NaN, NaN, -0.21424648, "- N/A -   "
16.349999368190765, 9.800176, 0.4200746, NaN, NaN, NaN, -0.22035037, "- N/A -   "
16.380000054836273, 9.35315, 0.42200255, NaN, NaN, NaN, -0.19593482, "- N/A -   "
16.41000074148178, 9.318764, 0.42339867, NaN, NaN, NaN, -0.18983093, "- N/A -   "
16.439999520778656, 9.181217, 0.42357597, NaN, NaN, NaN, -0.19959715, "- N/A -   "
16.470000207424164, 9.181217, 0.42357597, NaN, NaN, NaN, -0.2130257, "- N/A -   "
16.50000089406967, 9.387537, 0.4246175, NaN, NaN, NaN, -0.2081426, "- N/A -   "
16.529999673366547, 9.112445, 0.42576984, NaN, NaN, NaN, -0.20692182, "- N/A -   "
16.560000360012054, 9.112445, 0.42621306, NaN, NaN, NaN, -0.2081426, "- N/A -   "
16.58999913930893, 9.078057, 0.42645684, NaN, NaN, NaN, -0.2130257, "- N/A -   "
16.619999825954437, 9.009285, 0.4267006, NaN, NaN, NaN, -0.22157115, "- N/A -   "
16.650000512599945, 9.009285, 0.42707732, NaN, NaN, NaN, -0.22889581, "- N/A -   "
16.67999929189682, 9.009285, 0.4278751, NaN, NaN, NaN, -0.23011659, "- N/A -   "
16.709999978542328, 9.043672, 0.42958146, NaN, NaN, NaN, -0.21668804, "- N/A -   "
16.740000665187836, 9.043672, 0.43009114, NaN, NaN, NaN, -0.22035037, "- N/A -   "
16.76999944448471, 9.009285, 0.43162024, NaN, NaN, NaN, -0.2081426, "- N/A -   "
16.80000013113022, 8.940512, 0.43226287, NaN, NaN, NaN, -0.2130257, "- N/A -   "
16.830000817775726, 9.421924, 0.43308282, NaN, NaN, NaN, -0.21424648, "- N/A -   "
16.8599995970726, 8.974898, 0.43492216, NaN, NaN, NaN, -0.19593482, "- N/A -   "
16.89000028371811, 8.906125, 0.43587503, NaN, NaN, NaN, -0.19471404, "- N/A -   "
16.919999063014984, 8.871738, 0.43587503, NaN, NaN, NaN, -0.2081426, "- N/A -   "
16.949999749660492, 9.387537, 0.43614095, NaN, NaN, NaN, -0.21668804, "- N/A -   "
16.980000436306, 8.802965, 0.43775868, NaN, NaN, NaN, -0.20325948, "- N/A -   "
17.009999215602875, 8.768579, 0.43849, NaN, NaN, NaN, -0.20448026, "- N/A -   "
17.039999902248383, 8.734192, 0.43873376, NaN, NaN, NaN, -0.21058415, "- N/A -   "
17.07000058889389, 8.699805, 0.43884456, NaN, NaN, NaN, -0.22157115, "- N/A -   "
17.099999368190765, 8.665419, 0.4390883, NaN, NaN, NaN, -0.22767504, "- N/A -   "
17.130000054836273, 8.631032, 0.43944287, NaN, NaN, NaN, -0.23622048, "- N/A -   "
17.16000074148178, 8.596645, 0.4400412, NaN, NaN, NaN, -0.23988281, "- N/A -   "
17.189999520778656, 8.665419, 0.44134867, NaN, NaN, NaN, -0.23377892, "- N/A -   "
17.220000207424164, 8.631032, 0.44276696, NaN, NaN, NaN, -0.2240127, "- N/A -   "
17.25000089406967, 9.146831, 0.44338748, NaN, NaN, NaN, -0.22889581, "- N/A -   "
17.279999673366547, 8.665419, 0.44496083, NaN, NaN, NaN, -0.21546726, "- N/A -   "
17.310000360012054, 8.56226, 0.44542623, NaN, NaN, NaN, -0.22035037, "- N/A -   "
17.33999913930893, 8.56226, 0.44571432, NaN, NaN, NaN, -0.22889581, "- N/A -   "
17.369999825954437, 8.493486, 0.446224, NaN, NaN, NaN, -0.23377892, "- N/A -   "
17.400000512599945, 8.596645, 0.44750932, NaN, NaN, NaN, -0.22889581, "- N/A -   "
17.42999929189682, 8.56226, 0.44917136, NaN, NaN, NaN, -0.21058415, "- N/A -   "
17.459999978542328, 8.527872, 0.4493265, NaN, NaN, NaN, -0.21912959, "- N/A -   "
17.490000665187836, 8.974898, 0.4499913, NaN, NaN, NaN, -0.22279193, "- N/A -   "
17.51999944448471, 8.459099, 0.45143172, NaN, NaN, NaN, -0.21180493, "- N/A -   "
17.55000013113022, 8.424713, 0.45191926, NaN, NaN, NaN, -0.21546726, "- N/A -   "
17.580000817775726, 8.3903265, 0.45218518, NaN, NaN, NaN, -0.22645426, "- N/A -   "
17.6099995970726, 8.355939, 0.45258406, NaN, NaN, NaN, -0.23133737, "- N/A -   "
17.64000028371811, 8.355939, 0.4534705, NaN, NaN, NaN, -0.23255815, "- N/A -   "
17.669999063014984, 8.3903265, 0.45506606, NaN, NaN, NaN, -0.2240127, "- N/A -   "
17.699999749660492, 8.906125, 0.4556644, NaN, NaN, NaN, -0.22889581, "- N/A -   "
17.730000436306, 8.321553, 0.45741504, NaN, NaN, NaN, -0.21546726, "- N/A -   "
17.759999215602875, 8.287167, 0.4577696, NaN, NaN, NaN, -0.2240127, "- N/A -   "
17.789999902248383, -0.5501853, 0.45914358, NaN, NaN, NaN, -0.21058415, "- N/A -   "